Workbook

Sheet ReadMe
A1: H2-SHIFT Round 2 model: hydrogen retrofit of factory-CNG passenger cars versus continuing on CNG and versus a BEV
A2: Team Wookies, NIT Warangal. SRDI Igniters Innovation Challenge 2026, Engineering Track, Option 2. Research cut-off 14 September 2026.
A4: Purpose: one consistent set of inputs feeding the presentation, annexure and pitch. All outputs are formulas; change inputs only on the Inputs sheet.
A5: Scenario selector: Inputs!C3 (1 = Base, 2 = Downside for the retrofit case, 3 = Upside for the retrofit case). 'Downside' means the retrofit looks worse (for example cheaper CNG, dearer hydrogen).
A6: Colour code: blue text on yellow = input; black = formula; green header = key output.
A7: Evidence classes on the Inputs sheet: A = verified external evidence; B = our calculated estimate; C = explicit assumption or sensitivity range; D = proposed target requiring validation.
A8: Options compared for an owner deciding in the decision year: A = continue operating the CNG donor; B = retrofit the donor to hydrogen (H2-ICE, petrol retained as backup); C = sell the donor and buy a compact fleet BEV.
A9: Fairness rules: the donor's resale value is a cash inflow only in option C (sold at t0); options A and B receive the donor's residual value at the end of the horizon instead. No depreciation is charged in addition to capital cost. Battery replacement is not assumed within the horizon (warranty evidence on Inputs). Charging during idle hours carries no time cost; in-shift charging or refuelling carries a time cost in all three options.
A10: Levelised cost per km = NPV of costs divided by discounted kilometres. Break-even hydrogen price = the year-1 delivered price at which option B has the same NPV as the comparator, holding the same price trajectory shape.
A11: Hydrogen price is the delivered price at the dispenser and is built up on the H2_Supply sheet (production, transport, compression electricity, station capital recovery at a stated utilisation, O&M, losses, margin and taxes). Station capital is recovered through the fuel price only, never allocated twice.
A12: Sheets: Inputs; Donor_Tech (donor and technology comparison); BOM (conversion cost, pilot versus commercial volume); Energy_Range (energy balance, storage, range, mass, power); TCO (cash flows, NPVs, break-even); H2_Supply (fleet demand, station sizing, delivered price, utilisation); Market (bottom-up sizing); Pilot_Budget (phases, budget, rollout); Emissions (per-km and fleet-scale); Sensitivities (grids and one-at-a-time); Sources (register).
A13: Recalculated with LibreOffice Calc (headless) on the build date; open in Excel and press F9 if values do not appear.
A14: Limitations: many external documents were inaccessible through the build environment's network policy; such inputs are flagged in Sources with 'excerpt' or 'summary' status and should be re-verified against originals before publication.

Sheet Inputs
A1: Inputs (single source of truth)
A2: Change values in the Base / Downside / Upside columns only. Active column follows the scenario selector.
B3: Scenario selector (1 Base, 2 Downside, 3 Upside): | C3: 1
A5: Key | B5: Parameter | C5: Base | D5: Downside | E5: Upside | F5: Active | G5: Unit | H5: Class | I5: Source IDs | J5: Notes
A6: General frame
A7: decision_year | B7: Decision year for the owner's choice (first commercial kits after certification) | C7: 2028 | D7: 2028 | E7: 2028 | F7: =CHOOSE($C$3,C7,D7,E7) -> 2028 | G7: year | H7: C | J7: Pilot vehicles run from 2028; owner decision modelled at commercial availability
A8: horizon | B8: Analysis horizon (fixed at 5 years in the cash-flow table) | C8: 5 | D8: 5 | E8: 5 | F8: =CHOOSE($C$3,C8,D8,E8) -> 5 | G8: years | H8: C | J8: Remaining useful life of a 3-year-old fleet sedan
A9: disc | B9: Discount rate (nominal) | C9: 0.12 | D9: 0.14 | E9: 0.1 | F9: =CHOOSE($C$3,C9,D9,E9) -> 0.12 | G9: fraction | H9: A | I9: W4-S29 | J9: NBFC fleet loan rates 10-16 percent
A10: days | B10: Operating days per year | C10: 330 | D10: 330 | E10: 330 | F10: =CHOOSE($C$3,C10,D10,E10) -> 330 | G10: days | H10: C | I10: R1 | J10: Fleet taxi benchmark (Round 1)
A11: km_day | B11: Kilometres per operating day | C11: 167 | D11: 212 | E11: 150 | F11: =CHOOSE($C$3,C11,D11,E11) -> 167 | G11: km/day | H11: A | I11: W4-S30 | J11: 55,000 km/yr base; NITI Aayog Feb 2026 plans 70,000 km/yr for 4W taxis (downside); Round 1 used 150
A12: fuel_esc | B12: Annual escalation of petrol and CNG prices | C12: 0.03 | D12: 0.02 | E12: 0.04 | F12: =CHOOSE($C$3,C12,D12,E12) -> 0.03 | G12: fraction/yr | H12: C | J12: Nominal
A13: elec_esc | B13: Annual escalation of electricity tariffs | C13: 0.02 | D13: 0.01 | E13: 0.03 | F13: =CHOOSE($C$3,C13,D13,E13) -> 0.02 | G13: fraction/yr | H13: C | J13: Nominal
A14: vot | B14: Value of in-shift time lost to refuelling or charging | C14: 150 | D14: 150 | E14: 150 | F14: =CHOOSE($C$3,C14,D14,E14) -> 150 | G14: Rs/hour | H14: C | J14: Approximate contribution margin per hour of a fleet taxi
A15: Donor vehicle (Maruti Suzuki Dzire Tour S CNG, about 3 years old at decision)
A16: donor_value_now | B16: Resale value of donor at decision date (taxi-registered) | C16: 350000 | D16: 400000 | E16: 300000 | F16: =CHOOSE($C$3,C16,D16,E16) -> 350000 | G16: Rs | H16: C | I16: W4-S28 | J16: New Tour S CNG ex-showroom about Rs 7.1 lakh; taxi retention 45-55 percent at 3-4 years; higher value favours selling for a BEV
A17: donor_value_end | B17: Residual value of donor at end of horizon (about 8 years old, high km) | C17: 100000 | D17: 70000 | E17: 130000 | F17: =CHOOSE($C$3,C17,D17,E17) -> 100000 | G17: Rs | H17: C | I17: W4-S28
A18: cng_price | B18: CNG retail price, Delhi (IGL), September 2026 | C18: 87 | D18: 78 | E18: 95 | F18: =CHOOSE($C$3,C18,D18,E18) -> 87 | G18: Rs/kg | H18: A | I18: W4-S16 | J18: Rs 86.98/kg on 14 Sep 2026 (aggregator); Ahmedabad Rs 94; lower CNG price is downside for the retrofit
A19: cng_kmkg | B19: CNG consumption in fleet use (real world, AC, load) | C19: 25 | D19: 27 | E19: 23 | F19: =CHOOSE($C$3,C19,D19,E19) -> 25 | G19: km/kg | H19: C | I19: W1-S3b;W1-S8a | J19: Declared 32.1 km/kg (Tour S); owner reports 24-30; fleet use assumed lower
A20: petrol_price | B20: Petrol retail price, Delhi | C20: 102 | D20: 95 | E20: 111 | F20: =CHOOSE($C$3,C20,D20,E20) -> 102 | G20: Rs/L | H20: A | I20: W4-S19 | J20: Rs 102.12/L verified 25 May 2026; aggregators show Rs 111 in Sep 2026
A21: petrol_kml | B21: Petrol consumption in fleet use (real world, AC) | C21: 15 | D21: 16 | E21: 14 | F21: =CHOOSE($C$3,C21,D21,E21) -> 15 | G21: km/L | H21: C | I21: W1-S3a | J21: Declared 26.1 km/L (Tour S); fleet use assumed lower
A22: petrol_share_cng | B22: Share of km run on petrol by the CNG car (CNG unavailable, queues) | C22: 0.05 | D22: 0.05 | E22: 0.05 | F22: =CHOOSE($C$3,C22,D22,E22) -> 0.05 | G22: fraction | H22: C
A23: maint_cng | B23: Maintenance and tyres, CNG car | C23: 0.9 | D23: 0.7 | E23: 1.2 | F23: =CHOOSE($C$3,C23,D23,E23) -> 0.9 | G23: Rs/km | H23: C | I23: W4-S22 | J23: CEEW 2025 Table 5 to be transcribed; Round 1 value retained
A24: ins_cng | B24: Insurance per year, CNG car | C24: 18000 | D24: 18000 | E24: 18000 | F24: =CHOOSE($C$3,C24,D24,E24) -> 18000 | G24: Rs/yr | H24: C
A25: cng_retest | B25: CNG cylinder hydrostatic test every 3 years | C25: 2000 | D25: 2000 | E25: 2000 | F25: =CHOOSE($C$3,C25,D25,E25) -> 2000 | G25: Rs per test | H25: A | I25: W2-S24 | J25: Gas Cylinder Rules: 3-yearly test
A26: time_cng_h | B26: In-shift time lost refuelling CNG per day (queues) | C26: 0.5 | D26: 0.4 | E26: 0.6 | F26: =CHOOSE($C$3,C26,D26,E26) -> 0.5 | G26: hours/day | H26: C
A27: Hydrogen retrofit (H2-ICE, port injection, 350 bar composite cylinder, petrol retained as automatic backup)
A28: kit_cost | B28: Installed conversion cost at commercial volume, incl. taxes (from BOM sheet) | C28: =BOM!$H$40 -> 322123.48 | D28: =BOM!$H$40*1.25 -> 402654.35 | E28: =BOM!$H$40*0.85 -> 273804.96 | F28: =CHOOSE($C$3,C28,D28,E28) -> 322123.48 | G28: Rs | H28: B | I28: BOM | J28: Linked to BOM volume total
A29: kit_cost_pilot | B29: Installed conversion cost per pilot vehicle (from BOM sheet) | C29: =BOM!$G$40 -> 774375 | D29: =BOM!$G$40 -> 774375 | E29: =BOM!$G$40 -> 774375 | F29: =CHOOSE($C$3,C29,D29,E29) -> 774375 | G29: Rs | H29: B | I29: BOM
A30: salvage_cng | B30: Credit for removed CNG cylinder and kit | C30: 10000 | D30: 0 | E30: 20000 | F30: =CHOOSE($C$3,C30,D30,E30) -> 10000 | G30: Rs | H30: C | J30: Requalified cylinder resale
A31: downtime_days | B31: Conversion downtime | C31: 3 | D31: 4 | E31: 2 | F31: =CHOOSE($C$3,C31,D31,E31) -> 3 | G31: days | H31: C
A32: lost_margin_day | B32: Lost contribution per day of downtime | C32: 1500 | D32: 1500 | E32: 1500 | F32: =CHOOSE($C$3,C32,D32,E32) -> 1500 | G32: Rs/day | H32: C
A33: h2_cons | B33: Hydrogen consumption, H2-ICE mode, fleet use (real world, AC) | C33: 1.85 | D33: 2.3 | E33: 1.6 | F33: =CHOOSE($C$3,C33,D33,E33) -> 1.85 | G33: kg/100 km | H33: B | I33: W1-S12a;W1-S12c;W1-S9a | J33: Energy balance versus CNG (Energy_Range); Ford Focus H2RV 1.4, Mazda RX-8 RE 2.4, HiAce van 3.1 kg/100 km
A34: h2_share | B34: Share of km driven on hydrogen (rest on petrol backup) | C34: 0.65 | D34: 0.5 | E34: 0.85 | F34: =CHOOSE($C$3,C34,D34,E34) -> 0.65 | G34: fraction | H34: C | J34: Two depot fills per day; check Energy_Range max share
A35: h2_price_y1 | B35: Delivered hydrogen price at dispenser, year 1 (2028), unsubsidised, shared hub station | C35: 800 | D35: 1000 | E35: 550 | F35: =CHOOSE($C$3,C35,D35,E35) -> 800 | G35: Rs/kg | H35: B | I35: W4-S22;W4-S46 | J35: CEEW: small-network refuelling today above USD 10/kg; H2_Supply build-up gives the pilot-station price
A36: h2_change | B36: Annual change in delivered hydrogen price | C36: -0.1 | D36: -0.03 | E36: -0.15 | F36: =CHOOSE($C$3,C36,D36,E36) -> -0.1 | G36: fraction/yr | H36: C | I36: W4-S22 | J36: CEEW path to USD 4.2/kg (about Rs 360) delivered in 2030
A37: maint_h2 | B37: Maintenance and tyres, retrofitted car | C37: 1 | D37: 1.2 | E37: 0.85 | F37: =CHOOSE($C$3,C37,D37,E37) -> 1 | G37: Rs/km | H37: C | I37: W4-S22 | J37: Adds injector, sensor, regulator service
A38: ins_h2 | B38: Insurance per year, retrofitted car | C38: 21000 | D38: 24000 | E38: 19000 | F38: =CHOOSE($C$3,C38,D38,E38) -> 21000 | G38: Rs/yr | H38: C | I38: W2-S53 | J38: No IMT endorsement exists for hydrogen kits; assumes insurer accepts endorsed retrofit
A39: h2_inspect_yr | B39: Hydrogen system inspection and 3-yearly cylinder requalification, annualised | C39: 4000 | D39: 6000 | E39: 3000 | F39: =CHOOSE($C$3,C39,D39,E39) -> 4000 | G39: Rs/yr | H39: C | I39: W2-S24
A40: time_h2_h | B40: In-shift time lost for hydrogen refuelling and detour per day | C40: 0.4 | D40: 0.6 | E40: 0.3 | F40: =CHOOSE($C$3,C40,D40,E40) -> 0.4 | G40: hours/day | H40: C | J40: Two short fills at a depot dispenser
A41: mod_resid_factor | B41: Residual value factor for a modified vehicle | C41: 0.9 | D41: 0.8 | E41: 1 | F41: =CHOOSE($C$3,C41,D41,E41) -> 0.9 | G41: fraction | H41: C
...

Sheet BOM
A1: Retrofit bill of materials and conversion cost
A2: Pilot batch (about 30 kits) versus commercial volume (about 10,000 kits per year with localised cylinders). Unit costs are estimates unless a source is given.
A4: # | B4: Component / activity | C4: Qty | D4: Unit cost pilot (Rs) | E4: Unit cost volume (Rs) | F4: Pilot total (Rs) | G4: Volume total (Rs) | H4: Class | I4: Basis / source
B5: Storage and mounting
A6: 1 | B6: Composite hydrogen cylinder, 60 L water volume, 350 bar (Type III or IV), 15-year life | C6: 1 | D6: 250000 | E6: 95000 | F6: =C6*D6 -> 250000 | G6: =C6*E6 -> 95000 | H6: B | I6: Scaled from DOE/Strategic Analysis Type IV system cost records (S-CYLCOST): about $33/kWh at low volume and $21/kWh at 10k/yr for a 5.6 kg 700 bar system, applied to a 1.45 kg (48 kWh) cylinder with a small-size penalty; example product Luxfer G-Stor Pro V060H35 (S-CYL)
A7: 2 | B7: On-tank valve with solenoid, excess-flow, manual shut-off and TPRD (UN R134 class) | C7: 1 | D7: 55000 | E7: 18000 | F7: =C7*D7 -> 55000 | G7: =C7*E7 -> 18000 | H7: C | I7: Production parts exist (S-OTV); no public price; estimate
A8: 3 | B8: Mounting frame, straps, boot bulkhead shield, TPRD vent duct, boot ventilation | C8: 1 | D8: 30000 | E8: 11000 | F8: =C8*D8 -> 30000 | G8: =C8*E8 -> 11000 | H8: C | I8: Fabricated steel frame per UN R110-type 20 g / 8 g loads; estimate
B9: Fuel delivery
A10: 4 | B10: H35 receptacle, check valve, high-pressure filter | C10: 1 | D10: 25000 | E10: 8000 | F10: =C10*D10 -> 25000 | G10: =C10*E10 -> 8000 | H10: C | I10: ISO 17268 H35 receptacle; estimate
A11: 5 | B11: Stainless (316L) high-pressure lines and fittings | C11: 1 | D11: 18000 | E11: 7000 | F11: =C11*D11 -> 18000 | G11: =C11*E11 -> 7000 | H11: C | I11: Estimate
A12: 6 | B12: Two-stage pressure regulator 350 bar to injection pressure, with pressure and temperature sensors | C12: 1 | D12: 55000 | E12: 15000 | F12: =C12*D12 -> 55000 | G12: =C12*E12 -> 15000 | H12: C | I12: Production FCEV regulators exist (S-REG); estimate for ICE outlet pressure
A13: 7 | B13: Hydrogen port-fuel injectors (4) and rail | C13: 1 | D13: 40000 | E13: 12000 | F13: =C13*D13 -> 40000 | G13: =C13*E13 -> 12000 | H13: C | I13: Bosch / PHINIA H2 PFI injectors announced 2024-25 (S-INJ); estimate
A14: 8 | B14: Low-pressure hose, fuel shut-off, pressure relief | C14: 1 | D14: 8000 | E14: 3500 | F14: =C14*D14 -> 8000 | G14: =C14*E14 -> 3500 | H14: C | I14: Estimate
B15: Controls and safety
A16: 9 | B16: Hydrogen ECU (dual-map, CAN, automatic petrol fallback, diagnostics) with harness | C16: 1 | D16: 45000 | E16: 15000 | F16: =C16*D16 -> 45000 | G16: =C16*E16 -> 15000 | H16: C | I16: Analogous to sequential CNG ECU at volume; pilot uses low-volume controller
A17: 10 | B17: Hydrogen leak sensors (boot and engine bay), controller, cabin warning, vent fan | C17: 1 | D17: 22000 | E17: 7000 | F17: =C17*D17 -> 22000 | G17: =C17*E17 -> 7000 | H17: C | I17: Automotive H2 sensors exist (S-SENS); estimate
B18: Engine and emissions
A19: 11 | B19: Cold-grade spark plugs, PCV/oil-separator upgrade, coolant and knock sensor check | C19: 1 | D19: 8000 | E19: 4000 | F19: =C19*D19 -> 8000 | G19: =C19*E19 -> 4000 | H19: C | I19: Backfire and pre-ignition mitigation items (S-H2ICE)
A20: 12 | B20: Lean-NOx aftertreatment provision (lean NOx trap) and lambda sensor | C20: 1 | D20: 35000 | E20: 15000 | F20: =C20*D20 -> 35000 | G20: =C20*E20 -> 15000 | H20: C | I20: Needed if lean calibration alone does not meet BS-VI NOx over the cycle (S-NOX); estimate
B21: Installation and validation
A22: 13 | B22: Removal of CNG kit and cylinder, installation labour (hours) | C22: 40 | D22: 600 | E22: 600 | F22: =C22*D22 -> 24000 | G22: =14*E22 -> 8400 | H22: C | I22: Pilot 40 h; volume 14 h at Rs 600/h (see qty note)
A23: 14 | B23: Per-vehicle leak test, commissioning, road test and documentation | C23: 1 | D23: 10000 | E23: 2500 | F23: =C23*D23 -> 10000 | G23: =C23*E23 -> 2500 | H23: C | I23: Estimate
A24: 15 | B24: Certification and engineering amortisation per kit | C24: 1 | D24: 0 | E24: 8000 | F24: =C24*D24 -> 0 | G24: =C24*E24 -> 8000 | H24: B | I24: Volume: one-time development and type-approval cost (Pilot_Budget) spread over 50,000 kits; pilot carries it in the programme budget
B26: Subtotal parts, labour and validation | F26: =SUM(F6:F24) -> 625000 | G26: =SUM(G6:G24) -> 229400
B27: Warranty provision (share of subtotal) | D27: 0.05 | E27: 0.04 | F27: =F26*D27 -> 31250 | G27: =G26*E27 -> 9176
B28: Installer and kit-maker margin (share of subtotal) | D28: 0 | E28: 0.15 | F28: =F26*D28 -> 0 | G28: =G26*E28 -> 34410
B29: GST on kit and installation (rate assumed; CNG kits attract 28 percent, hydrogen kit classification to be confirmed) | D29: 0.18 | E29: 0.18 | F29: =(F26+F27+F28)*D29 -> 118125 | G29: =(G26+G27+G28)*E29 -> 49137.48
B40: Installed conversion cost per vehicle (incl. taxes) | E40: Pilot (G) / Volume (H): | F40: =F26+F27+F28+F29 -> 774375 | G40: =F40 -> 774375 | H40: =G26+G27+G28+G29 -> 322123.48
B41: Share of cylinder and valve in volume kit cost | F41: =(G6+G7)/G26 -> 0.49258936
B42: Volume kit cost in Rs lakh | F42: =H40/100000 -> 3.2212348
B43: Pilot kit cost in Rs lakh | F43: =G40/100000 -> 7.74375
B44: Reference: Round 1 assumed Rs 1.8 to 2.2 lakh installed. Reference: sequential CNG retrofit kit incl. cylinder and fitting in India about Rs 0.6 to 0.9 lakh (S-CNGKIT).

Sheet Energy_Range
A1: Energy balance, storage, range, mass and power
A2: Column vectors of formulas referencing Inputs. Hydrogen consumption is an input cross-checked against the CNG energy balance.
A4: Quantity | B4: Value | C4: Unit | D4: Formula / note
A5: Energy use per km on CNG (fleet real-world) | B5: =Inputs!$F$55/Inputs!$F$19 -> 1.92 | C5: MJ/km | D5: LHV / km per kg
A6: Energy use per km on petrol (fleet real-world) | B6: =Inputs!$F$56/Inputs!$F$21 -> 2.1466667 | C6: MJ/km
A7: Hydrogen consumption assumed (input) | B7: =Inputs!$F$33 -> 1.85 | C7: kg/100 km | D7: Input h2_cons
A8: Energy use per km on hydrogen | B8: =B7/100*Inputs!$F$57 -> 2.22 | C8: MJ/km
A9: Implied H2-ICE efficiency relative to CNG operation (>1 = better) | B9: =B5/B8 -> 0.86486486 | C9: ratio | D9: Cross-check: lean PFI hydrogen at part load can match or exceed CNG efficiency; retrofit calibration usually loses some of that
A10: Hydrogen economy | B10: =100/B7 -> 54.054054 | C10: km/kg
A11: Cylinder internal volume | B11: =Inputs!$F$58 -> 60 | C11: L
A12: Nominal hydrogen at 350 bar, 15 C | B12: =B11/1000*Inputs!$F$59 -> 1.44 | C12: kg | D12: Density 24.0 kg/m3 (S-DENS)
A13: Nominal hydrogen if 700 bar cylinder of same volume | B13: =B11/1000*Inputs!$F$60 -> 2.412 | C13: kg | D13: Design option; needs 700 bar dispensing
A14: Hydrogen after a non-cooled 350 bar fill | B14: =B12*Inputs!$F$61 -> 1.224 | C14: kg | D14: Fill SOC input; hot ambient, no pre-cooling
A15: Residual hydrogen at minimum usable pressure | B15: =B11/1000*Inputs!$F$62 -> 0.102 | C15: kg | D15: About 20 bar residual
A16: Usable hydrogen per fill | B16: =B14-B15 -> 1.122 | C16: kg | D16: Key output
A17: Range on hydrogen per fill | B17: =B16/(B7/100) -> 60.648649 | C17: km | D17: Key output
A18: Range on hydrogen per fill, 700 bar option | B18: =(B13*Inputs!$F$61-B15)/(B7/100) -> 105.30811 | C18: km
A19: Petrol backup range | B19: =Inputs!$F$71*Inputs!$F$21 -> 555 | C19: km | D19: Existing tank retained
A20: Daily hydrogen need at full hydrogen operation | B20: =Inputs!$F$11*B7/100 -> 3.0895 | C20: kg/day
A21: Fills per day needed for 100 percent hydrogen operation | B21: =B20/B16 -> 2.7535651 | C21: fills/day
A22: Maximum share of km on hydrogen with the available depot fills | B22: =MIN(1,Inputs!$F$63*B16/B20) -> 0.72633112 | C22: fraction | D22: Compare with input h2_share
A23: Share of km on hydrogen used in the model (input) | B23: =Inputs!$F$34 -> 0.65 | C23: fraction
A24: Hydrogen used per operating day in the model | B24: =Inputs!$F$11*B7/100*B23 -> 2.008175 | C24: kg/day
A25: Mass added: cylinder + valve/frame/regulator/lines/ECU | B25: =Inputs!$F$64+Inputs!$F$65 -> 50 | C25: kg
A26: Mass removed: CNG cylinder + CNG kit | B26: =Inputs!$F$66+Inputs!$F$67 -> 63 | C26: kg
A27: Net kerb mass change | B27: =B25-B26 -> -13 | C27: kg | D27: Negative = lighter than CNG configuration
A28: Peak power on petrol | B28: =Inputs!$F$68 -> 81.6 | C28: PS | D28: Donor spec
A29: Peak power on CNG (factory) | B29: =Inputs!$F$69 -> 70 | C29: PS | D29: Third-party figure; official CNG rating not captured
A30: Estimated peak power on hydrogen (lean PFI) | B30: =Inputs!$F$68*Inputs!$F$70 -> 42.432 | C30: PS | D30: About 30 percent air displacement plus lean operation (S-H2PWR)
A31: Power loss versus petrol | B31: =1-Inputs!$F$70 -> 0.48 | C31: fraction
A32: Power loss versus CNG | B32: =1-B30/B29 -> 0.39382857 | C32: fraction
A33: Power-to-mass, hydrogen mode, 4 occupants (kerb 1045 kg + 300 kg) | B33: =B30/((1045+B27+300)/1000) -> 31.855856 | C33: PS per tonne | D33: Urban duty reference: a loaded 800 cc hatchback is about 40 PS per tonne
A34: HCNG 18 vol% blend: hydrogen share of energy | B34: =(18*10.8)/(18*10.8+82*35.8) -> 0.062108626 | C34: fraction | D34: Volumetric LHVs 10.8 and 35.8 MJ/Nm3 (S-HCNG); no vehicle modification

Sheet TCO
A1: Ownership cost comparison for one vehicle: A continue on CNG, B hydrogen retrofit, C sell and buy BEV
A2: Nominal cash costs (Rs). Negative values are inflows (residual values). Years in columns; t0 = decision date.
A3: Year index | C3: 0 | D3: 1 | E3: 2 | F3: 3 | G3: 4 | H3: 5
A4: Calendar year | C4: =Inputs!$F$7+C3 -> 2028 | D4: =Inputs!$F$7+D3 -> 2029 | E4: =Inputs!$F$7+E3 -> 2030 | F4: =Inputs!$F$7+F3 -> 2031 | G4: =Inputs!$F$7+G3 -> 2032 | H4: =Inputs!$F$7+H3 -> 2033
A5: Discount factor | C5: =1/(1+Inputs!$F$9)^C3 -> 1 | D5: =1/(1+Inputs!$F$9)^D3 -> 0.89285714 | E5: =1/(1+Inputs!$F$9)^E3 -> 0.79719388 | F5: =1/(1+Inputs!$F$9)^F3 -> 0.71178025 | G5: =1/(1+Inputs!$F$9)^G3 -> 0.63551808 | H5: =1/(1+Inputs!$F$9)^H3 -> 0.56742686
A6: Annual km | C6: 0 | D6: =Inputs!$F$10*Inputs!$F$11 -> 55110 | E6: =Inputs!$F$10*Inputs!$F$11 -> 55110 | F6: =Inputs!$F$10*Inputs!$F$11 -> 55110 | G6: =Inputs!$F$10*Inputs!$F$11 -> 55110 | H6: =Inputs!$F$10*Inputs!$F$11 -> 55110
A7: Petrol price (Rs/L) | D7: =Inputs!$F$20*(1+Inputs!$F$12)^(D3-1) -> 102 | E7: =Inputs!$F$20*(1+Inputs!$F$12)^(E3-1) -> 105.06 | F7: =Inputs!$F$20*(1+Inputs!$F$12)^(F3-1) -> 108.2118 | G7: =Inputs!$F$20*(1+Inputs!$F$12)^(G3-1) -> 111.45815 | H7: =Inputs!$F$20*(1+Inputs!$F$12)^(H3-1) -> 114.8019
A8: CNG price (Rs/kg) | D8: =Inputs!$F$18*(1+Inputs!$F$12)^(D3-1) -> 87 | E8: =Inputs!$F$18*(1+Inputs!$F$12)^(E3-1) -> 89.61 | F8: =Inputs!$F$18*(1+Inputs!$F$12)^(F3-1) -> 92.2983 | G8: =Inputs!$F$18*(1+Inputs!$F$12)^(G3-1) -> 95.067249 | H8: =Inputs!$F$18*(1+Inputs!$F$12)^(H3-1) -> 97.919266
A9: Delivered hydrogen price (Rs/kg) | D9: =Inputs!$F$35*(1+Inputs!$F$36)^(D3-1) -> 800 | E9: =Inputs!$F$35*(1+Inputs!$F$36)^(E3-1) -> 720 | F9: =Inputs!$F$35*(1+Inputs!$F$36)^(F3-1) -> 648 | G9: =Inputs!$F$35*(1+Inputs!$F$36)^(G3-1) -> 583.2 | H9: =Inputs!$F$35*(1+Inputs!$F$36)^(H3-1) -> 524.88
A10: Hydrogen price trajectory multiplier (relative to year 1) | D10: =(1+Inputs!$F$36)^(D3-1) -> 1 | E10: =(1+Inputs!$F$36)^(E3-1) -> 0.9 | F10: =(1+Inputs!$F$36)^(F3-1) -> 0.81 | G10: =(1+Inputs!$F$36)^(G3-1) -> 0.729 | H10: =(1+Inputs!$F$36)^(H3-1) -> 0.6561
A11: Depot tariff (Rs/kWh) | D11: =Inputs!$F$47*(1+Inputs!$F$13)^(D3-1) -> 6 | E11: =Inputs!$F$47*(1+Inputs!$F$13)^(E3-1) -> 6.12 | F11: =Inputs!$F$47*(1+Inputs!$F$13)^(F3-1) -> 6.2424 | G11: =Inputs!$F$47*(1+Inputs!$F$13)^(G3-1) -> 6.367248 | H11: =Inputs!$F$47*(1+Inputs!$F$13)^(H3-1) -> 6.494593
A12: Public fast-charge price (Rs/kWh) | D12: =Inputs!$F$48*(1+Inputs!$F$13)^(D3-1) -> 20 | E12: =Inputs!$F$48*(1+Inputs!$F$13)^(E3-1) -> 20.4 | F12: =Inputs!$F$48*(1+Inputs!$F$13)^(F3-1) -> 20.808 | G12: =Inputs!$F$48*(1+Inputs!$F$13)^(G3-1) -> 21.22416 | H12: =Inputs!$F$48*(1+Inputs!$F$13)^(H3-1) -> 21.648643
A13: Hydrogen consumed (kg) | D13: =D6*Inputs!$F$34*Inputs!$F$33/100 -> 662.69775 | E13: =E6*Inputs!$F$34*Inputs!$F$33/100 -> 662.69775 | F13: =F6*Inputs!$F$34*Inputs!$F$33/100 -> 662.69775 | G13: =G6*Inputs!$F$34*Inputs!$F$33/100 -> 662.69775 | H13: =H6*Inputs!$F$34*Inputs!$F$33/100 -> 662.69775
A16: Option A: continue operating the CNG donor
A17: Capital / transaction at t0 | C17: =0 -> 0 | D17: 0 | E17: 0 | F17: 0 | G17: 0 | H17: 0
A18: CNG fuel | C18: 0 | D18: =D6*(1-Inputs!$F$22)/Inputs!$F$19*D8 -> 182193.66 | E18: =E6*(1-Inputs!$F$22)/Inputs!$F$19*E8 -> 187659.47 | F18: =F6*(1-Inputs!$F$22)/Inputs!$F$19*F8 -> 193289.25 | G18: =G6*(1-Inputs!$F$22)/Inputs!$F$19*G8 -> 199087.93 | H18: =H6*(1-Inputs!$F$22)/Inputs!$F$19*H8 -> 205060.57
A19: Petrol fuel (share of km) | C19: 0 | D19: =D6*Inputs!$F$22/Inputs!$F$21*D7 -> 18737.4 | E19: =E6*Inputs!$F$22/Inputs!$F$21*E7 -> 19299.522 | F19: =F6*Inputs!$F$22/Inputs!$F$21*F7 -> 19878.508 | G19: =G6*Inputs!$F$22/Inputs!$F$21*G7 -> 20474.863 | H19: =H6*Inputs!$F$22/Inputs!$F$21*H7 -> 21089.109
A20: Maintenance and tyres | C20: 0 | D20: =D6*Inputs!$F$23 -> 49599 | E20: =E6*Inputs!$F$23 -> 49599 | F20: =F6*Inputs!$F$23 -> 49599 | G20: =G6*Inputs!$F$23 -> 49599 | H20: =H6*Inputs!$F$23 -> 49599
A21: Insurance | C21: 0 | D21: =Inputs!$F$24 -> 18000 | E21: =Inputs!$F$24 -> 18000 | F21: =Inputs!$F$24 -> 18000 | G21: =Inputs!$F$24 -> 18000 | H21: =Inputs!$F$24 -> 18000
A22: Cylinder periodic test (annualised) | C22: 0 | D22: =Inputs!$F$25/3 -> 666.66667 | E22: =Inputs!$F$25/3 -> 666.66667 | F22: =Inputs!$F$25/3 -> 666.66667 | G22: =Inputs!$F$25/3 -> 666.66667 | H22: =Inputs!$F$25/3 -> 666.66667
A23: In-shift refuelling time cost | C23: 0 | D23: =Inputs!$F$26*Inputs!$F$10*Inputs!$F$14 -> 24750 | E23: =Inputs!$F$26*Inputs!$F$10*Inputs!$F$14 -> 24750 | F23: =Inputs!$F$26*Inputs!$F$10*Inputs!$F$14 -> 24750 | G23: =Inputs!$F$26*Inputs!$F$10*Inputs!$F$14 -> 24750 | H23: =Inputs!$F$26*Inputs!$F$10*Inputs!$F$14 -> 24750
A24: Residual value at end of horizon (inflow) | C24: 0 | D24: 0 | E24: 0 | F24: 0 | G24: 0 | H24: =-Inputs!$F$17 -> -100000
A25: Total cash cost | C25: =SUM(C17:C24) -> 0 | D25: =SUM(D17:D24) -> 293946.73 | E25: =SUM(E17:E24) -> 299974.66 | F25: =SUM(F17:F24) -> 306183.43 | G25: =SUM(G17:G24) -> 312578.46 | H25: =SUM(H17:H24) -> 219165.34
A26: Present value | C26: =C25*C$5 -> 0 | D26: =D25*D$5 -> 262452.43 | E26: =E25*E$5 -> 239137.96 | F26: =F25*F$5 -> 217935.32 | G26: =G25*G$5 -> 198649.26 | H26: =H25*H$5 -> 124360.3
A27: NPV of costs (Rs) | C27: =SUM(C26:H26) -> 1042535.3
A30: Option B: retrofit the donor to hydrogen (H2-ICE, petrol backup retained)
A31: Capital / transaction at t0 | C31: =Inputs!$F$28-Inputs!$F$30+Inputs!$F$31*Inputs!$F$32 -> 316623.48 | D31: 0 | E31: 0 | F31: 0 | G31: 0 | H31: 0
A32: Hydrogen fuel | C32: 0 | D32: =D13*D9 -> 530158.2 | E32: =E13*E9 -> 477142.38 | F32: =F13*F9 -> 429428.14 | G32: =G13*G9 -> 386485.33 | H32: =H13*H9 -> 347836.8
A33: Petrol fuel (backup share of km) | C33: 0 | D33: =D6*(1-Inputs!$F$34)/Inputs!$F$21*D7 -> 131161.8 | E33: =E6*(1-Inputs!$F$34)/Inputs!$F$21*E7 -> 135096.65 | F33: =F6*(1-Inputs!$F$34)/Inputs!$F$21*F7 -> 139149.55 | G33: =G6*(1-Inputs!$F$34)/Inputs!$F$21*G7 -> 143324.04 | H33: =H6*(1-Inputs!$F$34)/Inputs!$F$21*H7 -> 147623.76
A34: Maintenance and tyres | C34: 0 | D34: =D6*Inputs!$F$37 -> 55110 | E34: =E6*Inputs!$F$37 -> 55110 | F34: =F6*Inputs!$F$37 -> 55110 | G34: =G6*Inputs!$F$37 -> 55110 | H34: =H6*Inputs!$F$37 -> 55110
A35: Insurance | C35: 0 | D35: =Inputs!$F$38 -> 21000 | E35: =Inputs!$F$38 -> 21000 | F35: =Inputs!$F$38 -> 21000 | G35: =Inputs!$F$38 -> 21000 | H35: =Inputs!$F$38 -> 21000
A36: Hydrogen system inspection and cylinder requalification | C36: 0 | D36: =Inputs!$F$39 -> 4000 | E36: =Inputs!$F$39 -> 4000 | F36: =Inputs!$F$39 -> 4000 | G36: =Inputs!$F$39 -> 4000 | H36: =Inputs!$F$39 -> 4000
A37: In-shift refuelling time and detour cost | C37: 0 | D37: =Inputs!$F$40*Inputs!$F$10*Inputs!$F$14 -> 19800 | E37: =Inputs!$F$40*Inputs!$F$10*Inputs!$F$14 -> 19800 | F37: =Inputs!$F$40*Inputs!$F$10*Inputs!$F$14 -> 19800 | G37: =Inputs!$F$40*Inputs!$F$10*Inputs!$F$14 -> 19800 | H37: =Inputs!$F$40*Inputs!$F$10*Inputs!$F$14 -> 19800
A38: Residual value at end of horizon (inflow) | C38: 0 | D38: 0 | E38: 0 | F38: 0 | G38: 0 | H38: =-(Inputs!$F$17*Inputs!$F$41+Inputs!$F$42) -> -90000
A39: Total cash cost | C39: =SUM(C31:C38) -> 316623.48 | D39: =SUM(D31:D38) -> 761230 | E39: =SUM(E31:E38) -> 712149.03 | F39: =SUM(F31:F38) -> 668487.7 | G39: =SUM(G31:G38) -> 629719.37 | H39: =SUM(H31:H38) -> 505370.56
A40: Present value | C40: =C39*C$5 -> 316623.48 | D40: =D39*D$5 -> 679669.64 | E40: =E39*E$5 -> 567720.85 | F40: =F39*F$5 -> 475816.34 | G40: =G39*G$5 -> 400198.04 | H40: =H39*H$5 -> 286760.83
A41: NPV of costs (Rs) | C41: =SUM(C40:H40) -> 2726789.2
A42: NPV of option B excluding hydrogen fuel (Rs) | C42: =C41-SUMPRODUCT(D32:H32,D5:H5) -> 1124409.8
A45: Option C: sell the donor and buy a compact fleet BEV
A46: Capital / transaction at t0 | C46: =Inputs!$F$44+Inputs!$F$45-Inputs!$F$16 -> 730000 | D46: 0 | E46: 0 | F46: 0 | G46: 0 | H46: 0
...

Sheet H2_Supply
A1: Hydrogen supply: fleet demand, station sizing and delivered price build-up
A2: Delivered price = (production + transport + compression electricity + station capital recovery + O&M) x (1 + losses) x (1 + margin and taxes). Capital is recovered only here.
A4: Quantity | B4: Pilot (2028) | C4: Hub (2030) | D4: Unit | E4: Note
A5: Cars served | B5: =Inputs!$F$73 -> 30 | C5: =B27 -> 37.347343 | D5: cars | E5: Hub: cars per station at design utilisation (row 27)
A6: Hydrogen per car per operating day | B6: =Energy_Range!$B$24 -> 2.008175 | C6: =Energy_Range!$B$24 -> 2.008175 | D6: kg/car/day | E6: From Energy_Range
A7: Fleet hydrogen demand per operating day | B7: =B5*B6 -> 60.24525 | C7: =C5*C6 -> 75 | D7: kg/day
A8: Station design capacity | B8: =Inputs!$F$78 -> 150 | C8: =Inputs!$F$81 -> 500 | D8: kg/day
A9: Station utilisation assumed for pricing | B9: =Inputs!$F$79 -> 0.5 | C9: =Inputs!$F$82 -> 0.7 | D9: fraction | E9: Pilot station shared with bus/truck pilot users
A10: Hydrogen dispensed per year at that utilisation | B10: =B8*365*B9 -> 27375 | C10: =C8*365*C9 -> 127750 | D10: kg/yr
A11: Fills per day (cars x fills) | B11: =B5*Inputs!$F$63 -> 60 | C11: =C5*Inputs!$F$63 -> 74.694685 | D11: fills/day
A12: Peak window length | B12: 3 | C12: 3 | D12: hours | E12: Start-of-shift window
A13: Share of fills in the peak window | B13: 0.5 | C13: 0.4 | D13: fraction | E13: Assumption
A14: Fills per hour in the peak window | B14: =B11*B13/B12 -> 10 | C14: =C11*C13/C12 -> 9.9592914 | D14: fills/h
A15: Dispenser positions needed (6 fills per hour each, 1.2 kg fills at 350 bar) | B15: =ROUNDUP(B14/6,0) -> 2 | C15: =ROUNDUP(C14/6,0) -> 2 | D15: dispensers | E15: Assumption 6 fills/h per H35 dispenser incl. connection
A16: Compressor throughput needed (16 operating hours) | B16: =B8/16 -> 9.375 | C16: =C8/16 -> 31.25 | D16: kg/h | E16: Sized on design capacity
A17: On-site storage buffer (1.5 days of demand) | B17: =1.5*B7 -> 90.367875 | C17: =1.5*C7 -> 112.5 | D17: kg | E17: Cascade at 450 bar
A18: Tube-trailer deliveries per week | B18: =B7*7/Inputs!$F$89 -> 1.4057225 | C18: =C7*7/Inputs!$F$89 -> 1.75 | D18: deliveries/week
A19: Production cost at plant gate | B19: =Inputs!$F$74 -> 400 | C19: =Inputs!$F$75 -> 240 | D19: Rs/kg
A20: Transport (tube trailer) | B20: =Inputs!$F$76 -> 45 | C20: =Inputs!$F$76 -> 45 | D20: Rs/kg
A21: Compression and dispensing electricity | B21: =Inputs!$F$85*Inputs!$F$86 -> 27 | C21: =Inputs!$F$85*Inputs!$F$86 -> 27 | D21: Rs/kg
A22: Station capex | B22: =Inputs!$F$77 -> 100000000 | C22: =Inputs!$F$80 -> 120000000 | D22: Rs
A23: Capital recovery factor | B23: =Inputs!$F$9*(1+Inputs!$F$9)^Inputs!$F$83/((1+Inputs!$F$9)^Inputs!$F$83-1) -> 0.17698416 | C23: =Inputs!$F$9*(1+Inputs!$F$9)^Inputs!$F$83/((1+Inputs!$F$9)^Inputs!$F$83-1) -> 0.17698416 | D23: fraction
A24: Station capital recovery per kg | B24: =B22*B23/B10 -> 646.51749 | C24: =C22*C23/C10 -> 166.24736 | D24: Rs/kg | E24: At the assumed utilisation
A25: Station fixed O&M per kg | B25: =B22*Inputs!$F$84/B10 -> 146.11872 | C25: =C22*Inputs!$F$84/C10 -> 37.573386 | D25: Rs/kg
A26: Delivered price at dispenser | B26: =(B19+B20+B21+B24+B25)*(1+Inputs!$F$87)*(1+Inputs!$F$88) -> 1432.8328 | C26: =(C19+C20+C21+C24+C25)*(1+Inputs!$F$87)*(1+Inputs!$F$88) -> 584.4249 | D26: Rs/kg | E26: Key output; compare with Inputs h2_price_y1
A27: Cars a station can serve at design utilisation | B27: =B8*B9/B6 -> 37.347343 | C27: =C8*C9/C6 -> 174.2876 | D27: cars
A28: Utilisation implied by the car fleet alone | B28: =B7/B8 -> 0.401635 | C28: =C7/C8 -> 0.15 | D28: fraction
A31: Delivered price versus station utilisation (Rs/kg)
A32: Utilisation | B32: Pilot station (2028) | C32: Hub station (2030)
A33: 0.2 | B33: =($B$19+$B$20+$B$21+($B$22*$B$23+$B$22*Inputs!$F$84)/($B$8*365*A33))*(1+Inputs!$F$87)*(1+Inputs!$F$88) -> 2779.9181 | C33: =($C$19+$C$20+$C$21+($C$22*$C$23+$C$22*Inputs!$F$84)/($C$8*365*A33))*(1+Inputs!$F$87)*(1+Inputs!$F$88) -> 1161.7471
A34: 0.35 | B34: =($B$19+$B$20+$B$21+($B$22*$B$23+$B$22*Inputs!$F$84)/($B$8*365*A34))*(1+Inputs!$F$87)*(1+Inputs!$F$88) -> 1817.7143 | C34: =($C$19+$C$20+$C$21+($C$22*$C$23+$C$22*Inputs!$F$84)/($C$8*365*A34))*(1+Inputs!$F$87)*(1+Inputs!$F$88) -> 815.3538
A35: 0.5 | B35: =($B$19+$B$20+$B$21+($B$22*$B$23+$B$22*Inputs!$F$84)/($B$8*365*A35))*(1+Inputs!$F$87)*(1+Inputs!$F$88) -> 1432.8328 | C35: =($C$19+$C$20+$C$21+($C$22*$C$23+$C$22*Inputs!$F$84)/($C$8*365*A35))*(1+Inputs!$F$87)*(1+Inputs!$F$88) -> 676.79646
A36: 0.65 | B36: =($B$19+$B$20+$B$21+($B$22*$B$23+$B$22*Inputs!$F$84)/($B$8*365*A36))*(1+Inputs!$F$87)*(1+Inputs!$F$88) -> 1225.5889 | C36: =($C$19+$C$20+$C$21+($C$22*$C$23+$C$22*Inputs!$F$84)/($C$8*365*A36))*(1+Inputs!$F$87)*(1+Inputs!$F$88) -> 602.18866
A37: 0.8 | B37: =($B$19+$B$20+$B$21+($B$22*$B$23+$B$22*Inputs!$F$84)/($B$8*365*A37))*(1+Inputs!$F$87)*(1+Inputs!$F$88) -> 1096.0615 | C37: =($C$19+$C$20+$C$21+($C$22*$C$23+$C$22*Inputs!$F$84)/($C$8*365*A37))*(1+Inputs!$F$87)*(1+Inputs!$F$88) -> 555.55879
A38: 0.95 | B38: =($B$19+$B$20+$B$21+($B$22*$B$23+$B$22*Inputs!$F$84)/($B$8*365*A38))*(1+Inputs!$F$87)*(1+Inputs!$F$88) -> 1007.4375 | C38: =($C$19+$C$20+$C$21+($C$22*$C$23+$C$22*Inputs!$F$84)/($C$8*365*A38))*(1+Inputs!$F$87)*(1+Inputs!$F$88) -> 523.65414
A40: Utilisation needed to reach a target delivered price
A41: Target | B41: Target price (Rs/kg) | C41: Pilot station utilisation needed | D41: Hub station utilisation needed
A42: CNG fuel-parity price (from TCO) | B42: =TCO!$C$82 -> 188.10811 | C42: =IF(B42/((1+Inputs!$F$87)*(1+Inputs!$F$88))-($B$19+$B$20+$B$21)<=0,"not reachable at any utilisation",MIN(9.99,($B$22*$B$23+$B$22*Inputs!$F$84)/($B$8*365)/(B42/((1+Inputs!$F$87)*(1+Inputs!$F$88))-($B$19+$B$20+$B$21)))) -> not reachable at any utilisation | D42: =IF(B42/((1+Inputs!$F$87)*(1+Inputs!$F$88))-($C$19+$C$20+$C$21)<=0,"not reachable at any utilisation",MIN(9.99,($C$22*$C$23+$C$22*Inputs!$F$84)/($C$8*365)/(B42/((1+Inputs!$F$87)*(1+Inputs!$F$88))-($C$19+$C$20+$C$21)))) -> not reachable at any utilisation
A43: Full-TCO break-even versus continuing on CNG (from TCO) | B43: =TCO!$C$79 -> -40.876493 | C43: =IF(B43/((1+Inputs!$F$87)*(1+Inputs!$F$88))-($B$19+$B$20+$B$21)<=0,"not reachable at any utilisation",MIN(9.99,($B$22*$B$23+$B$22*Inputs!$F$84)/($B$8*365)/(B43/((1+Inputs!$F$87)*(1+Inputs!$F$88))-($B$19+$B$20+$B$21)))) -> not reachable at any utilisation | D43: =IF(B43/((1+Inputs!$F$87)*(1+Inputs!$F$88))-($C$19+$C$20+$C$21)<=0,"not reachable at any utilisation",MIN(9.99,($C$22*$C$23+$C$22*Inputs!$F$84)/($C$8*365)/(B43/((1+Inputs!$F$87)*(1+Inputs!$F$88))-($C$19+$C$20+$C$21)))) -> not reachable at any utilisation
A44: Petrol fuel-parity price (from TCO) | B44: =TCO!$C$83 -> 367.56757 | C44: =IF(B44/((1+Inputs!$F$87)*(1+Inputs!$F$88))-($B$19+$B$20+$B$21)<=0,"not reachable at any utilisation",MIN(9.99,($B$22*$B$23+$B$22*Inputs!$F$84)/($B$8*365)/(B44/((1+Inputs!$F$87)*(1+Inputs!$F$88))-($B$19+$B$20+$B$21)))) -> not reachable at any utilisation | D44: =IF(B44/((1+Inputs!$F$87)*(1+Inputs!$F$88))-($C$19+$C$20+$C$21)<=0,"not reachable at any utilisation",MIN(9.99,($C$22*$C$23+$C$22*Inputs!$F$84)/($C$8*365)/(B44/((1+Inputs!$F$87)*(1+Inputs!$F$88))-($C$19+$C$20+$C$21)))) -> 9.99
...

Sheet Market
A1: Bottom-up addressable market and supply-constrained deployment
A2: Funnel from national CNG stock to what stations can actually serve by 2030.
A4: Step | B4: Vehicles | C4: Share applied | D4: Note
A5: CNG vehicles in India, all categories | B5: =Inputs!$F$105 -> 8195000 | D5: Input, class A
A6: Passenger cars among them | B6: =B5*Inputs!$F$106 -> 4507250 | C6: =Inputs!$F$106 -> 0.55 | D6: Share input
A7: Technically eligible: factory-fitted, boot-cylinder layout, under 6 years old at 2028 | B7: =B6*Inputs!$F$107 -> 2253625 | C7: =Inputs!$F$107 -> 0.5 | D7: Excludes older vehicles and layouts without a compatible cylinder bay
A8: In commercial fleets (taxi, aggregator, corporate, institutional) | B8: =B7*Inputs!$F$108 -> 450725 | C8: =Inputs!$F$108 -> 0.2 | D8: Private owners excluded from the first segment
A9: In cities with a hydrogen hub station by 2030 | B9: =B8*Inputs!$F$109 -> 180290 | C9: =Inputs!$F$109 -> 0.4 | D9: Delhi-NCR, Gujarat corridor, Pune-Mumbai, Kochi and similar
A10: Plausible early adopters (return-to-base fleets willing to convert) | B10: =B9*Inputs!$F$110 -> 9014.5 | C10: =Inputs!$F$110 -> 0.05 | D10: Hypothesis to be validated with fleet interviews
A11: Supply-constrained capacity: stations x cars per station | B11: =Inputs!$F$111*H2_Supply!$C$27 -> 1394.3008 | D11: From H2_Supply
A12: Realistic 2030 converted fleet (minimum of demand and supply) | B12: =MIN(B10,B11) -> 1394.3008 | D12: Key output
A13: Round 1 claim for 2030 | B13: 100000 | D13: For comparison

Sheet Pilot_Budget
A1: Programme budget by phase and rollout quantities
A2: Rs. Phases run October 2026 to September 2030. Contingency applied to all phases.
A4: Phase | B4: Line item | C4: Quantity | D4: Unit cost (Rs) | E4: Total (Rs) | F4: Class | G4: Basis
A5: Phase 0: Feasibility and validation (Oct 2026 - Mar 2027)
B6: Regulator and test-agency consultations, route definition (AISC, MoRTH, ARAI/ICAT, PESO) | C6: 1 | D6: 2500000 | E6: =C6*D6 -> 2500000 | F6: C | G6: Engineering time, travel, legal review
B7: Fleet and fuel-partner validation: 30 operator interviews, duty-cycle telematics on 20 cars | C7: 1 | D7: 2500000 | E7: =C7*D7 -> 2500000 | F7: C | G7: Customer demand is a hypothesis; this buys the evidence
B8: Donor inspection, packaging study, CAD and mule vehicle (boot mock-up) | C8: 1 | D8: 4000000 | E8: =C8*D8 -> 4000000 | F8: C
B9: Phase subtotal | E9: =SUM(E6:E8) -> 9000000
A11: Phase 1: Engineering and controlled validation (Apr 2027 - Mar 2028)
B12: Hydrogen engine test-cell time and instrumentation (calibration, NOx, abnormal combustion, 500 h) | C12: 1 | D12: 30000000 | E12: =C12*D12 -> 30000000 | F12: C | G12: Hydrogen test cells exist at ARAI, iCAT and IOCL R&D (S-TEST)
B13: Prototype conversions (3 vehicles) at pilot kit cost | C13: 3 | D13: =BOM!$G$40 -> 774375 | E13: =C13*D13 -> 2323125 | F13: B | G13: BOM pilot cost
B14: Prototype donor vehicles (used Tour S CNG) | C14: 3 | D14: 500000 | E14: =C14*D14 -> 1500000 | F14: C
B15: Storage system qualification samples and tests (burst, cycling, bonfire, drop, permeation) | C15: 1 | D15: 15000000 | E15: =C15*D15 -> 15000000 | F15: C | G15: UN GTR 13 / R134 type tests via supplier and PESO
B16: Vehicle-level safety tests (leak, sled/crash structure, ventilation) at test agency | C16: 1 | D16: 12000000 | E16: =C16*D16 -> 12000000 | F16: C
B17: Engineering team (8 FTE x 12 months) | C17: 96 | D17: 250000 | E17: =C17*D17 -> 24000000 | F17: C | G17: Rs 2.5 lakh per FTE-month fully loaded
B18: Phase subtotal | E18: =SUM(E12:E17) -> 84823125
A20: Phase 2: Certification and pilot build (Apr 2028 - Mar 2029)
B21: Kit type approval and emissions testing at ARAI/ICAT (analogous to CNG kit approval) | C21: 1 | D21: 10000000 | E21: =C21*D21 -> 10000000 | F21: C | G21: Industry reports Rs 40-50 lakh for CNG kit approval (S-TAFEE); hydrogen scope larger
B22: Durability demonstration (2 vehicles x 80,000 km accelerated) | C22: 1 | D22: 8000000 | E22: =C22*D22 -> 8000000 | F22: C
B23: Pilot conversions (30 vehicles) at pilot kit cost | C23: =Inputs!$F$73 -> 30 | D23: =BOM!$G$40 -> 774375 | E23: =C23*D23 -> 23231250 | F23: B | G23: BOM pilot cost
B24: Instrumentation and telematics (30 cars + 20 comparison cars) | C24: 50 | D24: 60000 | E24: =C24*D24 -> 3000000 | F24: C | G24: CAN logger, GPS, hydrogen sensor logging
B25: Hydrogen dispensing point at partner site (compressor, cascade, one dispenser, safety, PESO) | C25: 1 | D25: =Inputs!$F$77 -> 100000000 | E25: =C25*D25 -> 100000000 | F25: B | G25: Input station_capex_pilot; delivered hydrogen, no on-site electrolyser
B26: Workshop upgrade (ventilation, detection, training) at 2 service points | C26: 2 | D26: 4000000 | E26: =C26*D26 -> 8000000 | F26: C | G26: NFPA 2 type ventilation and detection
B27: Phase subtotal | E27: =SUM(E21:E26) -> 152231250
A29: Phase 3: Pilot operation and evaluation (Apr 2029 - Sep 2030)
B30: Hydrogen fuel for 30 cars, 18 months (kg at delivered pilot price) | C30: =Inputs!$F$73*Energy_Range!$B$24*Inputs!$F$10*1.5 -> 29821.399 | D30: =H2_Supply!$B$26 -> 1432.8328 | E30: =C30*D30 -> 42729079 | F30: B | G30: Quantity from Energy_Range and H2_Supply
B31: Operations, safety officer, data analysis and independent evaluation (18 months) | C31: 18 | D31: 1500000 | E31: =C31*D31 -> 27000000 | F31: C | G31: Per month
B32: Quarterly emissions and consumption tests at test agency | C32: 6 | D32: 800000 | E32: =C32*D32 -> 4800000 | F32: C
B33: Insurance, incident reserve and driver training | C33: 1 | D33: 6000000 | E33: =C33*D33 -> 6000000 | F33: C
B34: Phase subtotal | E34: =SUM(E30:E33) -> 80529079
B36: Subtotal all phases | E36: =E9+E18+E27+E34 -> 3.2658345e+08
B37: Contingency (share of subtotal) | C37: 0.15 | E37: =E36*C37 -> 48987518
B38: Total programme budget to September 2030 (Rs) | E38: =E36+E37 -> 3.7557097e+08
B39: Total in Rs crore | E39: =E38/10000000 -> 37.557097
B41: Proposed funding split (shares are proposals, not commitments)
B42: Suzuki R&D Center India / Maruti Suzuki (engineering, prototypes, test cells) | C42: 0.4 | E42: =C42*E38 -> 1.5022839e+08
B43: Public support sought (MNRE NGHM R&D or pilot scheme, state hydrogen policy) | C43: 0.35 | E43: =C43*E38 -> 1.3144984e+08
B44: Fuel and station partner (OMC or gas utility): dispensing point | C44: 0.15 | E44: =C44*E38 -> 56335646
B45: Fleet partner (vehicles, drivers, operations) | C45: 0.1 | E45: =C45*E38 -> 37557097
B47: Rollout quantities (conditional expansion after gates)
...

Sheet Emissions
A1: Emissions per km and at fleet scale, same service boundary for all options
A2: Tailpipe, well-to-tank and amortised manufacturing. Hydrogen combustion emits NOx (not CO2); see NOx rows.
A4: Quantity | B4: Value | C4: Unit | D4: Note
A5: A: CNG tailpipe CO2 per km (CNG share of km) | B5: =(1-Inputs!$F$22)/Inputs!$F$19*Inputs!$F$91*1000 -> 102.22 | C5: g/km
A6: A: petrol tailpipe CO2 per km (petrol share) | B6: =Inputs!$F$22/Inputs!$F$21*Inputs!$F$93*1000 -> 7.5666667 | C6: g/km
A7: A: well-to-tank CO2e per km | B7: =B5*Inputs!$F$92+B6*Inputs!$F$94 -> 27.068333 | C7: g/km | D7: Uplift factors on tailpipe
A8: A: total well-to-wheel CO2e per km | B8: =B5+B6+B7 -> 136.855 | C8: g/km | D8: Key
A9: B: hydrogen share of km | B9: =Inputs!$F$34 -> 0.65 | C9: fraction
A10: B: hydrogen consumption | B10: =Inputs!$F$33 -> 1.85 | C10: kg/100 km
A11: B: well-to-wheel CO2e per km, green hydrogen | B11: =B9*B10/100*Inputs!$F$95*1000+(1-B9)/Inputs!$F$21*Inputs!$F$93*(1+Inputs!$F$94)*1000 -> 87.61 | C11: g/km | D11: Tailpipe CO2 on hydrogen km is zero; petrol backup km counted
A12: B: well-to-wheel CO2e per km, grid-electrolysis hydrogen | B12: =B9*B10/100*Inputs!$F$96*1000+(1-B9)/Inputs!$F$21*Inputs!$F$93*(1+Inputs!$F$94)*1000 -> 532.535 | C12: g/km | D12: Reversal case
A13: B: well-to-wheel CO2e per km, grey (SMR) hydrogen | B13: =B9*B10/100*Inputs!$F$97*1000+(1-B9)/Inputs!$F$21*Inputs!$F$93*(1+Inputs!$F$94)*1000 -> 207.86 | C13: g/km | D13: Reversal case
A14: B: retrofit kit manufacturing amortised over horizon km | B14: =Inputs!$F$102*1000000/(Inputs!$F$10*Inputs!$F$11*Inputs!$F$8) -> 1.8145527 | C14: g/km
A15: B: total per km incl. kit manufacturing, green hydrogen | B15: =B11+B14 -> 89.424553 | C15: g/km | D15: Key
A16: C: BEV electricity per km at 2025 grid factor | B16: =Inputs!$F$46/100*Inputs!$F$98*1000 -> 129 | C16: g/km | D16: Metered kWh already include charging losses
A17: C: BEV electricity per km at 2030 grid factor | B17: =Inputs!$F$46/100*Inputs!$F$99*1000 -> 87 | C17: g/km
A18: C: BEV manufacturing amortised per km | B18: =Inputs!$F$100*1000000/Inputs!$F$101 -> 46.666667 | C18: g/km | D18: New vehicle and battery; counterfactual is keeping the donor
A19: C: total per km incl. manufacturing, 2025 grid | B19: =B16+B18 -> 175.66667 | C19: g/km | D19: Key
A20: C: total per km incl. manufacturing, 2030 grid | B20: =B17+B18 -> 133.66667 | C20: g/km | D20: Key
A21: Reduction of B (green) versus A | B21: =1-B15/B8 -> 0.34657446 | C21: fraction
A22: Reduction of C (2030 grid) versus A | B22: =1-B20/B8 -> 0.023297164 | C22: fraction | D22: Negative = BEV replacement emits more than continuing on CNG within the horizon
A23: Grid factor at which BEV equals green-hydrogen retrofit per km | B23: =(B15-B18)/(Inputs!$F$46/100)/1000 -> 0.28505257 | C23: kg CO2/kWh | D23: Reversal threshold
A24: Hydrogen carbon intensity at which retrofit equals continuing on CNG | B24: =(B8-(1-B9)/Inputs!$F$21*Inputs!$F$93*(1+Inputs!$F$94)*1000-B14)/(B9*B10/100*1000) -> 5.9443199 | C24: kg CO2e/kg H2 | D24: Retrofit is worse than CNG above this hydrogen carbon intensity
A25: Per-car CO2e avoided over the horizon, B (green) versus A | B25: =(B8-B15)*Inputs!$F$10*Inputs!$F$11*Inputs!$F$8/1000000 -> 13.06946 | C25: t CO2e
A26: Abatement cost of the retrofit versus continuing on CNG (active scenario) | B26: =IF(B25>0,TCO!$C$65/B25,"n/a") -> 128869.44 | C26: Rs per t CO2e | D26: Extra ownership cost divided by CO2e avoided
A27: Pilot fleet (30 cars) CO2e avoided per year, green hydrogen | B27: =Inputs!$F$73*(B8-B15)*Inputs!$F$10*Inputs!$F$11/1000000 -> 78.416759 | C27: t CO2e/yr
A28: 2030 converted fleet CO2e avoided per year, green hydrogen | B28: =Market!$B$12*(B8-B15)*Inputs!$F$10*Inputs!$F$11/1000000 -> 3644.5516 | C28: t CO2e/yr | D28: Supply-constrained fleet from Market
A29: 2030 converted fleet hydrogen demand | B29: =Market!$B$12*Energy_Range!$B$24*Inputs!$F$10/1000 -> 924 | C29: t/yr
A30: NOx: BS-VI limit for M1 petrol | B30: =Inputs!$F$103 -> 60 | C30: mg/km | D30: Applies to the converted vehicle by analogy; test procedure for H2-ICE retrofits does not exist yet
A31: NOx: lean hydrogen combustion engine-out (lambda above 2) reported range | B31: 5 to 20 | C31: mg/km class | D31: Literature indicates near-zero NOx above lambda about 2 (S-NOX); transients and high load exceed it, hence aftertreatment provision

Sheet Sensitivities
A1: When does the recommendation change? Grids use the closed-form decomposition from the TCO sheet (same trajectory shape, active scenario for all other inputs).
A2: Values in Rs lakh over the horizon; negative = the hydrogen retrofit is cheaper than the comparator.
A4: Grid 1: retrofit minus continue-on-CNG (Rs lakh) by year-1 delivered hydrogen price (rows) and annual km (columns)
A5: Rs/kg \ km/yr | B5: 30000 | C5: 40000 | D5: 50000 | E5: 60000 | F5: 70000
A6: 100 | B6: =(TCO!$C$90+TCO!$C$91*B$5+TCO!$C$92*B$5*$A6)/100000 -> 3.0272672 | C6: =(TCO!$C$90+TCO!$C$91*C$5+TCO!$C$92*C$5*$A6)/100000 -> 2.9454084 | D6: =(TCO!$C$90+TCO!$C$91*D$5+TCO!$C$92*D$5*$A6)/100000 -> 2.8635496 | E6: =(TCO!$C$90+TCO!$C$91*E$5+TCO!$C$92*E$5*$A6)/100000 -> 2.7816908 | F6: =(TCO!$C$90+TCO!$C$91*F$5+TCO!$C$92*F$5*$A6)/100000 -> 2.699832
A7: 150 | B7: =(TCO!$C$90+TCO!$C$91*B$5+TCO!$C$92*B$5*$A7)/100000 -> 3.5724425 | C7: =(TCO!$C$90+TCO!$C$91*C$5+TCO!$C$92*C$5*$A7)/100000 -> 3.6723089 | D7: =(TCO!$C$90+TCO!$C$91*D$5+TCO!$C$92*D$5*$A7)/100000 -> 3.7721752 | E7: =(TCO!$C$90+TCO!$C$91*E$5+TCO!$C$92*E$5*$A7)/100000 -> 3.8720415 | F7: =(TCO!$C$90+TCO!$C$91*F$5+TCO!$C$92*F$5*$A7)/100000 -> 3.9719078
A8: 200 | B8: =(TCO!$C$90+TCO!$C$91*B$5+TCO!$C$92*B$5*$A8)/100000 -> 4.1176179 | C8: =(TCO!$C$90+TCO!$C$91*C$5+TCO!$C$92*C$5*$A8)/100000 -> 4.3992093 | D8: =(TCO!$C$90+TCO!$C$91*D$5+TCO!$C$92*D$5*$A8)/100000 -> 4.6808007 | E8: =(TCO!$C$90+TCO!$C$91*E$5+TCO!$C$92*E$5*$A8)/100000 -> 4.9623922 | F8: =(TCO!$C$90+TCO!$C$91*F$5+TCO!$C$92*F$5*$A8)/100000 -> 5.2439836
A9: 250 | B9: =(TCO!$C$90+TCO!$C$91*B$5+TCO!$C$92*B$5*$A9)/100000 -> 4.6627932 | C9: =(TCO!$C$90+TCO!$C$91*C$5+TCO!$C$92*C$5*$A9)/100000 -> 5.1261097 | D9: =(TCO!$C$90+TCO!$C$91*D$5+TCO!$C$92*D$5*$A9)/100000 -> 5.5894263 | E9: =(TCO!$C$90+TCO!$C$91*E$5+TCO!$C$92*E$5*$A9)/100000 -> 6.0527428 | F9: =(TCO!$C$90+TCO!$C$91*F$5+TCO!$C$92*F$5*$A9)/100000 -> 6.5160594
A10: 300 | B10: =(TCO!$C$90+TCO!$C$91*B$5+TCO!$C$92*B$5*$A10)/100000 -> 5.2079685 | C10: =(TCO!$C$90+TCO!$C$91*C$5+TCO!$C$92*C$5*$A10)/100000 -> 5.8530102 | D10: =(TCO!$C$90+TCO!$C$91*D$5+TCO!$C$92*D$5*$A10)/100000 -> 6.4980518 | E10: =(TCO!$C$90+TCO!$C$91*E$5+TCO!$C$92*E$5*$A10)/100000 -> 7.1430935 | F10: =(TCO!$C$90+TCO!$C$91*F$5+TCO!$C$92*F$5*$A10)/100000 -> 7.7881352
A11: 400 | B11: =(TCO!$C$90+TCO!$C$91*B$5+TCO!$C$92*B$5*$A11)/100000 -> 6.2983192 | C11: =(TCO!$C$90+TCO!$C$91*C$5+TCO!$C$92*C$5*$A11)/100000 -> 7.3068111 | D11: =(TCO!$C$90+TCO!$C$91*D$5+TCO!$C$92*D$5*$A11)/100000 -> 8.315303 | E11: =(TCO!$C$90+TCO!$C$91*E$5+TCO!$C$92*E$5*$A11)/100000 -> 9.3237948 | F11: =(TCO!$C$90+TCO!$C$91*F$5+TCO!$C$92*F$5*$A11)/100000 -> 10.332287
A12: 500 | B12: =(TCO!$C$90+TCO!$C$91*B$5+TCO!$C$92*B$5*$A12)/100000 -> 7.3886699 | C12: =(TCO!$C$90+TCO!$C$91*C$5+TCO!$C$92*C$5*$A12)/100000 -> 8.760612 | D12: =(TCO!$C$90+TCO!$C$91*D$5+TCO!$C$92*D$5*$A12)/100000 -> 10.132554 | E12: =(TCO!$C$90+TCO!$C$91*E$5+TCO!$C$92*E$5*$A12)/100000 -> 11.504496 | F12: =(TCO!$C$90+TCO!$C$91*F$5+TCO!$C$92*F$5*$A12)/100000 -> 12.876438
A13: 600 | B13: =(TCO!$C$90+TCO!$C$91*B$5+TCO!$C$92*B$5*$A13)/100000 -> 8.4790205 | C13: =(TCO!$C$90+TCO!$C$91*C$5+TCO!$C$92*C$5*$A13)/100000 -> 10.214413 | D13: =(TCO!$C$90+TCO!$C$91*D$5+TCO!$C$92*D$5*$A13)/100000 -> 11.949805 | E13: =(TCO!$C$90+TCO!$C$91*E$5+TCO!$C$92*E$5*$A13)/100000 -> 13.685198 | F13: =(TCO!$C$90+TCO!$C$91*F$5+TCO!$C$92*F$5*$A13)/100000 -> 15.42059
A14: 800 | B14: =(TCO!$C$90+TCO!$C$91*B$5+TCO!$C$92*B$5*$A14)/100000 -> 10.659722 | C14: =(TCO!$C$90+TCO!$C$91*C$5+TCO!$C$92*C$5*$A14)/100000 -> 13.122015 | D14: =(TCO!$C$90+TCO!$C$91*D$5+TCO!$C$92*D$5*$A14)/100000 -> 15.584307 | E14: =(TCO!$C$90+TCO!$C$91*E$5+TCO!$C$92*E$5*$A14)/100000 -> 18.0466 | F14: =(TCO!$C$90+TCO!$C$91*F$5+TCO!$C$92*F$5*$A14)/100000 -> 20.508893
A17: Grid 2: retrofit minus sell-and-buy-BEV (Rs lakh) by year-1 hydrogen price (rows) and BEV price in Rs lakh (columns)
A18: Rs/kg \ BEV price | B18: 9 | C18: 10 | D18: 11 | E18: 12 | F18: 13 | G18: 14
A19: 100 | B19: =(TCO!$C$94-(B$18*100000-Inputs!$F$44)+TCO!$C$95*TCO!$D$6+TCO!$C$92*TCO!$D$6*$A19)/100000 -> 3.7139401 | C19: =(TCO!$C$94-(C$18*100000-Inputs!$F$44)+TCO!$C$95*TCO!$D$6+TCO!$C$92*TCO!$D$6*$A19)/100000 -> 2.7139401 | D19: =(TCO!$C$94-(D$18*100000-Inputs!$F$44)+TCO!$C$95*TCO!$D$6+TCO!$C$92*TCO!$D$6*$A19)/100000 -> 1.7139401 | E19: =(TCO!$C$94-(E$18*100000-Inputs!$F$44)+TCO!$C$95*TCO!$D$6+TCO!$C$92*TCO!$D$6*$A19)/100000 -> 0.71394015 | F19: =(TCO!$C$94-(F$18*100000-Inputs!$F$44)+TCO!$C$95*TCO!$D$6+TCO!$C$92*TCO!$D$6*$A19)/100000 -> -0.28605985 | G19: =(TCO!$C$94-(G$18*100000-Inputs!$F$44)+TCO!$C$95*TCO!$D$6+TCO!$C$92*TCO!$D$6*$A19)/100000 -> -1.2860599
A20: 150 | B20: =(TCO!$C$94-(B$18*100000-Inputs!$F$44)+TCO!$C$95*TCO!$D$6+TCO!$C$92*TCO!$D$6*$A20)/100000 -> 4.7154272 | C20: =(TCO!$C$94-(C$18*100000-Inputs!$F$44)+TCO!$C$95*TCO!$D$6+TCO!$C$92*TCO!$D$6*$A20)/100000 -> 3.7154272 | D20: =(TCO!$C$94-(D$18*100000-Inputs!$F$44)+TCO!$C$95*TCO!$D$6+TCO!$C$92*TCO!$D$6*$A20)/100000 -> 2.7154272 | E20: =(TCO!$C$94-(E$18*100000-Inputs!$F$44)+TCO!$C$95*TCO!$D$6+TCO!$C$92*TCO!$D$6*$A20)/100000 -> 1.7154272 | F20: =(TCO!$C$94-(F$18*100000-Inputs!$F$44)+TCO!$C$95*TCO!$D$6+TCO!$C$92*TCO!$D$6*$A20)/100000 -> 0.71542723 | G20: =(TCO!$C$94-(G$18*100000-Inputs!$F$44)+TCO!$C$95*TCO!$D$6+TCO!$C$92*TCO!$D$6*$A20)/100000 -> -0.28457277
A21: 200 | B21: =(TCO!$C$94-(B$18*100000-Inputs!$F$44)+TCO!$C$95*TCO!$D$6+TCO!$C$92*TCO!$D$6*$A21)/100000 -> 5.7169143 | C21: =(TCO!$C$94-(C$18*100000-Inputs!$F$44)+TCO!$C$95*TCO!$D$6+TCO!$C$92*TCO!$D$6*$A21)/100000 -> 4.7169143 | D21: =(TCO!$C$94-(D$18*100000-Inputs!$F$44)+TCO!$C$95*TCO!$D$6+TCO!$C$92*TCO!$D$6*$A21)/100000 -> 3.7169143 | E21: =(TCO!$C$94-(E$18*100000-Inputs!$F$44)+TCO!$C$95*TCO!$D$6+TCO!$C$92*TCO!$D$6*$A21)/100000 -> 2.7169143 | F21: =(TCO!$C$94-(F$18*100000-Inputs!$F$44)+TCO!$C$95*TCO!$D$6+TCO!$C$92*TCO!$D$6*$A21)/100000 -> 1.7169143 | G21: =(TCO!$C$94-(G$18*100000-Inputs!$F$44)+TCO!$C$95*TCO!$D$6+TCO!$C$92*TCO!$D$6*$A21)/100000 -> 0.71691432
A22: 250 | B22: =(TCO!$C$94-(B$18*100000-Inputs!$F$44)+TCO!$C$95*TCO!$D$6+TCO!$C$92*TCO!$D$6*$A22)/100000 -> 6.7184014 | C22: =(TCO!$C$94-(C$18*100000-Inputs!$F$44)+TCO!$C$95*TCO!$D$6+TCO!$C$92*TCO!$D$6*$A22)/100000 -> 5.7184014 | D22: =(TCO!$C$94-(D$18*100000-Inputs!$F$44)+TCO!$C$95*TCO!$D$6+TCO!$C$92*TCO!$D$6*$A22)/100000 -> 4.7184014 | E22: =(TCO!$C$94-(E$18*100000-Inputs!$F$44)+TCO!$C$95*TCO!$D$6+TCO!$C$92*TCO!$D$6*$A22)/100000 -> 3.7184014 | F22: =(TCO!$C$94-(F$18*100000-Inputs!$F$44)+TCO!$C$95*TCO!$D$6+TCO!$C$92*TCO!$D$6*$A22)/100000 -> 2.7184014 | G22: =(TCO!$C$94-(G$18*100000-Inputs!$F$44)+TCO!$C$95*TCO!$D$6+TCO!$C$92*TCO!$D$6*$A22)/100000 -> 1.7184014
A23: 300 | B23: =(TCO!$C$94-(B$18*100000-Inputs!$F$44)+TCO!$C$95*TCO!$D$6+TCO!$C$92*TCO!$D$6*$A23)/100000 -> 7.7198885 | C23: =(TCO!$C$94-(C$18*100000-Inputs!$F$44)+TCO!$C$95*TCO!$D$6+TCO!$C$92*TCO!$D$6*$A23)/100000 -> 6.7198885 | D23: =(TCO!$C$94-(D$18*100000-Inputs!$F$44)+TCO!$C$95*TCO!$D$6+TCO!$C$92*TCO!$D$6*$A23)/100000 -> 5.7198885 | E23: =(TCO!$C$94-(E$18*100000-Inputs!$F$44)+TCO!$C$95*TCO!$D$6+TCO!$C$92*TCO!$D$6*$A23)/100000 -> 4.7198885 | F23: =(TCO!$C$94-(F$18*100000-Inputs!$F$44)+TCO!$C$95*TCO!$D$6+TCO!$C$92*TCO!$D$6*$A23)/100000 -> 3.7198885 | G23: =(TCO!$C$94-(G$18*100000-Inputs!$F$44)+TCO!$C$95*TCO!$D$6+TCO!$C$92*TCO!$D$6*$A23)/100000 -> 2.7198885
A24: 400 | B24: =(TCO!$C$94-(B$18*100000-Inputs!$F$44)+TCO!$C$95*TCO!$D$6+TCO!$C$92*TCO!$D$6*$A24)/100000 -> 9.7228627 | C24: =(TCO!$C$94-(C$18*100000-Inputs!$F$44)+TCO!$C$95*TCO!$D$6+TCO!$C$92*TCO!$D$6*$A24)/100000 -> 8.7228627 | D24: =(TCO!$C$94-(D$18*100000-Inputs!$F$44)+TCO!$C$95*TCO!$D$6+TCO!$C$92*TCO!$D$6*$A24)/100000 -> 7.7228627 | E24: =(TCO!$C$94-(E$18*100000-Inputs!$F$44)+TCO!$C$95*TCO!$D$6+TCO!$C$92*TCO!$D$6*$A24)/100000 -> 6.7228627 | F24: =(TCO!$C$94-(F$18*100000-Inputs!$F$44)+TCO!$C$95*TCO!$D$6+TCO!$C$92*TCO!$D$6*$A24)/100000 -> 5.7228627 | G24: =(TCO!$C$94-(G$18*100000-Inputs!$F$44)+TCO!$C$95*TCO!$D$6+TCO!$C$92*TCO!$D$6*$A24)/100000 -> 4.7228627
A25: 500 | B25: =(TCO!$C$94-(B$18*100000-Inputs!$F$44)+TCO!$C$95*TCO!$D$6+TCO!$C$92*TCO!$D$6*$A25)/100000 -> 11.725837 | C25: =(TCO!$C$94-(C$18*100000-Inputs!$F$44)+TCO!$C$95*TCO!$D$6+TCO!$C$92*TCO!$D$6*$A25)/100000 -> 10.725837 | D25: =(TCO!$C$94-(D$18*100000-Inputs!$F$44)+TCO!$C$95*TCO!$D$6+TCO!$C$92*TCO!$D$6*$A25)/100000 -> 9.7258368 | E25: =(TCO!$C$94-(E$18*100000-Inputs!$F$44)+TCO!$C$95*TCO!$D$6+TCO!$C$92*TCO!$D$6*$A25)/100000 -> 8.7258368 | F25: =(TCO!$C$94-(F$18*100000-Inputs!$F$44)+TCO!$C$95*TCO!$D$6+TCO!$C$92*TCO!$D$6*$A25)/100000 -> 7.7258368 | G25: =(TCO!$C$94-(G$18*100000-Inputs!$F$44)+TCO!$C$95*TCO!$D$6+TCO!$C$92*TCO!$D$6*$A25)/100000 -> 6.7258368
A26: 600 | B26: =(TCO!$C$94-(B$18*100000-Inputs!$F$44)+TCO!$C$95*TCO!$D$6+TCO!$C$92*TCO!$D$6*$A26)/100000 -> 13.728811 | C26: =(TCO!$C$94-(C$18*100000-Inputs!$F$44)+TCO!$C$95*TCO!$D$6+TCO!$C$92*TCO!$D$6*$A26)/100000 -> 12.728811 | D26: =(TCO!$C$94-(D$18*100000-Inputs!$F$44)+TCO!$C$95*TCO!$D$6+TCO!$C$92*TCO!$D$6*$A26)/100000 -> 11.728811 | E26: =(TCO!$C$94-(E$18*100000-Inputs!$F$44)+TCO!$C$95*TCO!$D$6+TCO!$C$92*TCO!$D$6*$A26)/100000 -> 10.728811 | F26: =(TCO!$C$94-(F$18*100000-Inputs!$F$44)+TCO!$C$95*TCO!$D$6+TCO!$C$92*TCO!$D$6*$A26)/100000 -> 9.728811 | G26: =(TCO!$C$94-(G$18*100000-Inputs!$F$44)+TCO!$C$95*TCO!$D$6+TCO!$C$92*TCO!$D$6*$A26)/100000 -> 8.728811
A27: 800 | B27: =(TCO!$C$94-(B$18*100000-Inputs!$F$44)+TCO!$C$95*TCO!$D$6+TCO!$C$92*TCO!$D$6*$A27)/100000 -> 17.734759 | C27: =(TCO!$C$94-(C$18*100000-Inputs!$F$44)+TCO!$C$95*TCO!$D$6+TCO!$C$92*TCO!$D$6*$A27)/100000 -> 16.734759 | D27: =(TCO!$C$94-(D$18*100000-Inputs!$F$44)+TCO!$C$95*TCO!$D$6+TCO!$C$92*TCO!$D$6*$A27)/100000 -> 15.734759 | E27: =(TCO!$C$94-(E$18*100000-Inputs!$F$44)+TCO!$C$95*TCO!$D$6+TCO!$C$92*TCO!$D$6*$A27)/100000 -> 14.734759 | F27: =(TCO!$C$94-(F$18*100000-Inputs!$F$44)+TCO!$C$95*TCO!$D$6+TCO!$C$92*TCO!$D$6*$A27)/100000 -> 13.734759 | G27: =(TCO!$C$94-(G$18*100000-Inputs!$F$44)+TCO!$C$95*TCO!$D$6+TCO!$C$92*TCO!$D$6*$A27)/100000 -> 12.734759
A30: Grid 3: retrofit minus continue-on-CNG (Rs lakh) by year-1 hydrogen price (rows) and installed kit cost in Rs lakh (columns)
A31: Rs/kg \ kit cost | B31: 1.5 | C31: 2 | D31: 2.5 | E31: 3 | F31: 4 | G31: 6
A32: 100 | B32: =(TCO!$C$90+(B$31*100000-Inputs!$F$28)+TCO!$C$91*TCO!$D$6+TCO!$C$92*TCO!$D$6*$A32)/100000 -> 1.100485 | C32: =(TCO!$C$90+(C$31*100000-Inputs!$F$28)+TCO!$C$91*TCO!$D$6+TCO!$C$92*TCO!$D$6*$A32)/100000 -> 1.600485 | D32: =(TCO!$C$90+(D$31*100000-Inputs!$F$28)+TCO!$C$91*TCO!$D$6+TCO!$C$92*TCO!$D$6*$A32)/100000 -> 2.100485 | E32: =(TCO!$C$90+(E$31*100000-Inputs!$F$28)+TCO!$C$91*TCO!$D$6+TCO!$C$92*TCO!$D$6*$A32)/100000 -> 2.600485 | F32: =(TCO!$C$90+(F$31*100000-Inputs!$F$28)+TCO!$C$91*TCO!$D$6+TCO!$C$92*TCO!$D$6*$A32)/100000 -> 3.600485 | G32: =(TCO!$C$90+(G$31*100000-Inputs!$F$28)+TCO!$C$91*TCO!$D$6+TCO!$C$92*TCO!$D$6*$A32)/100000 -> 5.600485
A33: 150 | B33: =(TCO!$C$90+(B$31*100000-Inputs!$F$28)+TCO!$C$91*TCO!$D$6+TCO!$C$92*TCO!$D$6*$A33)/100000 -> 2.1019721 | C33: =(TCO!$C$90+(C$31*100000-Inputs!$F$28)+TCO!$C$91*TCO!$D$6+TCO!$C$92*TCO!$D$6*$A33)/100000 -> 2.6019721 | D33: =(TCO!$C$90+(D$31*100000-Inputs!$F$28)+TCO!$C$91*TCO!$D$6+TCO!$C$92*TCO!$D$6*$A33)/100000 -> 3.1019721 | E33: =(TCO!$C$90+(E$31*100000-Inputs!$F$28)+TCO!$C$91*TCO!$D$6+TCO!$C$92*TCO!$D$6*$A33)/100000 -> 3.6019721 | F33: =(TCO!$C$90+(F$31*100000-Inputs!$F$28)+TCO!$C$91*TCO!$D$6+TCO!$C$92*TCO!$D$6*$A33)/100000 -> 4.6019721 | G33: =(TCO!$C$90+(G$31*100000-Inputs!$F$28)+TCO!$C$91*TCO!$D$6+TCO!$C$92*TCO!$D$6*$A33)/100000 -> 6.6019721
A34: 200 | B34: =(TCO!$C$90+(B$31*100000-Inputs!$F$28)+TCO!$C$91*TCO!$D$6+TCO!$C$92*TCO!$D$6*$A34)/100000 -> 3.1034592 | C34: =(TCO!$C$90+(C$31*100000-Inputs!$F$28)+TCO!$C$91*TCO!$D$6+TCO!$C$92*TCO!$D$6*$A34)/100000 -> 3.6034592 | D34: =(TCO!$C$90+(D$31*100000-Inputs!$F$28)+TCO!$C$91*TCO!$D$6+TCO!$C$92*TCO!$D$6*$A34)/100000 -> 4.1034592 | E34: =(TCO!$C$90+(E$31*100000-Inputs!$F$28)+TCO!$C$91*TCO!$D$6+TCO!$C$92*TCO!$D$6*$A34)/100000 -> 4.6034592 | F34: =(TCO!$C$90+(F$31*100000-Inputs!$F$28)+TCO!$C$91*TCO!$D$6+TCO!$C$92*TCO!$D$6*$A34)/100000 -> 5.6034592 | G34: =(TCO!$C$90+(G$31*100000-Inputs!$F$28)+TCO!$C$91*TCO!$D$6+TCO!$C$92*TCO!$D$6*$A34)/100000 -> 7.6034592
A35: 250 | B35: =(TCO!$C$90+(B$31*100000-Inputs!$F$28)+TCO!$C$91*TCO!$D$6+TCO!$C$92*TCO!$D$6*$A35)/100000 -> 4.1049462 | C35: =(TCO!$C$90+(C$31*100000-Inputs!$F$28)+TCO!$C$91*TCO!$D$6+TCO!$C$92*TCO!$D$6*$A35)/100000 -> 4.6049462 | D35: =(TCO!$C$90+(D$31*100000-Inputs!$F$28)+TCO!$C$91*TCO!$D$6+TCO!$C$92*TCO!$D$6*$A35)/100000 -> 5.1049462 | E35: =(TCO!$C$90+(E$31*100000-Inputs!$F$28)+TCO!$C$91*TCO!$D$6+TCO!$C$92*TCO!$D$6*$A35)/100000 -> 5.6049462 | F35: =(TCO!$C$90+(F$31*100000-Inputs!$F$28)+TCO!$C$91*TCO!$D$6+TCO!$C$92*TCO!$D$6*$A35)/100000 -> 6.6049462 | G35: =(TCO!$C$90+(G$31*100000-Inputs!$F$28)+TCO!$C$91*TCO!$D$6+TCO!$C$92*TCO!$D$6*$A35)/100000 -> 8.6049462
A36: 300 | B36: =(TCO!$C$90+(B$31*100000-Inputs!$F$28)+TCO!$C$91*TCO!$D$6+TCO!$C$92*TCO!$D$6*$A36)/100000 -> 5.1064333 | C36: =(TCO!$C$90+(C$31*100000-Inputs!$F$28)+TCO!$C$91*TCO!$D$6+TCO!$C$92*TCO!$D$6*$A36)/100000 -> 5.6064333 | D36: =(TCO!$C$90+(D$31*100000-Inputs!$F$28)+TCO!$C$91*TCO!$D$6+TCO!$C$92*TCO!$D$6*$A36)/100000 -> 6.1064333 | E36: =(TCO!$C$90+(E$31*100000-Inputs!$F$28)+TCO!$C$91*TCO!$D$6+TCO!$C$92*TCO!$D$6*$A36)/100000 -> 6.6064333 | F36: =(TCO!$C$90+(F$31*100000-Inputs!$F$28)+TCO!$C$91*TCO!$D$6+TCO!$C$92*TCO!$D$6*$A36)/100000 -> 7.6064333 | G36: =(TCO!$C$90+(G$31*100000-Inputs!$F$28)+TCO!$C$91*TCO!$D$6+TCO!$C$92*TCO!$D$6*$A36)/100000 -> 9.6064333
