Workbook

Sheet README
A1: PROJECT SATOSHI GATE — Paytm × Liminal Custody Solutions: transaction & accretion/dilution model
B2: Prepared for the Board / Investment Committee discussion. All ₹ figures in Cr unless stated. Model date: 23 Sep 2026.
B4: Purpose | C4: One workbook that traces every decision-relevant number from a labelled input to an output: valuation → FCF → leverage → EPS → transaction economics → decision thresholds.
B5: Source of truth | C5: The case document 'Project Satoshi Gate' (5 pp.) and 'Addendum 1: Modeling Inputs and Clarifications' (1 p.). Case inputs are never replaced by outside figures. External facts are used only for context, comparables and regulatory sequencing, and are labelled as such.
B6: Colour code | C6: Blue text on light-blue fill = CASE FACT (from the case document, cell comment gives the section). Blue text on yellow fill = TEAM / ANALYST ASSUMPTION (changeable). Blue text on orange fill = EXTERNAL FACT (sourced, dated). Black = formula. Green = link to another sheet. Green fill = key output.
B7: How to use | C7: Change the levers on 'Dashboard' (growth case, churn, capital drag level and interpretation, financing mix, minority stake terms, WACC). Every downstream sheet recalculates. Do not type over black formula cells.
B8: Sheet map | C8: Dashboard (levers + headline outputs) · Inputs (case facts, calculations on case facts, team assumptions) · Liminal_Ops (10-yr operating forecast, standalone and post-churn) · DCF (standalone value, what-you-need-to-believe, WACC×growth and churn×growth grids) · Financing (cash/debt/equity mixes, leverage, liquidity, cost of funds) · Sources_Uses · Accretion (EPS Y0–Y3 from the ₹7.50 baseline; accounting vs economic view) · Capital_Drag (three readings of the ₹750 Cr drag, ₹500–1,250 Cr grid, break-even drag, MDR offset) · Churn (0–60% grid, effective multiple, breakevens, maximum acceptable churn) · Structures (full / minority / JV / walk-away / hybrid side by side) · Earnout (retention-linked consideration, call-option strike, escrow) · Scenarios (base, upside, moderate, severe, break; dominant-variable test) · Thresholds (decision triggers, computed) · Synergies (tree with incrementality tests) · Comps · Precedents · Regulatory (external, sourced) · Audit_Trail.
B9: Conventions | C9: Y0 = trailing twelve months at signing (mid-Sep 2026). Y1 = first 12 months after close. Liminal revenue is modelled as ARR run-rate. Percentages stored as fractions. Negative = outflow. Breakeven year = first year in which the incremental line is ≥ 0 (PAT: accounting; FCF: cash, after capital drag and cost of funds).
B10: Evidence classes | C10: CASE FACT · CALCULATION (arithmetic on case facts) · ANALYST ASSUMPTION · EXTERNAL FACT (sourced) · INFERENCE · UNKNOWN. Every important number on the Audit_Trail sheet carries one of these tags.
B11: Not modelled | C11: Purchase-price-allocation amortisation is shown as a switchable line (default on for reported EPS, off for cash EPS). Liminal's tax-loss carry-forwards are ignored (conservative). Paytm standalone earnings are held flat at ₹480 Cr unless the growth lever is changed, so that the deal effect is isolated. Currency: ₹ only; the ~$470M is the case's own conversion.

Sheet Dashboard
A1: DASHBOARD — key levers (yellow) and headline outputs (green). Change a lever; every sheet recalculates.
A2: Levers are TEAM ASSUMPTIONS / scenario choices. Case facts live on 'Inputs' and are not levers.
A4: 1. SCENARIO LEVERS
A5: Liminal growth case (1 = bear, 2 = base, 3 = bull) | B5: 2 | G5: Selects a_g_bear / a_g_base / a_g_bull.
A6: ARR churn within 12 months of a FULL acquisition (case range 30–45%) | B6: 0.375 | G6: Case §3.1 range 30–45%; base = midpoint 37.5%. Set 0% to see the no-churn case.
A7: Recurring capital drag at full ownership (₹ Cr/yr) — case value 750; grid 500 / 750 / 1,000 / 1,250 | B7: 750 | G7: Case §3.2. Flex to test.
A8: Capital drag reading (1 = fixed cash drag as the case states; 2 = scales with retained/growing custodied assets; 3 = P&L operating cost) | B8: 1 | G8: See Capital_Drag for the three readings. Reading 1 is the case's literal wording.
A9: Discount rate for Liminal cash flows | B9: =a_wacc_base -> 0.13 | G9: Defaults to the Inputs base; overwrite to flex.
A10: Credit the ₹115 Cr MDR to the DEAL's breakeven? (0 = no: standalone Paytm item; 1 = yes: case-style offset) | B10: 0 | G10: The MDR accrues to Paytm with or without Liminal. Both views are always shown; this lever picks which one the verdict lines use.
A11: → Selected Liminal growth rate | B11: =CHOOSE(lv_gcase,a_g_bear,a_g_base,a_g_bull) -> 0.2
A13: 2. FINANCING LEVERS — full acquisition (₹4,000 Cr headline; case: ₹2,100 Cr cash portion from cash, new debt or mix; ₹1,900 Cr in Paytm shares)
A14: Cash consideration funded from balance-sheet cash (₹ Cr) | B14: 2100 | G14: Case headline: ₹2,100 Cr from existing cash.
A15: Cash consideration funded from new debt (₹ Cr) | B15: 0 | G15: Case headline: none.
A16: Consideration paid in new Paytm shares (₹ Cr) | B16: 1900 | G16: Case headline: ₹1,900 Cr.
A17: → Total consideration from the mix (must equal the price paid) | B17: =lv_mix_cash+lv_mix_debt+lv_mix_eq -> 4000
A18: Price paid for 100% (₹ Cr) — case headline 4,000; lower to test a renegotiated price | B18: =cf_deal -> 4000
A19: → Check: mix = price (should read 0) | B19: =lv_mix_total-lv_price -> 0
A21: 3. MINORITY / HYBRID LEVERS
A22: Minority stake | B22: =a_stake -> 0.26 | G22: Defaults to Inputs (26%).
A23: Implied 100% valuation for the minority entry (₹ Cr) — ceiling 4,000 (headline), floor = base DCF | B23: =a_min_val100 -> 2500 | G23: Defaults to Inputs (₹2,500 Cr = 11.4x ARR).
A24: Churn triggered at minority | B24: =a_min_churn -> 0 | G24: Defaults to Inputs (0%; a gate).
A25: Drag applied at minority (0 none / 1 pro-rata / 2 full) | B25: =a_min_drag_mode -> 0 | G25: Defaults to Inputs (0).
A26: → Minority price (₹ Cr) = stake × implied 100% valuation | B26: =lv_stake*lv_min_val100 -> 650
A27: → Implied entry multiple (× ARR) / discount to the headline pro-rata | B27: =lv_min_val100/cf_arr -> 11.363636 | C27: =1-lv_min_val100/lv_price -> 0.375
A29: 4. HEADLINE OUTPUTS — valuation → FCF → leverage → EPS → transaction economics → decision thresholds (green = key outputs)
A30: Output | B30: Full acquisition (levers) | C30: Minority stake | D30: Hybrid (minority + option) | E30: JV | F30: Walk away | G30: Read-across
A31: VALUATION — standalone DCF of 100% (₹ Cr) | B31: =dcf_ev -> 1218.8043 | C31: =dcf_ev -> 1218.8043 | D31: =dcf_ev -> 1218.8043 | E31: n/a | F31: n/a | G31: Financial value before churn and drag; compare with ₹4,000 Cr.
A32: Headline multiple / effective multiple on retained ARR | B32: =e_eff_mult -> 24.242424 | C32: =lv_min_val100/cf_arr -> 11.363636 | D32: =(lv_min_price+eo_total)/(cf_arr*(1+lv_g)^a_opt_year*(1-a_ctrl_churn)) -> 12.327652 | E32: n/a | F32: n/a | G32: Full: price ÷ year-1 retained ARR. Minority: entry valuation ÷ ARR. Hybrid: total consideration ÷ retained ARR at exercise.
A33: Breakeven 10-yr growth for DCF = price | B33: =dcf_be_growth -> 0.36843109 | G33: What you need to believe.
A34: FCF — year-1 incremental FCF after drag and cost of funds (₹ Cr) | B34: =e_fcf_y1 -> -1045.475 | C34: =Structures!D54 -> -29.925 | D34: =Structures!D105 -> -29.925 | E34: =Structures!D131 -> -13.41 | F34: =Structures!D139 -> -83.333333 | G34: Cash consumed in year 1.
A35: FCF breakeven year (99 = never within 10 yrs) | B35: =e_fcf_be -> 99 | C35: n/a | D35: =Structures!C113 -> 7 | E35: n/a | F35: n/a | G35: Case §5.3.
A36: PAT breakeven year (99 = never within 10 yrs) | B36: =e_pat_be -> 99 | C36: =Structures!C63 -> 7 | D36: =Structures!C112 -> 7 | E36: n/a | F36: n/a | G36: Addendum 1: accounting breakeven.
A37: LEVERAGE — gross debt ÷ EBITDA after close | B37: =e_lev_after -> 0.546875 | C37: =c_lev0 -> 0.546875 | D37: =Structures!C120 -> 1.328125 | E37: =c_lev0 -> 0.546875 | F37: =c_lev0 -> 0.546875 | G37: Guardrail ≤ a_max_lev.
A38: Cash after close (₹ Cr) | B38: =e_cash_after -> 6640 | C38: =Structures!C64 -> 8235 | D38: =Structures!C119 -> 7560.52 | E38: =cf_cash-a_jv_capital -> 8600 | F38: =cf_cash -> 8900 | G38: Guardrail ≥ a_min_cash.
A39: EPS — year-1 pro-forma ex-MDR (₹) | B39: =e_eps_y1 -> 5.2561362 | C39: =Structures!C61 -> 7.0485094 | D39: =Structures!C116 -> 7.0485094 | E39: =Structures!C134 -> 7.2960937 | F39: =Structures!C142 -> 6.5234375 | G39: From the ₹7.50 baseline.
A40: EPS — year-1 accretion / (dilution) vs ₹7.50 | B40: =e_eps_y1/cf_eps-1 -> -0.29918184 | C40: =Structures!C61/cf_eps-1 -> -0.06019875 | D40: =Structures!C116/cf_eps-1 -> -0.06019875 | E40: =Structures!C134/cf_eps-1 -> -0.0271875 | F40: =Structures!C142/cf_eps-1 -> -0.13020833 | G40: Case §3.3 lens.
A41: EPS — year-3 pro-forma ex-MDR (₹) | B41: =e_eps_y3 -> 5.2193652 | C41: =Structures!C62 -> 7.1714179 | D41: =Structures!C117 -> 6.5312617 | E41: =Structures!C135 -> 7.3523438 | F41: =cf_eps -> 7.5
A42: TRANSACTION ECONOMICS — NPV to Paytm (₹ Cr) | B42: =e_npv -> -7486.7574 | C42: =Structures!C60 -> -348.11089 | D42: =Structures!C115 -> -1187.3396 | E42: =Structures!C133 -> -283.57336 | F42: =Structures!C141 -> -196.76272 | G42: Economic verdict.
A43: Maximum total commitment (₹ Cr) | B43: =lv_price+lv_price*a_fees_pct+a_integ_full -> 4160 | C43: =lv_min_price+a_integ_min -> 665 | D43: =hy_max_total -> 2603.6 | E43: =a_jv_capital -> 300 | F43: =a_build_cost -> 250
A44: Maximum unconditional commitment (₹ Cr) | B44: =lv_price+lv_price*a_fees_pct+a_integ_full -> 4160 | C44: =lv_min_price+a_integ_min -> 665 | D44: =lv_min_price+a_integ_min -> 665 | E44: =a_jv_capital -> 300 | F44: =0 -> 0 | G44: Cash at risk before any gate.
...

Sheet Inputs
A1: INPUTS — case facts, calculations on case facts, and team assumptions
A2: Blue on light-blue = CASE FACT (comment = case section). Blue on yellow = TEAM ASSUMPTION (per Addendum 1, disclosed and flexed). Black = calculation.
A4: A. CASE FACTS — Paytm baseline (case §1, 'Baseline financials (assume for modeling)')
A5: Market capitalisation (₹ Cr) | B5: 118750 | D5: Case §1 and §2 table: ₹1,18,750 Cr (~$14B), mid-Sep 2026. Case note: real, verified fact.
A6: Diluted shares outstanding (Cr) | B6: 64 | D6: Case §1: 64 Cr diluted shares.
A7: Cash (₹ Cr) | B7: 8900 | D7: Case §1: ₹8,900 Cr cash.
A8: Gross debt (₹ Cr) | B8: 350 | D8: Case §1: ₹350 Cr gross debt.
A9: Trailing revenue (₹ Cr) | B9: 8450 | D9: Case §1: trailing revenue ₹8,450 Cr.
A10: EBITDA (₹ Cr) | B10: 640 | D10: Case §1: EBITDA ₹640 Cr.
A11: PAT (₹ Cr) | B11: 480 | D11: Case §1: PAT ₹480 Cr. Starting point for all dilution calculations (case §5.3).
A12: Diluted EPS (₹) | B12: 7.5 | D12: Case §1: diluted EPS ₹7.50. Baseline for §5.3.
A13: Credit rating | B13: CRISIL AA- (Stable)
A15: B. CASE FACTS — Liminal and the proposed transaction (case §2, §3)
A16: Headline deal value (₹ Cr) | B16: 4000 | D16: Case §2: ₹4,000 Cr (~$470M).
A17: of which cash consideration (₹ Cr) | B17: 2100 | D17: Case §2: ₹2,100 Cr cash; may be funded from balance-sheet cash, new debt, or a mix.
A18: of which equity consideration (₹ Cr) | B18: 1900 | D18: Case §2: ₹1,900 Cr equity (Paytm shares issued to Liminal shareholders).
A19: Liminal ARR (₹ Cr) | B19: 220 | D19: Case §2 table: Target ARR ₹220 Cr (~$26M).
A20: Liminal net income today (₹ Cr) | B20: 0 | D20: Case §2: 'approximately breakeven at the net income level today'.
A21: Top-4 clients' share of ARR (HDFC Bank, Axis Bank, CoinDCX, ZebPay) | B21: 0.6 | D21: Case §2: together 60% of Liminal's ARR.
A22: ARR lost within 12 months of a FULL acquisition — low end | B22: 0.3 | D22: Case §3.1: assume 30% to 45% of ARR lost within 12 months of a full acquisition.
A23: ARR lost within 12 months of a FULL acquisition — high end | B23: 0.45 | D23: Case §3.1.
A24: Recurring annual FCF drag from bank-like capital reserves if Paytm owns the custody infrastructure (₹ Cr/yr) | B24: 750 | D24: Case §3.2: RBI requires bank-like capital reserves against custodied assets because Paytm holds a PA licence, not a banking licence → recurring annual FCF drag ₹750 Cr (~$88M).
A25: Incremental net revenue to Paytm from the new UPI MDR (₹ Cr/yr) | B25: 115 | D25: Case §3.4: 0.4% MDR on P2M UPI > ₹2,000, capped ₹300/txn, effective 15 Oct 2026; assume ₹115 Cr/yr incremental net revenue for Paytm. Case note: the MDR framework is a real fact; the ₹115 Cr is the case's modelling input.
A26: Competing bidder | B26: PhonePe–Mastercard exploratory consortium
A27: Case's stated implied multiple | B27: 18x Deal Value / ARR
A29: C. CALCULATIONS on case facts (no assumptions involved)
A30: Implied Paytm share price (₹) = market cap ÷ diluted shares | B30: =cf_mcap/cf_shares -> 1855.4688
A31: Paytm trailing P/E = market cap ÷ PAT | B31: =cf_mcap/cf_pat -> 247.39583
A32: Paytm earnings yield = PAT ÷ market cap | B32: =cf_pat/cf_mcap -> 0.0040421053
A33: Headline multiple = deal value ÷ ARR | B33: =cf_deal/cf_arr -> 18.181818
A34: New Paytm shares for the ₹1,900 Cr equity leg (Cr) = equity ÷ share price | B34: =cf_deal_eq/c_price -> 1.024
A35: …as % of existing share count | B35: =c_new_shares_case/cf_shares -> 0.016
A36: Top-4 clients' ARR (₹ Cr) | B36: =cf_arr*cf_top4 -> 132
A37: ARR at risk — low (₹ Cr) | B37: =cf_arr*cf_churn_lo -> 66
A38: ARR at risk — high (₹ Cr) | B38: =cf_arr*cf_churn_hi -> 99
A39: Case churn as % of top-4 book — low | B39: =cf_churn_lo/cf_top4 -> 0.5
A40: Case churn as % of top-4 book — high | B40: =cf_churn_hi/cf_top4 -> 0.75
A41: Capital drag ÷ Paytm EBITDA | B41: =cf_drag/cf_ebitda -> 1.171875
A42: Capital drag ÷ Paytm PAT | B42: =cf_drag/cf_pat -> 1.5625
A43: Capital drag ÷ Liminal ARR | B43: =cf_drag/cf_arr -> 3.4090909
...

Sheet Liminal_Ops
A1: LIMINAL OPERATING FORECAST — 10 years, from case ARR ₹220 Cr and team assumptions (Inputs §D)
A2: Block 1: standalone, no churn, at the Dashboard growth case. Block 2: after a full acquisition, with the Dashboard churn applied in the churn year. Revenue = ARR run-rate.
A4: BLOCK 1 — Standalone Liminal (no churn) at the selected growth case
A5: Year | C5: 0 | D5: 1 | E5: 2 | F5: 3 | G5: 4 | H5: 5 | I5: 6 | J5: 7 | K5: 8 | L5: 9 | M5: 10
A6: Revenue (ARR run-rate) before churn | C6: =cf_arr -> 220 | D6: =C6*(1+lv_g) -> 264 | E6: =D6*(1+lv_g) -> 316.8 | F6: =E6*(1+lv_g) -> 380.16 | G6: =F6*(1+lv_g) -> 456.192 | H6: =G6*(1+lv_g) -> 547.4304 | I6: =H6*(1+lv_g) -> 656.91648 | J6: =I6*(1+lv_g) -> 788.29978 | K6: =J6*(1+lv_g) -> 945.95973 | ... M6: =L6*(1+lv_g) -> 1362.182
A7: Retention factor (1 − churn from churn year) | C7: =1 -> 1 | D7: =IF(D5>=a_churn_year,1-0,1) -> 1 | E7: =IF(E5>=a_churn_year,1-0,1) -> 1 | F7: =IF(F5>=a_churn_year,1-0,1) -> 1 | G7: =IF(G5>=a_churn_year,1-0,1) -> 1 | H7: =IF(H5>=a_churn_year,1-0,1) -> 1 | I7: =IF(I5>=a_churn_year,1-0,1) -> 1 | J7: =IF(J5>=a_churn_year,1-0,1) -> 1 | K7: =IF(K5>=a_churn_year,1-0,1) -> 1 | ... M7: =IF(M5>=a_churn_year,1-0,1) -> 1
A8: Revenue after churn | C8: =C6*C7 -> 220 | D8: =D6*D7 -> 264 | E8: =E6*E7 -> 316.8 | F8: =F6*F7 -> 380.16 | G8: =G6*G7 -> 456.192 | H8: =H6*H7 -> 547.4304 | I8: =I6*I7 -> 656.91648 | J8: =J6*J7 -> 788.29978 | ... M8: =M6*M7 -> 1362.182
A9: EBITDA margin (ramp) | C9: =MIN(a_m0+a_mstep*C5,a_mcap) -> 0 | D9: =MIN(a_m0+a_mstep*D5,a_mcap) -> 0.05 | E9: =MIN(a_m0+a_mstep*E5,a_mcap) -> 0.1 | F9: =MIN(a_m0+a_mstep*F5,a_mcap) -> 0.15 | G9: =MIN(a_m0+a_mstep*G5,a_mcap) -> 0.2 | H9: =MIN(a_m0+a_mstep*H5,a_mcap) -> 0.25 | I9: =MIN(a_m0+a_mstep*I5,a_mcap) -> 0.25 | J9: =MIN(a_m0+a_mstep*J5,a_mcap) -> 0.25 | ... M9: =MIN(a_m0+a_mstep*M5,a_mcap) -> 0.25
A10: Sticky cost of lost revenue (churn year only) | C10: =IF(C5=a_churn_year,a_sticky*(C6-C8)*(1-C9),0) -> 0 | D10: =IF(D5=a_churn_year,a_sticky*(D6-D8)*(1-D9),0) -> 0 | E10: =IF(E5=a_churn_year,a_sticky*(E6-E8)*(1-E9),0) -> 0 | F10: =IF(F5=a_churn_year,a_sticky*(F6-F8)*(1-F9),0) -> 0 | G10: =IF(G5=a_churn_year,a_sticky*(G6-G8)*(1-G9),0) -> 0 | H10: =IF(H5=a_churn_year,a_sticky*(H6-H8)*(1-H9),0) -> 0 | I10: =IF(I5=a_churn_year,a_sticky*(I6-I8)*(1-I9),0) -> 0 | J10: =IF(J5=a_churn_year,a_sticky*(J6-J8)*(1-J9),0) -> 0 | ... M10: =IF(M5=a_churn_year,a_sticky*(M6-M8)*(1-M9),0) -> 0
A11: EBITDA | C11: =C8*C9-C10 -> 0 | D11: =D8*D9-D10 -> 13.2 | E11: =E8*E9-E10 -> 31.68 | F11: =F8*F9-F10 -> 57.024 | G11: =G8*G9-G10 -> 91.2384 | H11: =H8*H9-H10 -> 136.8576 | I11: =I8*I9-I10 -> 164.22912 | J11: =J8*J9-J10 -> 197.07494 | ... M11: =M8*M9-M10 -> 340.5455
A12: Depreciation & amortisation | C12: =C8*a_da -> 6.6 | D12: =D8*a_da -> 7.92 | E12: =E8*a_da -> 9.504 | F12: =F8*a_da -> 11.4048 | G12: =G8*a_da -> 13.68576 | H12: =H8*a_da -> 16.422912 | I12: =I8*a_da -> 19.707494 | J12: =J8*a_da -> 23.648993 | ... M12: =M8*a_da -> 40.86546
A13: EBIT | C13: =C11-C12 -> -6.6 | D13: =D11-D12 -> 5.28 | E13: =E11-E12 -> 22.176 | F13: =F11-F12 -> 45.6192 | G13: =G11-G12 -> 77.55264 | H13: =H11-H12 -> 120.43469 | I13: =I11-I12 -> 144.52163 | J13: =J11-J12 -> 173.42595 | ... M13: =M11-M12 -> 299.68004
A14: Tax (only on positive EBIT; no group relief) | C14: =MAX(0,C13)*a_tax -> 0 | D14: =MAX(0,D13)*a_tax -> 1.32 | E14: =MAX(0,E13)*a_tax -> 5.544 | F14: =MAX(0,F13)*a_tax -> 11.4048 | G14: =MAX(0,G13)*a_tax -> 19.38816 | H14: =MAX(0,H13)*a_tax -> 30.108672 | I14: =MAX(0,I13)*a_tax -> 36.130406 | J14: =MAX(0,J13)*a_tax -> 43.356488 | ... M14: =MAX(0,M13)*a_tax -> 74.920011
A15: PAT (net income) | C15: =cf_lim_pat -> 0 | D15: =D13-D14 -> 3.96 | E15: =E13-E14 -> 16.632 | F15: =F13-F14 -> 34.2144 | G15: =G13-G14 -> 58.16448 | H15: =H13-H14 -> 90.326016 | I15: =I13-I14 -> 108.39122 | J15: =J13-J14 -> 130.06946 | K15: =K13-K14 -> 156.08336 | ... M15: =M13-M14 -> 224.76003
A16: Capex | C16: =C8*a_capex -> 6.6 | D16: =D8*a_capex -> 7.92 | E16: =E8*a_capex -> 9.504 | F16: =F8*a_capex -> 11.4048 | G16: =G8*a_capex -> 13.68576 | H16: =H8*a_capex -> 16.422912 | I16: =I8*a_capex -> 19.707494 | J16: =J8*a_capex -> 23.648993 | ... M16: =M8*a_capex -> 40.86546
A17: Increase in working capital | C17: =0 -> 0 | D17: =a_wc*(D8-C8) -> 2.2 | E17: =a_wc*(E8-D8) -> 2.64 | F17: =a_wc*(F8-E8) -> 3.168 | G17: =a_wc*(G8-F8) -> 3.8016 | H17: =a_wc*(H8-G8) -> 4.56192 | I17: =a_wc*(I8-H8) -> 5.474304 | J17: =a_wc*(J8-I8) -> 6.5691648 | K17: =a_wc*(K8-J8) -> 7.8829978 | ... M17: =a_wc*(M8-L8) -> 11.351517
A18: Unlevered free cash flow = PAT + D&A − capex − ΔWC | C18: =0 -> 0 | D18: =D15+D12-D16-D17 -> 1.76 | E18: =E15+E12-E16-E17 -> 13.992 | F18: =F15+F12-F16-F17 -> 31.0464 | G18: =G15+G12-G16-G17 -> 54.36288 | H18: =H15+H12-H16-H17 -> 85.764096 | I18: =I15+I12-I16-I17 -> 102.91692 | J18: =J15+J12-J16-J17 -> 123.5003 | K18: =K15+K12-K16-K17 -> 148.20036 | ... M18: =M15+M12-M16-M17 -> 213.40852
A20: BLOCK 2 — Liminal after a FULL acquisition (case churn applied in year 1)
A21: Year | C21: 0 | D21: 1 | E21: 2 | F21: 3 | G21: 4 | H21: 5 | I21: 6 | J21: 7 | K21: 8 | L21: 9 | M21: 10
A22: Revenue (ARR run-rate) before churn | C22: =cf_arr -> 220 | D22: =C22*(1+lv_g) -> 264 | E22: =D22*(1+lv_g) -> 316.8 | F22: =E22*(1+lv_g) -> 380.16 | G22: =F22*(1+lv_g) -> 456.192 | H22: =G22*(1+lv_g) -> 547.4304 | I22: =H22*(1+lv_g) -> 656.91648 | J22: =I22*(1+lv_g) -> 788.29978 | K22: =J22*(1+lv_g) -> 945.95973 | ... M22: =L22*(1+lv_g) -> 1362.182
A23: Retention factor (1 − churn from churn year) | C23: =1 -> 1 | D23: =IF(D21>=a_churn_year,1-lv_churn,1) -> 0.625 | E23: =IF(E21>=a_churn_year,1-lv_churn,1) -> 0.625 | F23: =IF(F21>=a_churn_year,1-lv_churn,1) -> 0.625 | G23: =IF(G21>=a_churn_year,1-lv_churn,1) -> 0.625 | H23: =IF(H21>=a_churn_year,1-lv_churn,1) -> 0.625 | I23: =IF(I21>=a_churn_year,1-lv_churn,1) -> 0.625 | J23: =IF(J21>=a_churn_year,1-lv_churn,1) -> 0.625 | K23: =IF(K21>=a_churn_year,1-lv_churn,1) -> 0.625 | ... M23: =IF(M21>=a_churn_year,1-lv_churn,1) -> 0.625
A24: Revenue after churn | C24: =C22*C23 -> 220 | D24: =D22*D23 -> 165 | E24: =E22*E23 -> 198 | F24: =F22*F23 -> 237.6 | G24: =G22*G23 -> 285.12 | H24: =H22*H23 -> 342.144 | I24: =I22*I23 -> 410.5728 | J24: =J22*J23 -> 492.68736 | ... M24: =M22*M23 -> 851.36376
A25: EBITDA margin (ramp) | C25: =MIN(a_m0+a_mstep*C21,a_mcap) -> 0 | D25: =MIN(a_m0+a_mstep*D21,a_mcap) -> 0.05 | E25: =MIN(a_m0+a_mstep*E21,a_mcap) -> 0.1 | F25: =MIN(a_m0+a_mstep*F21,a_mcap) -> 0.15 | G25: =MIN(a_m0+a_mstep*G21,a_mcap) -> 0.2 | H25: =MIN(a_m0+a_mstep*H21,a_mcap) -> 0.25 | I25: =MIN(a_m0+a_mstep*I21,a_mcap) -> 0.25 | J25: =MIN(a_m0+a_mstep*J21,a_mcap) -> 0.25 | ... M25: =MIN(a_m0+a_mstep*M21,a_mcap) -> 0.25
A26: Sticky cost of lost revenue (churn year only) | C26: =IF(C21=a_churn_year,a_sticky*(C22-C24)*(1-C25),0) -> 0 | D26: =IF(D21=a_churn_year,a_sticky*(D22-D24)*(1-D25),0) -> 47.025 | E26: =IF(E21=a_churn_year,a_sticky*(E22-E24)*(1-E25),0) -> 0 | F26: =IF(F21=a_churn_year,a_sticky*(F22-F24)*(1-F25),0) -> 0 | G26: =IF(G21=a_churn_year,a_sticky*(G22-G24)*(1-G25),0) -> 0 | H26: =IF(H21=a_churn_year,a_sticky*(H22-H24)*(1-H25),0) -> 0 | I26: =IF(I21=a_churn_year,a_sticky*(I22-I24)*(1-I25),0) -> 0 | J26: =IF(J21=a_churn_year,a_sticky*(J22-J24)*(1-J25),0) -> 0 | ... M26: =IF(M21=a_churn_year,a_sticky*(M22-M24)*(1-M25),0) -> 0
A27: EBITDA | C27: =C24*C25-C26 -> 0 | D27: =D24*D25-D26 -> -38.775 | E27: =E24*E25-E26 -> 19.8 | F27: =F24*F25-F26 -> 35.64 | G27: =G24*G25-G26 -> 57.024 | H27: =H24*H25-H26 -> 85.536 | I27: =I24*I25-I26 -> 102.6432 | J27: =J24*J25-J26 -> 123.17184 | ... M27: =M24*M25-M26 -> 212.84094
A28: Depreciation & amortisation | C28: =C24*a_da -> 6.6 | D28: =D24*a_da -> 4.95 | E28: =E24*a_da -> 5.94 | F28: =F24*a_da -> 7.128 | G28: =G24*a_da -> 8.5536 | H28: =H24*a_da -> 10.26432 | I28: =I24*a_da -> 12.317184 | J28: =J24*a_da -> 14.780621 | ... M28: =M24*a_da -> 25.540913
A29: EBIT | C29: =C27-C28 -> -6.6 | D29: =D27-D28 -> -43.725 | E29: =E27-E28 -> 13.86 | F29: =F27-F28 -> 28.512 | G29: =G27-G28 -> 48.4704 | H29: =H27-H28 -> 75.27168 | I29: =I27-I28 -> 90.326016 | J29: =J27-J28 -> 108.39122 | ... M29: =M27-M28 -> 187.30003
A30: Tax (only on positive EBIT; no group relief) | C30: =MAX(0,C29)*a_tax -> 0 | D30: =MAX(0,D29)*a_tax -> 0 | E30: =MAX(0,E29)*a_tax -> 3.465 | F30: =MAX(0,F29)*a_tax -> 7.128 | G30: =MAX(0,G29)*a_tax -> 12.1176 | H30: =MAX(0,H29)*a_tax -> 18.81792 | I30: =MAX(0,I29)*a_tax -> 22.581504 | J30: =MAX(0,J29)*a_tax -> 27.097805 | ... M30: =MAX(0,M29)*a_tax -> 46.825007
A31: PAT (net income) | C31: =cf_lim_pat -> 0 | D31: =D29-D30 -> -43.725 | E31: =E29-E30 -> 10.395 | F31: =F29-F30 -> 21.384 | G31: =G29-G30 -> 36.3528 | H31: =H29-H30 -> 56.45376 | I31: =I29-I30 -> 67.744512 | J31: =J29-J30 -> 81.293414 | K31: =K29-K30 -> 97.552097 | ... M31: =M29-M30 -> 140.47502
A32: Capex | C32: =C24*a_capex -> 6.6 | D32: =D24*a_capex -> 4.95 | E32: =E24*a_capex -> 5.94 | F32: =F24*a_capex -> 7.128 | G32: =G24*a_capex -> 8.5536 | H32: =H24*a_capex -> 10.26432 | I32: =I24*a_capex -> 12.317184 | J32: =J24*a_capex -> 14.780621 | ... M32: =M24*a_capex -> 25.540913
A33: Increase in working capital | C33: =0 -> 0 | D33: =a_wc*(D24-C24) -> -2.75 | E33: =a_wc*(E24-D24) -> 1.65 | F33: =a_wc*(F24-E24) -> 1.98 | G33: =a_wc*(G24-F24) -> 2.376 | H33: =a_wc*(H24-G24) -> 2.8512 | I33: =a_wc*(I24-H24) -> 3.42144 | J33: =a_wc*(J24-I24) -> 4.105728 | K33: =a_wc*(K24-J24) -> 4.9268736 | ... M33: =a_wc*(M24-L24) -> 7.094698
A34: Unlevered free cash flow = PAT + D&A − capex − ΔWC | C34: =0 -> 0 | D34: =D31+D28-D32-D33 -> -40.975 | E34: =E31+E28-E32-E33 -> 8.745 | F34: =F31+F28-F32-F33 -> 19.404 | G34: =G31+G28-G32-G33 -> 33.9768 | H34: =H31+H28-H32-H33 -> 53.60256 | I34: =I31+I28-I32-I33 -> 64.323072 | J34: =J31+J28-J32-J33 -> 77.187686 | K34: =K31+K28-K32-K33 -> 92.625224 | ... M34: =M31+M28-M32-M33 -> 133.38032
A36: BLOCK 3 — Standalone revenue and PAT by growth case (no churn), for reference
A37: Year | C37: 0 | D37: 1 | E37: 2 | F37: 3 | G37: 4 | H37: 5 | I37: 6 | J37: 7 | K37: 8 | L37: 9 | M37: 10
A38: Bear — revenue | C38: =cf_arr -> 220 | D38: =C38*(1+a_g_bear) -> 242 | E38: =D38*(1+a_g_bear) -> 266.2 | F38: =E38*(1+a_g_bear) -> 292.82 | G38: =F38*(1+a_g_bear) -> 322.102 | H38: =G38*(1+a_g_bear) -> 354.3122 | I38: =H38*(1+a_g_bear) -> 389.74342 | J38: =I38*(1+a_g_bear) -> 428.71776 | K38: =J38*(1+a_g_bear) -> 471.58954 | ... M38: =L38*(1+a_g_bear) -> 570.62334
A39: Bear — PAT (margin ramp, tax on positive EBIT) | C39: =cf_lim_pat -> 0 | D39: =(D38*(MIN(a_m0+a_mstep*D37,a_mcap)-a_da))*(1-a_tax*(D38*(MIN(a_m0+a_mstep*D37,a_mcap)-a_da)>0)) -> 3.63 | E39: =(E38*(MIN(a_m0+a_mstep*E37,a_mcap)-a_da))*(1-a_tax*(E38*(MIN(a_m0+a_mstep*E37,a_mcap)-a_da)>0)) -> 13.9755 | F39: =(F38*(MIN(a_m0+a_mstep*F37,a_mcap)-a_da))*(1-a_tax*(F38*(MIN(a_m0+a_mstep*F37,a_mcap)-a_da)>0)) -> 26.3538 | G39: =(G38*(MIN(a_m0+a_mstep*G37,a_mcap)-a_da))*(1-a_tax*(G38*(MIN(a_m0+a_mstep*G37,a_mcap)-a_da)>0)) -> 41.068005 | H39: =(H38*(MIN(a_m0+a_mstep*H37,a_mcap)-a_da))*(1-a_tax*(H38*(MIN(a_m0+a_mstep*H37,a_mcap)-a_da)>0)) -> 58.461513 | I39: =(I38*(MIN(a_m0+a_mstep*I37,a_mcap)-a_da))*(1-a_tax*(I38*(MIN(a_m0+a_mstep*I37,a_mcap)-a_da)>0)) -> 64.307664 | J39: =(J38*(MIN(a_m0+a_mstep*J37,a_mcap)-a_da))*(1-a_tax*(J38*(MIN(a_m0+a_mstep*J37,a_mcap)-a_da)>0)) -> 70.738431 | K39: =(K38*(MIN(a_m0+a_mstep*K37,a_mcap)-a_da))*(1-a_tax*(K38*(MIN(a_m0+a_mstep*K37,a_mcap)-a_da)>0)) -> 77.812274 | ... M39: =(M38*(MIN(a_m0+a_mstep*M37,a_mcap)-a_da))*(1-a_tax*(M38*(MIN(a_m0+a_mstep*M37,a_mcap)-a_da)>0)) -> 94.152851
A40: Base — revenue | C40: =cf_arr -> 220 | D40: =C40*(1+a_g_base) -> 264 | E40: =D40*(1+a_g_base) -> 316.8 | F40: =E40*(1+a_g_base) -> 380.16 | G40: =F40*(1+a_g_base) -> 456.192 | H40: =G40*(1+a_g_base) -> 547.4304 | I40: =H40*(1+a_g_base) -> 656.91648 | J40: =I40*(1+a_g_base) -> 788.29978 | K40: =J40*(1+a_g_base) -> 945.95973 | ... M40: =L40*(1+a_g_base) -> 1362.182
A41: Base — PAT (margin ramp, tax on positive EBIT) | C41: =cf_lim_pat -> 0 | D41: =(D40*(MIN(a_m0+a_mstep*D37,a_mcap)-a_da))*(1-a_tax*(D40*(MIN(a_m0+a_mstep*D37,a_mcap)-a_da)>0)) -> 3.96 | E41: =(E40*(MIN(a_m0+a_mstep*E37,a_mcap)-a_da))*(1-a_tax*(E40*(MIN(a_m0+a_mstep*E37,a_mcap)-a_da)>0)) -> 16.632 | F41: =(F40*(MIN(a_m0+a_mstep*F37,a_mcap)-a_da))*(1-a_tax*(F40*(MIN(a_m0+a_mstep*F37,a_mcap)-a_da)>0)) -> 34.2144 | G41: =(G40*(MIN(a_m0+a_mstep*G37,a_mcap)-a_da))*(1-a_tax*(G40*(MIN(a_m0+a_mstep*G37,a_mcap)-a_da)>0)) -> 58.16448 | H41: =(H40*(MIN(a_m0+a_mstep*H37,a_mcap)-a_da))*(1-a_tax*(H40*(MIN(a_m0+a_mstep*H37,a_mcap)-a_da)>0)) -> 90.326016 | I41: =(I40*(MIN(a_m0+a_mstep*I37,a_mcap)-a_da))*(1-a_tax*(I40*(MIN(a_m0+a_mstep*I37,a_mcap)-a_da)>0)) -> 108.39122 | J41: =(J40*(MIN(a_m0+a_mstep*J37,a_mcap)-a_da))*(1-a_tax*(J40*(MIN(a_m0+a_mstep*J37,a_mcap)-a_da)>0)) -> 130.06946 | K41: =(K40*(MIN(a_m0+a_mstep*K37,a_mcap)-a_da))*(1-a_tax*(K40*(MIN(a_m0+a_mstep*K37,a_mcap)-a_da)>0)) -> 156.08336 | ... M41: =(M40*(MIN(a_m0+a_mstep*M37,a_mcap)-a_da))*(1-a_tax*(M40*(MIN(a_m0+a_mstep*M37,a_mcap)-a_da)>0)) -> 224.76003
A42: Bull — revenue | C42: =cf_arr -> 220 | D42: =C42*(1+a_g_bull) -> 286 | E42: =D42*(1+a_g_bull) -> 371.8 | F42: =E42*(1+a_g_bull) -> 483.34 | G42: =F42*(1+a_g_bull) -> 628.342 | H42: =G42*(1+a_g_bull) -> 816.8446 | I42: =H42*(1+a_g_bull) -> 1061.898 | J42: =I42*(1+a_g_bull) -> 1380.4674 | K42: =J42*(1+a_g_bull) -> 1794.6076 | ... M42: =L42*(1+a_g_bull) -> 3032.8868
A43: Bull — PAT (margin ramp, tax on positive EBIT) | C43: =cf_lim_pat -> 0 | D43: =(D42*(MIN(a_m0+a_mstep*D37,a_mcap)-a_da))*(1-a_tax*(D42*(MIN(a_m0+a_mstep*D37,a_mcap)-a_da)>0)) -> 4.29 | E43: =(E42*(MIN(a_m0+a_mstep*E37,a_mcap)-a_da))*(1-a_tax*(E42*(MIN(a_m0+a_mstep*E37,a_mcap)-a_da)>0)) -> 19.5195 | F43: =(F42*(MIN(a_m0+a_mstep*F37,a_mcap)-a_da))*(1-a_tax*(F42*(MIN(a_m0+a_mstep*F37,a_mcap)-a_da)>0)) -> 43.5006 | G43: =(G42*(MIN(a_m0+a_mstep*G37,a_mcap)-a_da))*(1-a_tax*(G42*(MIN(a_m0+a_mstep*G37,a_mcap)-a_da)>0)) -> 80.113605 | H43: =(H42*(MIN(a_m0+a_mstep*H37,a_mcap)-a_da))*(1-a_tax*(H42*(MIN(a_m0+a_mstep*H37,a_mcap)-a_da)>0)) -> 134.77936 | I43: =(I42*(MIN(a_m0+a_mstep*I37,a_mcap)-a_da))*(1-a_tax*(I42*(MIN(a_m0+a_mstep*I37,a_mcap)-a_da)>0)) -> 175.21317 | J43: =(J42*(MIN(a_m0+a_mstep*J37,a_mcap)-a_da))*(1-a_tax*(J42*(MIN(a_m0+a_mstep*J37,a_mcap)-a_da)>0)) -> 227.77712 | K43: =(K42*(MIN(a_m0+a_mstep*K37,a_mcap)-a_da))*(1-a_tax*(K42*(MIN(a_m0+a_mstep*K37,a_mcap)-a_da)>0)) -> 296.11025 | ... M43: =(M42*(MIN(a_m0+a_mstep*M37,a_mcap)-a_da))*(1-a_tax*(M42*(MIN(a_m0+a_mstep*M37,a_mcap)-a_da)>0)) -> 500.42633

Sheet DCF
A1: DCF — standalone value of Liminal, what you need to believe for ₹4,000 Cr, and sensitivity grids
A2: Unlevered FCF from Liminal_Ops Block 1 (standalone, no churn). End-year discounting. Terminal value = Gordon growth. This is the STANDALONE FINANCIAL value; strategic/option value is assessed separately (Structures, Synergies).
A4: 1. Standalone DCF at Dashboard settings (growth case, WACC)
A5: Year | C5: 0 | D5: 1 | E5: 2 | F5: 3 | G5: 4 | H5: 5 | I5: 6 | J5: 7 | K5: 8 | L5: 9 | M5: 10
A6: Unlevered FCF (from Liminal_Ops Block 1) | C6: =Liminal_Ops!C18 -> 0 | D6: =Liminal_Ops!D18 -> 1.76 | E6: =Liminal_Ops!E18 -> 13.992 | F6: =Liminal_Ops!F18 -> 31.0464 | G6: =Liminal_Ops!G18 -> 54.36288 | H6: =Liminal_Ops!H18 -> 85.764096 | I6: =Liminal_Ops!I18 -> 102.91692 | J6: =Liminal_Ops!J18 -> 123.5003 | ... M6: =Liminal_Ops!M18 -> 213.40852
A7: Discount factor | C7: =1 -> 1 | D7: =1/(1+lv_wacc)^D5 -> 0.88495575 | E7: =1/(1+lv_wacc)^E5 -> 0.78314668 | F7: =1/(1+lv_wacc)^F5 -> 0.69305016 | G7: =1/(1+lv_wacc)^G5 -> 0.61331873 | H7: =1/(1+lv_wacc)^H5 -> 0.54275994 | I7: =1/(1+lv_wacc)^I5 -> 0.48031853 | J7: =1/(1+lv_wacc)^J5 -> 0.42506064 | K7: =1/(1+lv_wacc)^K5 -> 0.37615986 | ... M7: =1/(1+lv_wacc)^M5 -> 0.29458835
A8: PV of FCF | C8: =C6*C7 -> 0 | D8: =D6*D7 -> 1.5575221 | E8: =E6*E7 -> 10.957788 | F8: =F6*F7 -> 21.516713 | G8: =G6*G7 -> 33.341772 | H8: =H6*H7 -> 46.549315 | I8: =I6*I7 -> 49.432901 | J8: =J6*J7 -> 52.495116 | ... M8: =M6*M7 -> 62.867662
A9: Sum of PV of FCF, years 1–10 (₹ Cr) | B9: =SUM(D8:M8) -> 393.6662
A10: Terminal value at Y10 (₹ Cr) = FCF10 × (1 + g) ÷ (WACC − g) | B10: =M6*(1+a_tg)/(lv_wacc-a_tg) -> 2800.9868
A11: PV of terminal value (₹ Cr) | B11: =B10*M7 -> 825.13806
A12: Standalone DCF value of 100% of Liminal (₹ Cr) | B12: =B9+B11 -> 1218.8043
A13: Share of value from terminal value | B13: =B11/B12 -> 0.67700622
A14: Implied EV ÷ current ARR | B14: =B12/cf_arr -> 5.5400194
A15: DCF value − headline price (₹ Cr): negative = price exceeds standalone value | B15: =B12-lv_price -> -2781.1957
A16: Price ÷ DCF value − 1 = premium over standalone value | B16: =lv_price/B12-1 -> 2.2819052
A17: DCF value of the minority stake (pro-rata, before minority discount) (₹ Cr) | B17: =lv_stake*B12 -> 316.88911
A18: Minority price ÷ pro-rata DCF value − 1 | B18: =lv_min_price/B17-1 -> 1.0511907
A20: 2. WHAT YOU NEED TO BELIEVE — standalone DCF by 10-year growth rate (no churn, no drag), at the Dashboard WACC
A21: Helper rows compute unlevered FCF for each growth rate with the same formulas as Liminal_Ops (closed form). The grid then discounts each row at several WACCs.
A22: Year | C22: 0 | D22: 1 | E22: 2 | F22: 3 | G22: 4 | H22: 5 | I22: 6 | J22: 7 | K22: 8 | L22: 9 | M22: 10
A23: Growth 10% p.a. — unlevered FCF | B23: 0.1 | C23: =0 -> 0 | D23: =(((cf_arr*(1+$B23)^D22)*IF(D22>=a_churn_year,1-0,1))*(MIN(a_m0+a_mstep*D22,a_mcap)-a_da)-IF(D22=a_churn_year,a_sticky*((cf_arr*(1+$B23)^D22)-((cf_arr*(1+$B23)^D22)*IF(D22>=a_churn_year,1-0,1)))*(1-MIN(a_m0+a_mstep*D22,a_mcap)),0))-MAX(0,(((cf_arr*(1+$B23)^D22)*IF(D22>=a_churn_year,1-0,1))*(MIN(a_m0+a_mstep*D22,a_mcap)-a_da)-IF(D22=a_churn_year,a_sticky*((cf_arr*(1+$B23)^D22)-((cf_arr*(1+$B23)^D22)*IF(D22>=a_churn_year,1-0,1)))*(1-MIN(a_m0+a_mstep*D22,a_mcap)),0)))*a_tax+((cf_arr*(1+$B23)^D22)*IF(D22>=a_churn_year,1-0,1))*a_da-((cf_arr*(1+$B23)^D22)*IF(D22>=a_churn_year,1-0,1))*a_capex-a_wc*(((cf_arr*(1+$B23)^D22)*IF(D22>=a_churn_year,1-0,1))-(cf_arr*(1+$B23)^C22*IF(C22>=a_churn_year,1-0,1))) -> 2.53 | E23: =(((cf_arr*(1+$B23)^E22)*IF(E22>=a_churn_year,1-0,1))*(MIN(a_m0+a_mstep*E22,a_mcap)-a_da)-IF(E22=a_churn_year,a_sticky*((cf_arr*(1+$B23)^E22)-((cf_arr*(1+$B23)^E22)*IF(E22>=a_churn_year,1-0,1)))*(1-MIN(a_m0+a_mstep*E22,a_mcap)),0))-MAX(0,(((cf_arr*(1+$B23)^E22)*IF(E22>=a_churn_year,1-0,1))*(MIN(a_m0+a_mstep*E22,a_mcap)-a_da)-IF(E22=a_churn_year,a_sticky*((cf_arr*(1+$B23)^E22)-((cf_arr*(1+$B23)^E22)*IF(E22>=a_churn_year,1-0,1)))*(1-MIN(a_m0+a_mstep*E22,a_mcap)),0)))*a_tax+((cf_arr*(1+$B23)^E22)*IF(E22>=a_churn_year,1-0,1))*a_da-((cf_arr*(1+$B23)^E22)*IF(E22>=a_churn_year,1-0,1))*a_capex-a_wc*(((cf_arr*(1+$B23)^E22)*IF(E22>=a_churn_year,1-0,1))-(cf_arr*(1+$B23)^D22*IF(D22>=a_churn_year,1-0,1))) -> 12.7655 | F23: =(((cf_arr*(1+$B23)^F22)*IF(F22>=a_churn_year,1-0,1))*(MIN(a_m0+a_mstep*F22,a_mcap)-a_da)-IF(F22=a_churn_year,a_sticky*((cf_arr*(1+$B23)^F22)-((cf_arr*(1+$B23)^F22)*IF(F22>=a_churn_year,1-0,1)))*(1-MIN(a_m0+a_mstep*F22,a_mcap)),0))-MAX(0,(((cf_arr*(1+$B23)^F22)*IF(F22>=a_churn_year,1-0,1))*(MIN(a_m0+a_mstep*F22,a_mcap)-a_da)-IF(F22=a_churn_year,a_sticky*((cf_arr*(1+$B23)^F22)-((cf_arr*(1+$B23)^F22)*IF(F22>=a_churn_year,1-0,1)))*(1-MIN(a_m0+a_mstep*F22,a_mcap)),0)))*a_tax+((cf_arr*(1+$B23)^F22)*IF(F22>=a_churn_year,1-0,1))*a_da-((cf_arr*(1+$B23)^F22)*IF(F22>=a_churn_year,1-0,1))*a_capex-a_wc*(((cf_arr*(1+$B23)^F22)*IF(F22>=a_churn_year,1-0,1))-(cf_arr*(1+$B23)^E22*IF(E22>=a_churn_year,1-0,1))) -> 25.0228 | G23: =(((cf_arr*(1+$B23)^G22)*IF(G22>=a_churn_year,1-0,1))*(MIN(a_m0+a_mstep*G22,a_mcap)-a_da)-IF(G22=a_churn_year,a_sticky*((cf_arr*(1+$B23)^G22)-((cf_arr*(1+$B23)^G22)*IF(G22>=a_churn_year,1-0,1)))*(1-MIN(a_m0+a_mstep*G22,a_mcap)),0))-MAX(0,(((cf_arr*(1+$B23)^G22)*IF(G22>=a_churn_year,1-0,1))*(MIN(a_m0+a_mstep*G22,a_mcap)-a_da)-IF(G22=a_churn_year,a_sticky*((cf_arr*(1+$B23)^G22)-((cf_arr*(1+$B23)^G22)*IF(G22>=a_churn_year,1-0,1)))*(1-MIN(a_m0+a_mstep*G22,a_mcap)),0)))*a_tax+((cf_arr*(1+$B23)^G22)*IF(G22>=a_churn_year,1-0,1))*a_da-((cf_arr*(1+$B23)^G22)*IF(G22>=a_churn_year,1-0,1))*a_capex-a_wc*(((cf_arr*(1+$B23)^G22)*IF(G22>=a_churn_year,1-0,1))-(cf_arr*(1+$B23)^F22*IF(F22>=a_churn_year,1-0,1))) -> 39.603905 | H23: =(((cf_arr*(1+$B23)^H22)*IF(H22>=a_churn_year,1-0,1))*(MIN(a_m0+a_mstep*H22,a_mcap)-a_da)-IF(H22=a_churn_year,a_sticky*((cf_arr*(1+$B23)^H22)-((cf_arr*(1+$B23)^H22)*IF(H22>=a_churn_year,1-0,1)))*(1-MIN(a_m0+a_mstep*H22,a_mcap)),0))-MAX(0,(((cf_arr*(1+$B23)^H22)*IF(H22>=a_churn_year,1-0,1))*(MIN(a_m0+a_mstep*H22,a_mcap)-a_da)-IF(H22=a_churn_year,a_sticky*((cf_arr*(1+$B23)^H22)-((cf_arr*(1+$B23)^H22)*IF(H22>=a_churn_year,1-0,1)))*(1-MIN(a_m0+a_mstep*H22,a_mcap)),0)))*a_tax+((cf_arr*(1+$B23)^H22)*IF(H22>=a_churn_year,1-0,1))*a_da-((cf_arr*(1+$B23)^H22)*IF(H22>=a_churn_year,1-0,1))*a_capex-a_wc*(((cf_arr*(1+$B23)^H22)*IF(H22>=a_churn_year,1-0,1))-(cf_arr*(1+$B23)^G22*IF(G22>=a_churn_year,1-0,1))) -> 56.851003 | I23: =(((cf_arr*(1+$B23)^I22)*IF(I22>=a_churn_year,1-0,1))*(MIN(a_m0+a_mstep*I22,a_mcap)-a_da)-IF(I22=a_churn_year,a_sticky*((cf_arr*(1+$B23)^I22)-((cf_arr*(1+$B23)^I22)*IF(I22>=a_churn_year,1-0,1)))*(1-MIN(a_m0+a_mstep*I22,a_mcap)),0))-MAX(0,(((cf_arr*(1+$B23)^I22)*IF(I22>=a_churn_year,1-0,1))*(MIN(a_m0+a_mstep*I22,a_mcap)-a_da)-IF(I22=a_churn_year,a_sticky*((cf_arr*(1+$B23)^I22)-((cf_arr*(1+$B23)^I22)*IF(I22>=a_churn_year,1-0,1)))*(1-MIN(a_m0+a_mstep*I22,a_mcap)),0)))*a_tax+((cf_arr*(1+$B23)^I22)*IF(I22>=a_churn_year,1-0,1))*a_da-((cf_arr*(1+$B23)^I22)*IF(I22>=a_churn_year,1-0,1))*a_capex-a_wc*(((cf_arr*(1+$B23)^I22)*IF(I22>=a_churn_year,1-0,1))-(cf_arr*(1+$B23)^H22*IF(H22>=a_churn_year,1-0,1))) -> 62.536103 | J23: =(((cf_arr*(1+$B23)^J22)*IF(J22>=a_churn_year,1-0,1))*(MIN(a_m0+a_mstep*J22,a_mcap)-a_da)-IF(J22=a_churn_year,a_sticky*((cf_arr*(1+$B23)^J22)-((cf_arr*(1+$B23)^J22)*IF(J22>=a_churn_year,1-0,1)))*(1-MIN(a_m0+a_mstep*J22,a_mcap)),0))-MAX(0,(((cf_arr*(1+$B23)^J22)*IF(J22>=a_churn_year,1-0,1))*(MIN(a_m0+a_mstep*J22,a_mcap)-a_da)-IF(J22=a_churn_year,a_sticky*((cf_arr*(1+$B23)^J22)-((cf_arr*(1+$B23)^J22)*IF(J22>=a_churn_year,1-0,1)))*(1-MIN(a_m0+a_mstep*J22,a_mcap)),0)))*a_tax+((cf_arr*(1+$B23)^J22)*IF(J22>=a_churn_year,1-0,1))*a_da-((cf_arr*(1+$B23)^J22)*IF(J22>=a_churn_year,1-0,1))*a_capex-a_wc*(((cf_arr*(1+$B23)^J22)*IF(J22>=a_churn_year,1-0,1))-(cf_arr*(1+$B23)^I22*IF(I22>=a_churn_year,1-0,1))) -> 68.789714 | K23: =(((cf_arr*(1+$B23)^K22)*IF(K22>=a_churn_year,1-0,1))*(MIN(a_m0+a_mstep*K22,a_mcap)-a_da)-IF(K22=a_churn_year,a_sticky*((cf_arr*(1+$B23)^K22)-((cf_arr*(1+$B23)^K22)*IF(K22>=a_churn_year,1-0,1)))*(1-MIN(a_m0+a_mstep*K22,a_mcap)),0))-MAX(0,(((cf_arr*(1+$B23)^K22)*IF(K22>=a_churn_year,1-0,1))*(MIN(a_m0+a_mstep*K22,a_mcap)-a_da)-IF(K22=a_churn_year,a_sticky*((cf_arr*(1+$B23)^K22)-((cf_arr*(1+$B23)^K22)*IF(K22>=a_churn_year,1-0,1)))*(1-MIN(a_m0+a_mstep*K22,a_mcap)),0)))*a_tax+((cf_arr*(1+$B23)^K22)*IF(K22>=a_churn_year,1-0,1))*a_da-((cf_arr*(1+$B23)^K22)*IF(K22>=a_churn_year,1-0,1))*a_capex-a_wc*(((cf_arr*(1+$B23)^K22)*IF(K22>=a_churn_year,1-0,1))-(cf_arr*(1+$B23)^J22*IF(J22>=a_churn_year,1-0,1))) -> 75.668685 | ... M23: =(((cf_arr*(1+$B23)^M22)*IF(M22>=a_churn_year,1-0,1))*(MIN(a_m0+a_mstep*M22,a_mcap)-a_da)-IF(M22=a_churn_year,a_sticky*((cf_arr*(1+$B23)^M22)-((cf_arr*(1+$B23)^M22)*IF(M22>=a_churn_year,1-0,1)))*(1-MIN(a_m0+a_mstep*M22,a_mcap)),0))-MAX(0,(((cf_arr*(1+$B23)^M22)*IF(M22>=a_churn_year,1-0,1))*(MIN(a_m0+a_mstep*M22,a_mcap)-a_da)-IF(M22=a_churn_year,a_sticky*((cf_arr*(1+$B23)^M22)-((cf_arr*(1+$B23)^M22)*IF(M22>=a_churn_year,1-0,1)))*(1-MIN(a_m0+a_mstep*M22,a_mcap)),0)))*a_tax+((cf_arr*(1+$B23)^M22)*IF(M22>=a_churn_year,1-0,1))*a_da-((cf_arr*(1+$B23)^M22)*IF(M22>=a_churn_year,1-0,1))*a_capex-a_wc*(((cf_arr*(1+$B23)^M22)*IF(M22>=a_churn_year,1-0,1))-(cf_arr*(1+$B23)^L22*IF(L22>=a_churn_year,1-0,1))) -> 91.559109
A24: Growth 15% p.a. — unlevered FCF | B24: 0.15 | C24: =0 -> 0 | D24: =(((cf_arr*(1+$B24)^D22)*IF(D22>=a_churn_year,1-0,1))*(MIN(a_m0+a_mstep*D22,a_mcap)-a_da)-IF(D22=a_churn_year,a_sticky*((cf_arr*(1+$B24)^D22)-((cf_arr*(1+$B24)^D22)*IF(D22>=a_churn_year,1-0,1)))*(1-MIN(a_m0+a_mstep*D22,a_mcap)),0))-MAX(0,(((cf_arr*(1+$B24)^D22)*IF(D22>=a_churn_year,1-0,1))*(MIN(a_m0+a_mstep*D22,a_mcap)-a_da)-IF(D22=a_churn_year,a_sticky*((cf_arr*(1+$B24)^D22)-((cf_arr*(1+$B24)^D22)*IF(D22>=a_churn_year,1-0,1)))*(1-MIN(a_m0+a_mstep*D22,a_mcap)),0)))*a_tax+((cf_arr*(1+$B24)^D22)*IF(D22>=a_churn_year,1-0,1))*a_da-((cf_arr*(1+$B24)^D22)*IF(D22>=a_churn_year,1-0,1))*a_capex-a_wc*(((cf_arr*(1+$B24)^D22)*IF(D22>=a_churn_year,1-0,1))-(cf_arr*(1+$B24)^C22*IF(C22>=a_churn_year,1-0,1))) -> 2.145 | E24: =(((cf_arr*(1+$B24)^E22)*IF(E22>=a_churn_year,1-0,1))*(MIN(a_m0+a_mstep*E22,a_mcap)-a_da)-IF(E22=a_churn_year,a_sticky*((cf_arr*(1+$B24)^E22)-((cf_arr*(1+$B24)^E22)*IF(E22>=a_churn_year,1-0,1)))*(1-MIN(a_m0+a_mstep*E22,a_mcap)),0))-MAX(0,(((cf_arr*(1+$B24)^E22)*IF(E22>=a_churn_year,1-0,1))*(MIN(a_m0+a_mstep*E22,a_mcap)-a_da)-IF(E22=a_churn_year,a_sticky*((cf_arr*(1+$B24)^E22)-((cf_arr*(1+$B24)^E22)*IF(E22>=a_churn_year,1-0,1)))*(1-MIN(a_m0+a_mstep*E22,a_mcap)),0)))*a_tax+((cf_arr*(1+$B24)^E22)*IF(E22>=a_churn_year,1-0,1))*a_da-((cf_arr*(1+$B24)^E22)*IF(E22>=a_churn_year,1-0,1))*a_capex-a_wc*(((cf_arr*(1+$B24)^E22)*IF(E22>=a_churn_year,1-0,1))-(cf_arr*(1+$B24)^D22*IF(D22>=a_churn_year,1-0,1))) -> 13.377375 | F24: =(((cf_arr*(1+$B24)^F22)*IF(F22>=a_churn_year,1-0,1))*(MIN(a_m0+a_mstep*F22,a_mcap)-a_da)-IF(F22=a_churn_year,a_sticky*((cf_arr*(1+$B24)^F22)-((cf_arr*(1+$B24)^F22)*IF(F22>=a_churn_year,1-0,1)))*(1-MIN(a_m0+a_mstep*F22,a_mcap)),0))-MAX(0,(((cf_arr*(1+$B24)^F22)*IF(F22>=a_churn_year,1-0,1))*(MIN(a_m0+a_mstep*F22,a_mcap)-a_da)-IF(F22=a_churn_year,a_sticky*((cf_arr*(1+$B24)^F22)-((cf_arr*(1+$B24)^F22)*IF(F22>=a_churn_year,1-0,1)))*(1-MIN(a_m0+a_mstep*F22,a_mcap)),0)))*a_tax+((cf_arr*(1+$B24)^F22)*IF(F22>=a_churn_year,1-0,1))*a_da-((cf_arr*(1+$B24)^F22)*IF(F22>=a_churn_year,1-0,1))*a_capex-a_wc*(((cf_arr*(1+$B24)^F22)*IF(F22>=a_churn_year,1-0,1))-(cf_arr*(1+$B24)^E22*IF(E22>=a_churn_year,1-0,1))) -> 27.9312 | G24: =(((cf_arr*(1+$B24)^G22)*IF(G22>=a_churn_year,1-0,1))*(MIN(a_m0+a_mstep*G22,a_mcap)-a_da)-IF(G22=a_churn_year,a_sticky*((cf_arr*(1+$B24)^G22)-((cf_arr*(1+$B24)^G22)*IF(G22>=a_churn_year,1-0,1)))*(1-MIN(a_m0+a_mstep*G22,a_mcap)),0))-MAX(0,(((cf_arr*(1+$B24)^G22)*IF(G22>=a_churn_year,1-0,1))*(MIN(a_m0+a_mstep*G22,a_mcap)-a_da)-IF(G22=a_churn_year,a_sticky*((cf_arr*(1+$B24)^G22)-((cf_arr*(1+$B24)^G22)*IF(G22>=a_churn_year,1-0,1)))*(1-MIN(a_m0+a_mstep*G22,a_mcap)),0)))*a_tax+((cf_arr*(1+$B24)^G22)*IF(G22>=a_churn_year,1-0,1))*a_da-((cf_arr*(1+$B24)^G22)*IF(G22>=a_churn_year,1-0,1))*a_capex-a_wc*(((cf_arr*(1+$B24)^G22)*IF(G22>=a_churn_year,1-0,1))-(cf_arr*(1+$B24)^F22*IF(F22>=a_churn_year,1-0,1))) -> 46.550182 | H24: =(((cf_arr*(1+$B24)^H22)*IF(H22>=a_churn_year,1-0,1))*(MIN(a_m0+a_mstep*H22,a_mcap)-a_da)-IF(H22=a_churn_year,a_sticky*((cf_arr*(1+$B24)^H22)-((cf_arr*(1+$B24)^H22)*IF(H22>=a_churn_year,1-0,1)))*(1-MIN(a_m0+a_mstep*H22,a_mcap)),0))-MAX(0,(((cf_arr*(1+$B24)^H22)*IF(H22>=a_churn_year,1-0,1))*(MIN(a_m0+a_mstep*H22,a_mcap)-a_da)-IF(H22=a_churn_year,a_sticky*((cf_arr*(1+$B24)^H22)-((cf_arr*(1+$B24)^H22)*IF(H22>=a_churn_year,1-0,1)))*(1-MIN(a_m0+a_mstep*H22,a_mcap)),0)))*a_tax+((cf_arr*(1+$B24)^H22)*IF(H22>=a_churn_year,1-0,1))*a_da-((cf_arr*(1+$B24)^H22)*IF(H22>=a_churn_year,1-0,1))*a_capex-a_wc*(((cf_arr*(1+$B24)^H22)*IF(H22>=a_churn_year,1-0,1))-(cf_arr*(1+$B24)^G22*IF(G22>=a_churn_year,1-0,1))) -> 70.126406 | I24: =(((cf_arr*(1+$B24)^I22)*IF(I22>=a_churn_year,1-0,1))*(MIN(a_m0+a_mstep*I22,a_mcap)-a_da)-IF(I22=a_churn_year,a_sticky*((cf_arr*(1+$B24)^I22)-((cf_arr*(1+$B24)^I22)*IF(I22>=a_churn_year,1-0,1)))*(1-MIN(a_m0+a_mstep*I22,a_mcap)),0))-MAX(0,(((cf_arr*(1+$B24)^I22)*IF(I22>=a_churn_year,1-0,1))*(MIN(a_m0+a_mstep*I22,a_mcap)-a_da)-IF(I22=a_churn_year,a_sticky*((cf_arr*(1+$B24)^I22)-((cf_arr*(1+$B24)^I22)*IF(I22>=a_churn_year,1-0,1)))*(1-MIN(a_m0+a_mstep*I22,a_mcap)),0)))*a_tax+((cf_arr*(1+$B24)^I22)*IF(I22>=a_churn_year,1-0,1))*a_da-((cf_arr*(1+$B24)^I22)*IF(I22>=a_churn_year,1-0,1))*a_capex-a_wc*(((cf_arr*(1+$B24)^I22)*IF(I22>=a_churn_year,1-0,1))-(cf_arr*(1+$B24)^H22*IF(H22>=a_churn_year,1-0,1))) -> 80.645366 | J24: =(((cf_arr*(1+$B24)^J22)*IF(J22>=a_churn_year,1-0,1))*(MIN(a_m0+a_mstep*J22,a_mcap)-a_da)-IF(J22=a_churn_year,a_sticky*((cf_arr*(1+$B24)^J22)-((cf_arr*(1+$B24)^J22)*IF(J22>=a_churn_year,1-0,1)))*(1-MIN(a_m0+a_mstep*J22,a_mcap)),0))-MAX(0,(((cf_arr*(1+$B24)^J22)*IF(J22>=a_churn_year,1-0,1))*(MIN(a_m0+a_mstep*J22,a_mcap)-a_da)-IF(J22=a_churn_year,a_sticky*((cf_arr*(1+$B24)^J22)-((cf_arr*(1+$B24)^J22)*IF(J22>=a_churn_year,1-0,1)))*(1-MIN(a_m0+a_mstep*J22,a_mcap)),0)))*a_tax+((cf_arr*(1+$B24)^J22)*IF(J22>=a_churn_year,1-0,1))*a_da-((cf_arr*(1+$B24)^J22)*IF(J22>=a_churn_year,1-0,1))*a_capex-a_wc*(((cf_arr*(1+$B24)^J22)*IF(J22>=a_churn_year,1-0,1))-(cf_arr*(1+$B24)^I22*IF(I22>=a_churn_year,1-0,1))) -> 92.742171 | K24: =(((cf_arr*(1+$B24)^K22)*IF(K22>=a_churn_year,1-0,1))*(MIN(a_m0+a_mstep*K22,a_mcap)-a_da)-IF(K22=a_churn_year,a_sticky*((cf_arr*(1+$B24)^K22)-((cf_arr*(1+$B24)^K22)*IF(K22>=a_churn_year,1-0,1)))*(1-MIN(a_m0+a_mstep*K22,a_mcap)),0))-MAX(0,(((cf_arr*(1+$B24)^K22)*IF(K22>=a_churn_year,1-0,1))*(MIN(a_m0+a_mstep*K22,a_mcap)-a_da)-IF(K22=a_churn_year,a_sticky*((cf_arr*(1+$B24)^K22)-((cf_arr*(1+$B24)^K22)*IF(K22>=a_churn_year,1-0,1)))*(1-MIN(a_m0+a_mstep*K22,a_mcap)),0)))*a_tax+((cf_arr*(1+$B24)^K22)*IF(K22>=a_churn_year,1-0,1))*a_da-((cf_arr*(1+$B24)^K22)*IF(K22>=a_churn_year,1-0,1))*a_capex-a_wc*(((cf_arr*(1+$B24)^K22)*IF(K22>=a_churn_year,1-0,1))-(cf_arr*(1+$B24)^J22*IF(J22>=a_churn_year,1-0,1))) -> 106.6535 | ... M24: =(((cf_arr*(1+$B24)^M22)*IF(M22>=a_churn_year,1-0,1))*(MIN(a_m0+a_mstep*M22,a_mcap)-a_da)-IF(M22=a_churn_year,a_sticky*((cf_arr*(1+$B24)^M22)-((cf_arr*(1+$B24)^M22)*IF(M22>=a_churn_year,1-0,1)))*(1-MIN(a_m0+a_mstep*M22,a_mcap)),0))-MAX(0,(((cf_arr*(1+$B24)^M22)*IF(M22>=a_churn_year,1-0,1))*(MIN(a_m0+a_mstep*M22,a_mcap)-a_da)-IF(M22=a_churn_year,a_sticky*((cf_arr*(1+$B24)^M22)-((cf_arr*(1+$B24)^M22)*IF(M22>=a_churn_year,1-0,1)))*(1-MIN(a_m0+a_mstep*M22,a_mcap)),0)))*a_tax+((cf_arr*(1+$B24)^M22)*IF(M22>=a_churn_year,1-0,1))*a_da-((cf_arr*(1+$B24)^M22)*IF(M22>=a_churn_year,1-0,1))*a_capex-a_wc*(((cf_arr*(1+$B24)^M22)*IF(M22>=a_churn_year,1-0,1))-(cf_arr*(1+$B24)^L22*IF(L22>=a_churn_year,1-0,1))) -> 141.04925
A25: Growth 20% p.a. — unlevered FCF | B25: 0.2 | C25: =0 -> 0 | D25: =(((cf_arr*(1+$B25)^D22)*IF(D22>=a_churn_year,1-0,1))*(MIN(a_m0+a_mstep*D22,a_mcap)-a_da)-IF(D22=a_churn_year,a_sticky*((cf_arr*(1+$B25)^D22)-((cf_arr*(1+$B25)^D22)*IF(D22>=a_churn_year,1-0,1)))*(1-MIN(a_m0+a_mstep*D22,a_mcap)),0))-MAX(0,(((cf_arr*(1+$B25)^D22)*IF(D22>=a_churn_year,1-0,1))*(MIN(a_m0+a_mstep*D22,a_mcap)-a_da)-IF(D22=a_churn_year,a_sticky*((cf_arr*(1+$B25)^D22)-((cf_arr*(1+$B25)^D22)*IF(D22>=a_churn_year,1-0,1)))*(1-MIN(a_m0+a_mstep*D22,a_mcap)),0)))*a_tax+((cf_arr*(1+$B25)^D22)*IF(D22>=a_churn_year,1-0,1))*a_da-((cf_arr*(1+$B25)^D22)*IF(D22>=a_churn_year,1-0,1))*a_capex-a_wc*(((cf_arr*(1+$B25)^D22)*IF(D22>=a_churn_year,1-0,1))-(cf_arr*(1+$B25)^C22*IF(C22>=a_churn_year,1-0,1))) -> 1.76 | E25: =(((cf_arr*(1+$B25)^E22)*IF(E22>=a_churn_year,1-0,1))*(MIN(a_m0+a_mstep*E22,a_mcap)-a_da)-IF(E22=a_churn_year,a_sticky*((cf_arr*(1+$B25)^E22)-((cf_arr*(1+$B25)^E22)*IF(E22>=a_churn_year,1-0,1)))*(1-MIN(a_m0+a_mstep*E22,a_mcap)),0))-MAX(0,(((cf_arr*(1+$B25)^E22)*IF(E22>=a_churn_year,1-0,1))*(MIN(a_m0+a_mstep*E22,a_mcap)-a_da)-IF(E22=a_churn_year,a_sticky*((cf_arr*(1+$B25)^E22)-((cf_arr*(1+$B25)^E22)*IF(E22>=a_churn_year,1-0,1)))*(1-MIN(a_m0+a_mstep*E22,a_mcap)),0)))*a_tax+((cf_arr*(1+$B25)^E22)*IF(E22>=a_churn_year,1-0,1))*a_da-((cf_arr*(1+$B25)^E22)*IF(E22>=a_churn_year,1-0,1))*a_capex-a_wc*(((cf_arr*(1+$B25)^E22)*IF(E22>=a_churn_year,1-0,1))-(cf_arr*(1+$B25)^D22*IF(D22>=a_churn_year,1-0,1))) -> 13.992 | F25: =(((cf_arr*(1+$B25)^F22)*IF(F22>=a_churn_year,1-0,1))*(MIN(a_m0+a_mstep*F22,a_mcap)-a_da)-IF(F22=a_churn_year,a_sticky*((cf_arr*(1+$B25)^F22)-((cf_arr*(1+$B25)^F22)*IF(F22>=a_churn_year,1-0,1)))*(1-MIN(a_m0+a_mstep*F22,a_mcap)),0))-MAX(0,(((cf_arr*(1+$B25)^F22)*IF(F22>=a_churn_year,1-0,1))*(MIN(a_m0+a_mstep*F22,a_mcap)-a_da)-IF(F22=a_churn_year,a_sticky*((cf_arr*(1+$B25)^F22)-((cf_arr*(1+$B25)^F22)*IF(F22>=a_churn_year,1-0,1)))*(1-MIN(a_m0+a_mstep*F22,a_mcap)),0)))*a_tax+((cf_arr*(1+$B25)^F22)*IF(F22>=a_churn_year,1-0,1))*a_da-((cf_arr*(1+$B25)^F22)*IF(F22>=a_churn_year,1-0,1))*a_capex-a_wc*(((cf_arr*(1+$B25)^F22)*IF(F22>=a_churn_year,1-0,1))-(cf_arr*(1+$B25)^E22*IF(E22>=a_churn_year,1-0,1))) -> 31.0464 | G25: =(((cf_arr*(1+$B25)^G22)*IF(G22>=a_churn_year,1-0,1))*(MIN(a_m0+a_mstep*G22,a_mcap)-a_da)-IF(G22=a_churn_year,a_sticky*((cf_arr*(1+$B25)^G22)-((cf_arr*(1+$B25)^G22)*IF(G22>=a_churn_year,1-0,1)))*(1-MIN(a_m0+a_mstep*G22,a_mcap)),0))-MAX(0,(((cf_arr*(1+$B25)^G22)*IF(G22>=a_churn_year,1-0,1))*(MIN(a_m0+a_mstep*G22,a_mcap)-a_da)-IF(G22=a_churn_year,a_sticky*((cf_arr*(1+$B25)^G22)-((cf_arr*(1+$B25)^G22)*IF(G22>=a_churn_year,1-0,1)))*(1-MIN(a_m0+a_mstep*G22,a_mcap)),0)))*a_tax+((cf_arr*(1+$B25)^G22)*IF(G22>=a_churn_year,1-0,1))*a_da-((cf_arr*(1+$B25)^G22)*IF(G22>=a_churn_year,1-0,1))*a_capex-a_wc*(((cf_arr*(1+$B25)^G22)*IF(G22>=a_churn_year,1-0,1))-(cf_arr*(1+$B25)^F22*IF(F22>=a_churn_year,1-0,1))) -> 54.36288 | H25: =(((cf_arr*(1+$B25)^H22)*IF(H22>=a_churn_year,1-0,1))*(MIN(a_m0+a_mstep*H22,a_mcap)-a_da)-IF(H22=a_churn_year,a_sticky*((cf_arr*(1+$B25)^H22)-((cf_arr*(1+$B25)^H22)*IF(H22>=a_churn_year,1-0,1)))*(1-MIN(a_m0+a_mstep*H22,a_mcap)),0))-MAX(0,(((cf_arr*(1+$B25)^H22)*IF(H22>=a_churn_year,1-0,1))*(MIN(a_m0+a_mstep*H22,a_mcap)-a_da)-IF(H22=a_churn_year,a_sticky*((cf_arr*(1+$B25)^H22)-((cf_arr*(1+$B25)^H22)*IF(H22>=a_churn_year,1-0,1)))*(1-MIN(a_m0+a_mstep*H22,a_mcap)),0)))*a_tax+((cf_arr*(1+$B25)^H22)*IF(H22>=a_churn_year,1-0,1))*a_da-((cf_arr*(1+$B25)^H22)*IF(H22>=a_churn_year,1-0,1))*a_capex-a_wc*(((cf_arr*(1+$B25)^H22)*IF(H22>=a_churn_year,1-0,1))-(cf_arr*(1+$B25)^G22*IF(G22>=a_churn_year,1-0,1))) -> 85.764096 | I25: =(((cf_arr*(1+$B25)^I22)*IF(I22>=a_churn_year,1-0,1))*(MIN(a_m0+a_mstep*I22,a_mcap)-a_da)-IF(I22=a_churn_year,a_sticky*((cf_arr*(1+$B25)^I22)-((cf_arr*(1+$B25)^I22)*IF(I22>=a_churn_year,1-0,1)))*(1-MIN(a_m0+a_mstep*I22,a_mcap)),0))-MAX(0,(((cf_arr*(1+$B25)^I22)*IF(I22>=a_churn_year,1-0,1))*(MIN(a_m0+a_mstep*I22,a_mcap)-a_da)-IF(I22=a_churn_year,a_sticky*((cf_arr*(1+$B25)^I22)-((cf_arr*(1+$B25)^I22)*IF(I22>=a_churn_year,1-0,1)))*(1-MIN(a_m0+a_mstep*I22,a_mcap)),0)))*a_tax+((cf_arr*(1+$B25)^I22)*IF(I22>=a_churn_year,1-0,1))*a_da-((cf_arr*(1+$B25)^I22)*IF(I22>=a_churn_year,1-0,1))*a_capex-a_wc*(((cf_arr*(1+$B25)^I22)*IF(I22>=a_churn_year,1-0,1))-(cf_arr*(1+$B25)^H22*IF(H22>=a_churn_year,1-0,1))) -> 102.91692 | J25: =(((cf_arr*(1+$B25)^J22)*IF(J22>=a_churn_year,1-0,1))*(MIN(a_m0+a_mstep*J22,a_mcap)-a_da)-IF(J22=a_churn_year,a_sticky*((cf_arr*(1+$B25)^J22)-((cf_arr*(1+$B25)^J22)*IF(J22>=a_churn_year,1-0,1)))*(1-MIN(a_m0+a_mstep*J22,a_mcap)),0))-MAX(0,(((cf_arr*(1+$B25)^J22)*IF(J22>=a_churn_year,1-0,1))*(MIN(a_m0+a_mstep*J22,a_mcap)-a_da)-IF(J22=a_churn_year,a_sticky*((cf_arr*(1+$B25)^J22)-((cf_arr*(1+$B25)^J22)*IF(J22>=a_churn_year,1-0,1)))*(1-MIN(a_m0+a_mstep*J22,a_mcap)),0)))*a_tax+((cf_arr*(1+$B25)^J22)*IF(J22>=a_churn_year,1-0,1))*a_da-((cf_arr*(1+$B25)^J22)*IF(J22>=a_churn_year,1-0,1))*a_capex-a_wc*(((cf_arr*(1+$B25)^J22)*IF(J22>=a_churn_year,1-0,1))-(cf_arr*(1+$B25)^I22*IF(I22>=a_churn_year,1-0,1))) -> 123.5003 | K25: =(((cf_arr*(1+$B25)^K22)*IF(K22>=a_churn_year,1-0,1))*(MIN(a_m0+a_mstep*K22,a_mcap)-a_da)-IF(K22=a_churn_year,a_sticky*((cf_arr*(1+$B25)^K22)-((cf_arr*(1+$B25)^K22)*IF(K22>=a_churn_year,1-0,1)))*(1-MIN(a_m0+a_mstep*K22,a_mcap)),0))-MAX(0,(((cf_arr*(1+$B25)^K22)*IF(K22>=a_churn_year,1-0,1))*(MIN(a_m0+a_mstep*K22,a_mcap)-a_da)-IF(K22=a_churn_year,a_sticky*((cf_arr*(1+$B25)^K22)-((cf_arr*(1+$B25)^K22)*IF(K22>=a_churn_year,1-0,1)))*(1-MIN(a_m0+a_mstep*K22,a_mcap)),0)))*a_tax+((cf_arr*(1+$B25)^K22)*IF(K22>=a_churn_year,1-0,1))*a_da-((cf_arr*(1+$B25)^K22)*IF(K22>=a_churn_year,1-0,1))*a_capex-a_wc*(((cf_arr*(1+$B25)^K22)*IF(K22>=a_churn_year,1-0,1))-(cf_arr*(1+$B25)^J22*IF(J22>=a_churn_year,1-0,1))) -> 148.20036 | ... M25: =(((cf_arr*(1+$B25)^M22)*IF(M22>=a_churn_year,1-0,1))*(MIN(a_m0+a_mstep*M22,a_mcap)-a_da)-IF(M22=a_churn_year,a_sticky*((cf_arr*(1+$B25)^M22)-((cf_arr*(1+$B25)^M22)*IF(M22>=a_churn_year,1-0,1)))*(1-MIN(a_m0+a_mstep*M22,a_mcap)),0))-MAX(0,(((cf_arr*(1+$B25)^M22)*IF(M22>=a_churn_year,1-0,1))*(MIN(a_m0+a_mstep*M22,a_mcap)-a_da)-IF(M22=a_churn_year,a_sticky*((cf_arr*(1+$B25)^M22)-((cf_arr*(1+$B25)^M22)*IF(M22>=a_churn_year,1-0,1)))*(1-MIN(a_m0+a_mstep*M22,a_mcap)),0)))*a_tax+((cf_arr*(1+$B25)^M22)*IF(M22>=a_churn_year,1-0,1))*a_da-((cf_arr*(1+$B25)^M22)*IF(M22>=a_churn_year,1-0,1))*a_capex-a_wc*(((cf_arr*(1+$B25)^M22)*IF(M22>=a_churn_year,1-0,1))-(cf_arr*(1+$B25)^L22*IF(L22>=a_churn_year,1-0,1))) -> 213.40852
A26: Growth 25% p.a. — unlevered FCF | B26: 0.25 | C26: =0 -> 0 | D26: =(((cf_arr*(1+$B26)^D22)*IF(D22>=a_churn_year,1-0,1))*(MIN(a_m0+a_mstep*D22,a_mcap)-a_da)-IF(D22=a_churn_year,a_sticky*((cf_arr*(1+$B26)^D22)-((cf_arr*(1+$B26)^D22)*IF(D22>=a_churn_year,1-0,1)))*(1-MIN(a_m0+a_mstep*D22,a_mcap)),0))-MAX(0,(((cf_arr*(1+$B26)^D22)*IF(D22>=a_churn_year,1-0,1))*(MIN(a_m0+a_mstep*D22,a_mcap)-a_da)-IF(D22=a_churn_year,a_sticky*((cf_arr*(1+$B26)^D22)-((cf_arr*(1+$B26)^D22)*IF(D22>=a_churn_year,1-0,1)))*(1-MIN(a_m0+a_mstep*D22,a_mcap)),0)))*a_tax+((cf_arr*(1+$B26)^D22)*IF(D22>=a_churn_year,1-0,1))*a_da-((cf_arr*(1+$B26)^D22)*IF(D22>=a_churn_year,1-0,1))*a_capex-a_wc*(((cf_arr*(1+$B26)^D22)*IF(D22>=a_churn_year,1-0,1))-(cf_arr*(1+$B26)^C22*IF(C22>=a_churn_year,1-0,1))) -> 1.375 | E26: =(((cf_arr*(1+$B26)^E22)*IF(E22>=a_churn_year,1-0,1))*(MIN(a_m0+a_mstep*E22,a_mcap)-a_da)-IF(E22=a_churn_year,a_sticky*((cf_arr*(1+$B26)^E22)-((cf_arr*(1+$B26)^E22)*IF(E22>=a_churn_year,1-0,1)))*(1-MIN(a_m0+a_mstep*E22,a_mcap)),0))-MAX(0,(((cf_arr*(1+$B26)^E22)*IF(E22>=a_churn_year,1-0,1))*(MIN(a_m0+a_mstep*E22,a_mcap)-a_da)-IF(E22=a_churn_year,a_sticky*((cf_arr*(1+$B26)^E22)-((cf_arr*(1+$B26)^E22)*IF(E22>=a_churn_year,1-0,1)))*(1-MIN(a_m0+a_mstep*E22,a_mcap)),0)))*a_tax+((cf_arr*(1+$B26)^E22)*IF(E22>=a_churn_year,1-0,1))*a_da-((cf_arr*(1+$B26)^E22)*IF(E22>=a_churn_year,1-0,1))*a_capex-a_wc*(((cf_arr*(1+$B26)^E22)*IF(E22>=a_churn_year,1-0,1))-(cf_arr*(1+$B26)^D22*IF(D22>=a_churn_year,1-0,1))) -> 14.609375 | F26: =(((cf_arr*(1+$B26)^F22)*IF(F22>=a_churn_year,1-0,1))*(MIN(a_m0+a_mstep*F22,a_mcap)-a_da)-IF(F22=a_churn_year,a_sticky*((cf_arr*(1+$B26)^F22)-((cf_arr*(1+$B26)^F22)*IF(F22>=a_churn_year,1-0,1)))*(1-MIN(a_m0+a_mstep*F22,a_mcap)),0))-MAX(0,(((cf_arr*(1+$B26)^F22)*IF(F22>=a_churn_year,1-0,1))*(MIN(a_m0+a_mstep*F22,a_mcap)-a_da)-IF(F22=a_churn_year,a_sticky*((cf_arr*(1+$B26)^F22)-((cf_arr*(1+$B26)^F22)*IF(F22>=a_churn_year,1-0,1)))*(1-MIN(a_m0+a_mstep*F22,a_mcap)),0)))*a_tax+((cf_arr*(1+$B26)^F22)*IF(F22>=a_churn_year,1-0,1))*a_da-((cf_arr*(1+$B26)^F22)*IF(F22>=a_churn_year,1-0,1))*a_capex-a_wc*(((cf_arr*(1+$B26)^F22)*IF(F22>=a_churn_year,1-0,1))-(cf_arr*(1+$B26)^E22*IF(E22>=a_churn_year,1-0,1))) -> 34.375 | G26: =(((cf_arr*(1+$B26)^G22)*IF(G22>=a_churn_year,1-0,1))*(MIN(a_m0+a_mstep*G22,a_mcap)-a_da)-IF(G22=a_churn_year,a_sticky*((cf_arr*(1+$B26)^G22)-((cf_arr*(1+$B26)^G22)*IF(G22>=a_churn_year,1-0,1)))*(1-MIN(a_m0+a_mstep*G22,a_mcap)),0))-MAX(0,(((cf_arr*(1+$B26)^G22)*IF(G22>=a_churn_year,1-0,1))*(MIN(a_m0+a_mstep*G22,a_mcap)-a_da)-IF(G22=a_churn_year,a_sticky*((cf_arr*(1+$B26)^G22)-((cf_arr*(1+$B26)^G22)*IF(G22>=a_churn_year,1-0,1)))*(1-MIN(a_m0+a_mstep*G22,a_mcap)),0)))*a_tax+((cf_arr*(1+$B26)^G22)*IF(G22>=a_churn_year,1-0,1))*a_da-((cf_arr*(1+$B26)^G22)*IF(G22>=a_churn_year,1-0,1))*a_capex-a_wc*(((cf_arr*(1+$B26)^G22)*IF(G22>=a_churn_year,1-0,1))-(cf_arr*(1+$B26)^F22*IF(F22>=a_churn_year,1-0,1))) -> 63.110352 | H26: =(((cf_arr*(1+$B26)^H22)*IF(H22>=a_churn_year,1-0,1))*(MIN(a_m0+a_mstep*H22,a_mcap)-a_da)-IF(H22=a_churn_year,a_sticky*((cf_arr*(1+$B26)^H22)-((cf_arr*(1+$B26)^H22)*IF(H22>=a_churn_year,1-0,1)))*(1-MIN(a_m0+a_mstep*H22,a_mcap)),0))-MAX(0,(((cf_arr*(1+$B26)^H22)*IF(H22>=a_churn_year,1-0,1))*(MIN(a_m0+a_mstep*H22,a_mcap)-a_da)-IF(H22=a_churn_year,a_sticky*((cf_arr*(1+$B26)^H22)-((cf_arr*(1+$B26)^H22)*IF(H22>=a_churn_year,1-0,1)))*(1-MIN(a_m0+a_mstep*H22,a_mcap)),0)))*a_tax+((cf_arr*(1+$B26)^H22)*IF(H22>=a_churn_year,1-0,1))*a_da-((cf_arr*(1+$B26)^H22)*IF(H22>=a_churn_year,1-0,1))*a_capex-a_wc*(((cf_arr*(1+$B26)^H22)*IF(H22>=a_churn_year,1-0,1))-(cf_arr*(1+$B26)^G22*IF(G22>=a_churn_year,1-0,1))) -> 104.06494 | I26: =(((cf_arr*(1+$B26)^I22)*IF(I22>=a_churn_year,1-0,1))*(MIN(a_m0+a_mstep*I22,a_mcap)-a_da)-IF(I22=a_churn_year,a_sticky*((cf_arr*(1+$B26)^I22)-((cf_arr*(1+$B26)^I22)*IF(I22>=a_churn_year,1-0,1)))*(1-MIN(a_m0+a_mstep*I22,a_mcap)),0))-MAX(0,(((cf_arr*(1+$B26)^I22)*IF(I22>=a_churn_year,1-0,1))*(MIN(a_m0+a_mstep*I22,a_mcap)-a_da)-IF(I22=a_churn_year,a_sticky*((cf_arr*(1+$B26)^I22)-((cf_arr*(1+$B26)^I22)*IF(I22>=a_churn_year,1-0,1)))*(1-MIN(a_m0+a_mstep*I22,a_mcap)),0)))*a_tax+((cf_arr*(1+$B26)^I22)*IF(I22>=a_churn_year,1-0,1))*a_da-((cf_arr*(1+$B26)^I22)*IF(I22>=a_churn_year,1-0,1))*a_capex-a_wc*(((cf_arr*(1+$B26)^I22)*IF(I22>=a_churn_year,1-0,1))-(cf_arr*(1+$B26)^H22*IF(H22>=a_churn_year,1-0,1))) -> 130.08118 | J26: =(((cf_arr*(1+$B26)^J22)*IF(J22>=a_churn_year,1-0,1))*(MIN(a_m0+a_mstep*J22,a_mcap)-a_da)-IF(J22=a_churn_year,a_sticky*((cf_arr*(1+$B26)^J22)-((cf_arr*(1+$B26)^J22)*IF(J22>=a_churn_year,1-0,1)))*(1-MIN(a_m0+a_mstep*J22,a_mcap)),0))-MAX(0,(((cf_arr*(1+$B26)^J22)*IF(J22>=a_churn_year,1-0,1))*(MIN(a_m0+a_mstep*J22,a_mcap)-a_da)-IF(J22=a_churn_year,a_sticky*((cf_arr*(1+$B26)^J22)-((cf_arr*(1+$B26)^J22)*IF(J22>=a_churn_year,1-0,1)))*(1-MIN(a_m0+a_mstep*J22,a_mcap)),0)))*a_tax+((cf_arr*(1+$B26)^J22)*IF(J22>=a_churn_year,1-0,1))*a_da-((cf_arr*(1+$B26)^J22)*IF(J22>=a_churn_year,1-0,1))*a_capex-a_wc*(((cf_arr*(1+$B26)^J22)*IF(J22>=a_churn_year,1-0,1))-(cf_arr*(1+$B26)^I22*IF(I22>=a_churn_year,1-0,1))) -> 162.60147 | K26: =(((cf_arr*(1+$B26)^K22)*IF(K22>=a_churn_year,1-0,1))*(MIN(a_m0+a_mstep*K22,a_mcap)-a_da)-IF(K22=a_churn_year,a_sticky*((cf_arr*(1+$B26)^K22)-((cf_arr*(1+$B26)^K22)*IF(K22>=a_churn_year,1-0,1)))*(1-MIN(a_m0+a_mstep*K22,a_mcap)),0))-MAX(0,(((cf_arr*(1+$B26)^K22)*IF(K22>=a_churn_year,1-0,1))*(MIN(a_m0+a_mstep*K22,a_mcap)-a_da)-IF(K22=a_churn_year,a_sticky*((cf_arr*(1+$B26)^K22)-((cf_arr*(1+$B26)^K22)*IF(K22>=a_churn_year,1-0,1)))*(1-MIN(a_m0+a_mstep*K22,a_mcap)),0)))*a_tax+((cf_arr*(1+$B26)^K22)*IF(K22>=a_churn_year,1-0,1))*a_da-((cf_arr*(1+$B26)^K22)*IF(K22>=a_churn_year,1-0,1))*a_capex-a_wc*(((cf_arr*(1+$B26)^K22)*IF(K22>=a_churn_year,1-0,1))-(cf_arr*(1+$B26)^J22*IF(J22>=a_churn_year,1-0,1))) -> 203.25184 | ... M26: =(((cf_arr*(1+$B26)^M22)*IF(M22>=a_churn_year,1-0,1))*(MIN(a_m0+a_mstep*M22,a_mcap)-a_da)-IF(M22=a_churn_year,a_sticky*((cf_arr*(1+$B26)^M22)-((cf_arr*(1+$B26)^M22)*IF(M22>=a_churn_year,1-0,1)))*(1-MIN(a_m0+a_mstep*M22,a_mcap)),0))-MAX(0,(((cf_arr*(1+$B26)^M22)*IF(M22>=a_churn_year,1-0,1))*(MIN(a_m0+a_mstep*M22,a_mcap)-a_da)-IF(M22=a_churn_year,a_sticky*((cf_arr*(1+$B26)^M22)-((cf_arr*(1+$B26)^M22)*IF(M22>=a_churn_year,1-0,1)))*(1-MIN(a_m0+a_mstep*M22,a_mcap)),0)))*a_tax+((cf_arr*(1+$B26)^M22)*IF(M22>=a_churn_year,1-0,1))*a_da-((cf_arr*(1+$B26)^M22)*IF(M22>=a_churn_year,1-0,1))*a_capex-a_wc*(((cf_arr*(1+$B26)^M22)*IF(M22>=a_churn_year,1-0,1))-(cf_arr*(1+$B26)^L22*IF(L22>=a_churn_year,1-0,1))) -> 317.581
