Workbook

Sheet Cover
B2: PROJECT SATOSHI GATE
B3: Paytm × Liminal Custody Solutions — Accretion/Dilution and Transaction Model
B4: Board Transaction Recommendation · Team ETERNAL · September 2026
B6: Recommendation | C6: Do not acquire 100% of Liminal today. Pursue a 20–30% strategic minority investment (25% midpoint) with a commercial custody/MPC partnership, standalone governance, a pre-agreed call option for future control and retention-linked future consideration.
B8: Sheet | C8: Purpose
B9: 1. Inputs | C9: Case facts (source: case document) and team assumptions. Blue cells are the only cells to edit.
B10: 2. Valuation & Churn | C10: Headline multiple, churn sensitivity, implied value at 18.2× and revenue recovery hurdle.
B11: 3. Financing & EPS | C11: Full-acquisition financing mixes (cash / debt / equity), mechanical and full EPS dilution from the ₹7.50 baseline; Phase-1 minority structure.
B12: 4. Liminal Projection | C12: 10-year Liminal ARR, EBITDA, PAT and FCF under team growth and margin assumptions; churned path for the full-acquisition counterfactual.
B13: 5. PAT & FCF Breakeven | C13: Incremental PAT and FCF by year for full acquisition, Phase-1 minority and control exercise; ₹750 Cr capital drag; ₹115 Cr UPI MDR treated as a Paytm standalone offset.
B14: 6. Call Option & Earn-out | C14: Retention-linked control consideration: valuation cap, upfront and earn-out tied to retained ARR.
B15: 7. Sensitivities | C15: Year-1 EPS and FCF sensitivity grids across churn, growth, cash yield and capital-drag treatment; downside triggers.
B17: Legend
B18: Blue font | C18: Hard-coded input (case fact or team assumption)
B19: Black font | C19: Formula
B20: Green font | C20: Link to another sheet
B21: Light blue fill | C21: Section header
B22: Light yellow fill | C22: Key output
B24: Conventions
B25: 1. | C25: All amounts in ₹ Cr unless stated; shares in Cr; EPS in ₹ per share.
B26: 2. | C26: CASE FACT ≠ DERIVED CALCULATION ≠ TEAM ASSUMPTION — every input is labelled by category on the Inputs sheet.
B27: 3. | C27: The ₹115 Cr/year UPI MDR benefit is Paytm standalone net revenue, not a Liminal transaction synergy; it is modelled as a separate offset.
B28: 4. | C28: Negative numbers in parentheses; zero shown as "-".

Sheet Summary
B2: Summary of key outputs
B3: Live links to the model — recommendation: 25% minority + partnership + call option; control only after gates clear
B5: Output | C5: Value | D5: Where
B6: Headline multiple (deal value / ARR) | C6: =Inputs!$C$68 -> 18.181818 | D6: Inputs / Valuation & Churn
B7: Effective multiple at 45% churn | C7: ='Valuation & Churn'!E11 -> 33.057851 | D7: Valuation & Churn
B8: Implied value at 18.2× after 30% / 45% churn (₹ Cr) | C8: ='Valuation & Churn'!F9 -> 2800 | D8: Valuation & Churn (see F11 for 45%)
B9: Growth required to recover ₹220 Cr after 45% churn | C9: ='Valuation & Churn'!E17 -> 0.81818182 | D9: Valuation & Churn
B10: Mechanical EPS dilution — headline mix (share count only) | C10: ='Financing & EPS'!C10 -> -0.015748031 | D10: Financing & EPS
B11: Year-1 EPS — full acquisition, headline mix, incl. financing costs (₹) | C11: ='Financing & EPS'!C26 -> 5.2941991 | D11: Financing & EPS
B12: Year-1 EPS — Phase-1 minority, economic basis (₹) | C12: ='Financing & EPS'!C46 -> 6.8355469 | D12: Financing & EPS
B13: Cash remaining after Phase 1 (₹ Cr) | C13: ='Financing & EPS'!C41 -> 7885 | D13: Financing & EPS
B14: Full acquisition — first year of PAT breakeven | C14: ='PAT & FCF Breakeven'!C31 -> 8 | D14: PAT & FCF Breakeven
B15: Full acquisition — first year of FCF breakeven (after ₹750 Cr drag) | C15: ='PAT & FCF Breakeven'!C32 -> Not within 10 years | D15: PAT & FCF Breakeven
B16: Control exercise — first year of FCF breakeven (drag per Inputs) | C16: ='PAT & FCF Breakeven'!C76 -> Not within 10 years | D16: PAT & FCF Breakeven
B17: UPI MDR as % of capital drag — gross / after conversion | C17: =Inputs!$C$77 -> 0.15333333 | D17: Inputs (see next line)
B18: UPI MDR as % of capital drag — after conversion | C18: =Inputs!$C$78 -> 0.092 | D18: Inputs
B19: 10-year NPV of capital drag at WACC (₹ Cr) | C19: =Inputs!$C$79 -> 4237.6673 | D19: Inputs
B20: Maximum total consideration incl. Phase 1 (₹ Cr) | C20: ='Call Option & Earn-out'!C10 -> 4000 | D20: Call Option & Earn-out
B21: Maximum unconditional consideration (₹ Cr) | C21: ='Call Option & Earn-out'!C11 -> 1000 | D21: Call Option & Earn-out
B22: Standalone DCF value at base growth (₹ Cr) and verdict | C22: ='Valuation & Churn'!G36 -> 1753.3618 | D22: Valuation & Churn

Sheet Inputs
B2: 1. Inputs
B3: Blue cells are inputs. Category: CF = case fact · TA = team assumption. Source noted per line.
B5: Item | C5: Value | D5: Category | E5: Source / note
B6: PAYTM — baseline financials
B7: Market capitalisation (₹ Cr) | C7: 118750 | D7: CF | E7: Case §1: ₹1,18,750 Cr (~$14B), mid-September 2026
B8: Diluted shares outstanding (Cr) | C8: 64 | D8: CF | E8: Case §1 baseline financials
B9: Cash (₹ Cr) | C9: 8900 | D9: CF | E9: Case §1
B10: Gross debt (₹ Cr) | C10: 350 | D10: CF | E10: Case §1
B11: Trailing revenue (₹ Cr) | C11: 8450 | D11: CF | E11: Case §1
B12: EBITDA (₹ Cr) | C12: 640 | D12: CF | E12: Case §1
B13: PAT (₹ Cr) | C13: 480 | D13: CF | E13: Case §1
B14: Diluted EPS (₹) — starting point for all dilution | C14: 7.5 | D14: CF | E14: Case §1: use as starting point for Section 5.3
B15: Credit rating | C15: CRISIL AA− (Stable) | D15: CF | E15: Case §1
B17: LIMINAL / DEAL — case terms
B18: Headline acquisition value (₹ Cr) | C18: 4000 | D18: CF | E18: Case §2: ₹4,000 Cr (~$470M)
B19: Headline cash consideration (₹ Cr) | C19: 2100 | D19: CF | E19: Case §2
B20: Headline equity consideration (₹ Cr) | C20: 1900 | D20: CF | E20: Case §2
B21: Liminal ARR (₹ Cr) | C21: 220 | D21: CF | E21: Case §2: ₹220 Cr (~$26M)
B22: Liminal current PAT (₹ Cr) | C22: 0 | D22: CF | E22: Case §2: approximately breakeven at net income level
B23: Four largest clients — share of ARR | C23: 0.6 | D23: CF | E23: Case §2: HDFC Bank, Axis Bank, CoinDCX, ZebPay
B24: Full-acquisition ARR churn — low | C24: 0.3 | D24: CF | E24: Case §3.1: 30% to 45% lost within 12 months
B25: Full-acquisition ARR churn — high | C25: 0.45 | D25: CF | E25: Case §3.1
B26: Full-control capital drag — recurring annual FCF (₹ Cr) | C26: 750 | D26: CF | E26: Case §3.2: bank-like capital reserves
B27: UPI MDR — incremental net revenue to Paytm (₹ Cr/yr) | C27: 115 | D27: CF | E27: Case §3.4: real, effective 15 Oct 2026; Paytm standalone
B29: TEAM ASSUMPTIONS — transaction structure
B30: Initial minority ownership | C30: 0.25 | D30: TA | E30: Midpoint of the permitted 20–30% range
B31: Minority priced pro-rata to headline value? (1 = yes) | C31: 1 | D31: TA | E31: Illustrative: ₹1,000 Cr = 25% × ₹4,000 Cr
B32: Phase-1 funding — share from existing cash | C32: 1 | D32: TA | E32: No new debt, no new equity issuance in Phase 1
B33: Phase-1 transaction fees (₹ Cr) | C33: 15 | D33: TA | E33: One-time
B34: Validation period before option window (months) | C34: 12 | D34: TA | E34: Phase 2 · 3–12 months
B35: Call-option window (months, after validation) | C35: 12 | D35: TA | E35: Phase 3 · ~12 months+
B36: Control-tranche upfront share of cap | C36: 0.55 | D36: TA | E36: Balance is retention-linked earn-out
B37: Earn-out floor — retained ARR at which earn-out is zero | C37: 0.55 | D37: TA | E37: Mirrors case high-churn bound (45% churn)
B38: Earn-out paid in Paytm shares? (1 = shares, 0 = cash) | C38: 1 | D38: TA | E38: Contingent equity, collared
B39: Integration cost at control (₹ Cr, one-time) | C39: 100 | D39: TA | E39: Cash and P&L, year of exercise
B40: Control-exercise cash portion (₹ Cr) | C40: 1200 | D40: TA | E40: Balance of upfront funded by new debt
B42: TEAM ASSUMPTIONS — financing, tax, returns
B43: Pre-tax yield on Paytm surplus cash | C43: 0.06 | D43: TA | E43: Foregone treasury income on cash used
B44: Pre-tax cost of new debt (CRISIL AA− issuer) | C44: 0.085 | D44: TA | E44: Financing cost on debt-funded consideration
B45: Corporate tax rate | C45: 0.25 | D45: TA | E45: Applied to interest, foregone income and Liminal profits
...

Sheet Valuation & Churn
B2: 2. Valuation & Churn
B3: 18.2× headline ARR becomes 26–33× on retained ARR under full-control churn
B5: Headline valuation | C5: =Inputs!$C$18 -> 4000 | D5: ÷ ARR | E5: =Inputs!$C$21 -> 220 | F5: → multiple | G5: =Inputs!$C$68 -> 18.181818
B7: Full-control churn | C7: ARR lost (₹ Cr) | D7: Retained ARR (₹ Cr) | E7: ₹4,000 Cr / retained ARR | F7: Implied value at headline multiple (₹ Cr) | G7: Value gap vs ₹4,000 Cr
B8: 0 | C8: =Inputs!$C$21*B8 -> 0 | D8: =Inputs!$C$21-C8 -> 220 | E8: =Inputs!$C$18/D8 -> 18.181818 | F8: =Inputs!$C$68*D8 -> 4000 | G8: =Inputs!$C$18-F8 -> 0
B9: =Inputs!$C$24 -> 0.3 | C9: =Inputs!$C$21*B9 -> 66 | D9: =Inputs!$C$21-C9 -> 154 | E9: =Inputs!$C$18/D9 -> 25.974026 | F9: =Inputs!$C$68*D9 -> 2800 | G9: =Inputs!$C$18-F9 -> 1200
B10: =Inputs!$C$57 -> 0.375 | C10: =Inputs!$C$21*B10 -> 82.5 | D10: =Inputs!$C$21-C10 -> 137.5 | E10: =Inputs!$C$18/D10 -> 29.090909 | F10: =Inputs!$C$68*D10 -> 2500 | G10: =Inputs!$C$18-F10 -> 1500
B11: =Inputs!$C$25 -> 0.45 | C11: =Inputs!$C$21*B11 -> 99 | D11: =Inputs!$C$21-C11 -> 121 | E11: =Inputs!$C$18/D11 -> 33.057851 | F11: =Inputs!$C$68*D11 -> 2200 | G11: =Inputs!$C$18-F11 -> 1800
B13: Value destroyed per 10 pts of churn at headline multiple (₹ Cr) | E13: =Inputs!$C$68*Inputs!$C$21*0.1 -> 400
B15: Revenue recovery hurdle | C15: Retained ARR (₹ Cr) | D15: Original ARR (₹ Cr) | E15: Growth required to recover
B16: After 30% churn | C16: =D9 -> 154 | D16: =Inputs!$C$21 -> 220 | E16: =D16/C16-1 -> 0.42857143
B17: After 45% churn | C17: =D11 -> 121 | D17: =Inputs!$C$21 -> 220 | E17: =D17/C17-1 -> 0.81818182
B19: Top-4 client concentration | C19: =Inputs!$C$23 -> 0.6 | D19: ARR (₹ Cr) | E19: =Inputs!$C$21*C19 -> 132
B20: Case churn as % of top-4 ARR — low | E20: =Inputs!$C$24*Inputs!$C$21/E19 -> 0.5
B21: Case churn as % of top-4 ARR — high | E21: =Inputs!$C$25*Inputs!$C$21/E19 -> 0.75
B23: DCF cross-check — what growth does ₹4,000 Cr require? (team assumptions, standalone, no churn, no drag)
B24: Year | C24: ARR (₹ Cr) | D24: EBITDA margin | E24: FCF (₹ Cr) | F24: Discount factor | G24: PV (₹ Cr)
B25: 1 | C25: =Inputs!$C$21*(1+Inputs!$C$52)^B25 -> 264 | D25: =MIN(Inputs!$C$53*B25,Inputs!$C$54) -> 0.05 | E25: =C25*D25*Inputs!$C$55*Inputs!$C$56 -> 9.9 | F25: =1/(1+Inputs!$C$46)^B25 -> 0.89285714 | G25: =E25*F25 -> 8.8392857
B26: 2 | C26: =Inputs!$C$21*(1+Inputs!$C$52)^B26 -> 316.8 | D26: =MIN(Inputs!$C$53*B26,Inputs!$C$54) -> 0.1 | E26: =C26*D26*Inputs!$C$55*Inputs!$C$56 -> 23.76 | F26: =1/(1+Inputs!$C$46)^B26 -> 0.79719388 | G26: =E26*F26 -> 18.941327
B27: 3 | C27: =Inputs!$C$21*(1+Inputs!$C$52)^B27 -> 380.16 | D27: =MIN(Inputs!$C$53*B27,Inputs!$C$54) -> 0.15 | E27: =C27*D27*Inputs!$C$55*Inputs!$C$56 -> 42.768 | F27: =1/(1+Inputs!$C$46)^B27 -> 0.71178025 | G27: =E27*F27 -> 30.441418
B28: 4 | C28: =Inputs!$C$21*(1+Inputs!$C$52)^B28 -> 456.192 | D28: =MIN(Inputs!$C$53*B28,Inputs!$C$54) -> 0.2 | E28: =C28*D28*Inputs!$C$55*Inputs!$C$56 -> 68.4288 | F28: =1/(1+Inputs!$C$46)^B28 -> 0.63551808 | G28: =E28*F28 -> 43.487739
B29: 5 | C29: =Inputs!$C$21*(1+Inputs!$C$52)^B29 -> 547.4304 | D29: =MIN(Inputs!$C$53*B29,Inputs!$C$54) -> 0.25 | E29: =C29*D29*Inputs!$C$55*Inputs!$C$56 -> 102.6432 | F29: =1/(1+Inputs!$C$46)^B29 -> 0.56742686 | G29: =E29*F29 -> 58.242508
B30: 6 | C30: =Inputs!$C$21*(1+Inputs!$C$52)^B30 -> 656.91648 | D30: =MIN(Inputs!$C$53*B30,Inputs!$C$54) -> 0.25 | E30: =C30*D30*Inputs!$C$55*Inputs!$C$56 -> 123.17184 | F30: =1/(1+Inputs!$C$46)^B30 -> 0.50663112 | G30: =E30*F30 -> 62.402687
B31: 7 | C31: =Inputs!$C$21*(1+Inputs!$C$52)^B31 -> 788.29978 | D31: =MIN(Inputs!$C$53*B31,Inputs!$C$54) -> 0.25 | E31: =C31*D31*Inputs!$C$55*Inputs!$C$56 -> 147.80621 | F31: =1/(1+Inputs!$C$46)^B31 -> 0.45234922 | G31: =E31*F31 -> 66.860022
B32: 8 | C32: =Inputs!$C$21*(1+Inputs!$C$52)^B32 -> 945.95973 | D32: =MIN(Inputs!$C$53*B32,Inputs!$C$54) -> 0.25 | E32: =C32*D32*Inputs!$C$55*Inputs!$C$56 -> 177.36745 | F32: =1/(1+Inputs!$C$46)^B32 -> 0.40388323 | G32: =E32*F32 -> 71.635738
B33: 9 | C33: =Inputs!$C$21*(1+Inputs!$C$52)^B33 -> 1135.1517 | D33: =MIN(Inputs!$C$53*B33,Inputs!$C$54) -> 0.25 | E33: =C33*D33*Inputs!$C$55*Inputs!$C$56 -> 212.84094 | F33: =1/(1+Inputs!$C$46)^B33 -> 0.36061002 | G33: =E33*F33 -> 76.752577
B34: 10 | C34: =Inputs!$C$21*(1+Inputs!$C$52)^B34 -> 1362.182 | D34: =MIN(Inputs!$C$53*B34,Inputs!$C$54) -> 0.25 | E34: =C34*D34*Inputs!$C$55*Inputs!$C$56 -> 255.40913 | F34: =1/(1+Inputs!$C$46)^B34 -> 0.32197324 | G34: =E34*F34 -> 82.234903
B35: Terminal value at year 10 | E35: =E34*(1+Inputs!$C$47)/(Inputs!$C$46-Inputs!$C$47) -> 3831.1369 | F35: =F34 -> 0.32197324 | G35: =E35*F35 -> 1233.5236
B36: Standalone DCF value (₹ Cr) | G36: =SUM(G25:G35) -> 1753.3618
B37: Implied DCF multiple of ARR | G37: =G36/Inputs!$C$21 -> 7.9698262
B38: Headline price supported by base-case DCF? | G38: =IF(G36>=Inputs!$C$18,"Supported","Not supported") -> Not supported
B39: Note: DCF value scales with the growth input on Inputs (base 20%). The Sensitivities sheet shows the value at 10% / 30% / 40%.

Sheet Financing & EPS
B2: 3. Financing & EPS
B3: Year-1 accretion / dilution from the ₹7.50 baseline under alternative financing mixes; recommended Phase-1 structure
B5: A. Mechanical dilution — headline mix, share count only (as in the deck)
B6: Implied Paytm share price (₹) | C6: =Inputs!$C$67 -> 1855.4688
B7: ₹1,900 Cr equity consideration → new shares (Cr) | C7: =Inputs!$C$20/C6 -> 1.024
B8: Pro-forma diluted shares (Cr) | C8: =Inputs!$C$8+C7 -> 65.024
B9: EPS if PAT remains ₹480 Cr (₹) | C9: =Inputs!$C$13/C8 -> 7.3818898
B10: Mechanical dilution vs ₹7.50 baseline | C10: =C9/Inputs!$C$14-1 -> -0.015748031
B11: Cash after ₹2,100 Cr funded from balance sheet (₹ Cr) | C11: =Inputs!$C$9-Inputs!$C$19 -> 6800
B13: B. Full-acquisition year-1 EPS — including financing costs and post-churn Liminal result
B14: Line item (₹ Cr unless stated) | C14: Case headline: ₹2,100 cash + ₹1,900 equity | D14: Debt-funded: ₹2,100 debt + ₹1,900 equity | E14: Mix: ₹1,400 cash + ₹700 debt + ₹1,900 equity | F14: All cash ₹4,000 | G14: All equity ₹4,000
B15: Cash from balance sheet | C15: 2100 | D15: 0 | E15: 1400 | F15: 4000 | G15: 0
B16: New debt | C16: 0 | D16: 2100 | E16: 700 | F16: 0 | G16: 0
B17: Equity issued | C17: 1900 | D17: 1900 | E17: 1900 | F17: 0 | G17: 4000
B18: New shares issued (Cr) | C18: =C17/Inputs!$C$67 -> 1.024 | D18: =D17/Inputs!$C$67 -> 1.024 | E18: =E17/Inputs!$C$67 -> 1.024 | F18: =F17/Inputs!$C$67 -> 0 | G18: =G17/Inputs!$C$67 -> 2.1557895
B19: Pro-forma diluted shares (Cr) | C19: =Inputs!$C$8+C18 -> 65.024 | D19: =Inputs!$C$8+D18 -> 65.024 | E19: =Inputs!$C$8+E18 -> 65.024 | F19: =Inputs!$C$8+F18 -> 64 | G19: =Inputs!$C$8+G18 -> 66.155789
B20: Foregone post-tax interest on cash used | C20: =-C15*Inputs!$C$43*(1-Inputs!$C$45) -> -94.5 | D20: =-D15*Inputs!$C$43*(1-Inputs!$C$45) -> 0 | E20: =-E15*Inputs!$C$43*(1-Inputs!$C$45) -> -63 | F20: =-F15*Inputs!$C$43*(1-Inputs!$C$45) -> -180 | G20: =-G15*Inputs!$C$43*(1-Inputs!$C$45) -> 0
B21: Post-tax interest on new debt | C21: =-C16*Inputs!$C$44*(1-Inputs!$C$45) -> 0 | D21: =-D16*Inputs!$C$44*(1-Inputs!$C$45) -> -133.875 | E21: =-E16*Inputs!$C$44*(1-Inputs!$C$45) -> -44.625 | F21: =-F16*Inputs!$C$44*(1-Inputs!$C$45) -> 0 | G21: =-G16*Inputs!$C$44*(1-Inputs!$C$45) -> 0
B22: Liminal year-1 PAT after churn (from Projection) | C22: ='Liminal Projection'!$D$25 -> -41.25 | D22: ='Liminal Projection'!$D$25 -> -41.25 | E22: ='Liminal Projection'!$D$25 -> -41.25 | F22: ='Liminal Projection'!$D$25 -> -41.25 | G22: ='Liminal Projection'!$D$25 -> -41.25
B23: Synergies (base) | C23: =Inputs!$C$64 -> 0 | D23: =Inputs!$C$64 -> 0 | E23: =Inputs!$C$64 -> 0 | F23: =Inputs!$C$64 -> 0 | G23: =Inputs!$C$64 -> 0
B24: Incremental PAT | C24: =SUM(C20:C23) -> -135.75 | D24: =SUM(D20:D23) -> -175.125 | E24: =SUM(E20:E23) -> -148.875 | F24: =SUM(F20:F23) -> -221.25 | G24: =SUM(G20:G23) -> -41.25
B25: Pro-forma PAT | C25: =Inputs!$C$13+C24 -> 344.25 | D25: =Inputs!$C$13+D24 -> 304.875 | E25: =Inputs!$C$13+E24 -> 331.125 | F25: =Inputs!$C$13+F24 -> 258.75 | G25: =Inputs!$C$13+G24 -> 438.75
B26: Year-1 EPS (₹) | C26: =C25/C19 -> 5.2941991 | D26: =D25/D19 -> 4.6886534 | E26: =E25/E19 -> 5.0923505 | F26: =F25/F19 -> 4.0429688 | G26: =G25/G19 -> 6.6320726
B27: Accretion / (dilution) vs ₹7.50 | C27: =C26/Inputs!$C$14-1 -> -0.29410679 | D27: =D26/Inputs!$C$14-1 -> -0.37484621 | E27: =E26/Inputs!$C$14-1 -> -0.32101993 | F27: =F26/Inputs!$C$14-1 -> -0.4609375 | G27: =G26/Inputs!$C$14-1 -> -0.11572365
B28: + UPI MDR standalone offset → EPS (₹) | C28: =(C25+Inputs!$C$76)/C19 -> 6.3553457 | D28: =(D25+Inputs!$C$76)/D19 -> 5.7498001 | E28: =(E25+Inputs!$C$76)/E19 -> 6.1534972 | F28: =(F25+Inputs!$C$76)/F19 -> 5.1210938 | G28: =(G25+Inputs!$C$76)/G19 -> 7.6750652
B29: Cash after transaction | C29: =Inputs!$C$9-C15 -> 6800 | D29: =Inputs!$C$9-D15 -> 8900 | E29: =Inputs!$C$9-E15 -> 7500 | F29: =Inputs!$C$9-F15 -> 4900 | G29: =Inputs!$C$9-G15 -> 8900
B30: Gross debt after transaction | C30: =Inputs!$C$10+C16 -> 350 | D30: =Inputs!$C$10+D16 -> 2450 | E30: =Inputs!$C$10+E16 -> 1050 | F30: =Inputs!$C$10+F16 -> 350 | G30: =Inputs!$C$10+G16 -> 350
B31: Gross debt / EBITDA | C31: =C30/Inputs!$C$12 -> 0.546875 | D31: =D30/Inputs!$C$12 -> 3.828125 | E31: =E30/Inputs!$C$12 -> 1.640625 | F31: =F30/Inputs!$C$12 -> 0.546875 | G31: =G30/Inputs!$C$12 -> 0.546875
B32: Within guardrails? (cash ≥ floor and leverage ≤ max) | C32: =IF(AND(C29>=Inputs!$C$48,C31<=Inputs!$C$49),"Yes","No") -> Yes | D32: =IF(AND(D29>=Inputs!$C$48,D31<=Inputs!$C$49),"Yes","No") -> No | E32: =IF(AND(E29>=Inputs!$C$48,E31<=Inputs!$C$49),"Yes","No") -> No | F32: =IF(AND(F29>=Inputs!$C$48,F31<=Inputs!$C$49),"Yes","No") -> No | G32: =IF(AND(G29>=Inputs!$C$48,G31<=Inputs!$C$49),"Yes","No") -> Yes
B34: Note: Liminal year-1 PAT after churn is negative because 50% of the lost revenue’s cost base is assumed to persist for one year (Inputs). No group tax relief is assumed on Liminal losses.
B36: C. Recommended Phase-1 structure — 25% minority for ₹1,000 Cr, funded from existing cash
B37: Phase-1 investment (₹ Cr) | C37: =Inputs!$C$70 -> 1000
B38: Funded from existing cash (₹ Cr) | C38: =C37*Inputs!$C$32 -> 1000
B39: New debt (₹ Cr) | C39: =C37-C38 -> 0
B40: New shares issued (Cr) | C40: 0
B41: Cash remaining (₹ Cr) | C41: =Inputs!$C$9-C38-Inputs!$C$33 -> 7885
B42: Gross debt / EBITDA after Phase 1 | C42: =(Inputs!$C$10+C39)/Inputs!$C$12 -> 0.546875
B43: Immediate share-count dilution | C43: =C40/Inputs!$C$8 -> 0
B44: Foregone post-tax interest on cash used (₹ Cr/yr) | C44: =-C38*Inputs!$C$43*(1-Inputs!$C$45) -> -45
B45: Paytm share of Liminal year-1 PAT (equity method, ₹ Cr) | C45: =Inputs!$C$30*'Liminal Projection'!$D$8 -> 2.475
...

Sheet Liminal Projection
B2: 4. Liminal Projection
B3: Standalone path (no churn) and churned path for the full-acquisition counterfactual — team assumptions
B5: A. Standalone path — no change of control (basis for Phase-1 minority)
B6: Year | C6: Y0 | D6: Y1 | E6: Y2 | F6: Y3 | G6: Y4 | H6: Y5 | I6: Y6 | J6: Y7 | K6: Y8 | L6: Y9 | M6: Y10
B7: ARR / revenue (₹ Cr) | C7: =Inputs!$C$21*(1+Inputs!$C$52)^0 -> 220 | D7: =Inputs!$C$21*(1+Inputs!$C$52)^1 -> 264 | E7: =Inputs!$C$21*(1+Inputs!$C$52)^2 -> 316.8 | F7: =Inputs!$C$21*(1+Inputs!$C$52)^3 -> 380.16 | G7: =Inputs!$C$21*(1+Inputs!$C$52)^4 -> 456.192 | H7: =Inputs!$C$21*(1+Inputs!$C$52)^5 -> 547.4304 | I7: =Inputs!$C$21*(1+Inputs!$C$52)^6 -> 656.91648 | J7: =Inputs!$C$21*(1+Inputs!$C$52)^7 -> 788.29978 | K7: =Inputs!$C$21*(1+Inputs!$C$52)^8 -> 945.95973 | L7: =Inputs!$C$21*(1+Inputs!$C$52)^9 -> 1135.1517 | M7: =Inputs!$C$21*(1+Inputs!$C$52)^10 -> 1362.182
B8: PAT (₹ Cr) | C8: =IF(C10>0,C10*Inputs!$C$55,C10) -> 0 | D8: =IF(D10>0,D10*Inputs!$C$55,D10) -> 9.9 | E8: =IF(E10>0,E10*Inputs!$C$55,E10) -> 23.76 | F8: =IF(F10>0,F10*Inputs!$C$55,F10) -> 42.768 | G8: =IF(G10>0,G10*Inputs!$C$55,G10) -> 68.4288 | H8: =IF(H10>0,H10*Inputs!$C$55,H10) -> 102.6432 | I8: =IF(I10>0,I10*Inputs!$C$55,I10) -> 123.17184 | J8: =IF(J10>0,J10*Inputs!$C$55,J10) -> 147.80621 | ... M8: =IF(M10>0,M10*Inputs!$C$55,M10) -> 255.40913
B9: EBITDA margin | C9: =MIN(Inputs!$C$53*0,Inputs!$C$54) -> 0 | D9: =MIN(Inputs!$C$53*1,Inputs!$C$54) -> 0.05 | E9: =MIN(Inputs!$C$53*2,Inputs!$C$54) -> 0.1 | F9: =MIN(Inputs!$C$53*3,Inputs!$C$54) -> 0.15 | G9: =MIN(Inputs!$C$53*4,Inputs!$C$54) -> 0.2 | H9: =MIN(Inputs!$C$53*5,Inputs!$C$54) -> 0.25 | I9: =MIN(Inputs!$C$53*6,Inputs!$C$54) -> 0.25 | J9: =MIN(Inputs!$C$53*7,Inputs!$C$54) -> 0.25 | K9: =MIN(Inputs!$C$53*8,Inputs!$C$54) -> 0.25 | L9: =MIN(Inputs!$C$53*9,Inputs!$C$54) -> 0.25 | M9: =MIN(Inputs!$C$53*10,Inputs!$C$54) -> 0.25
B10: EBITDA (₹ Cr) | C10: =C7*C9 -> 0 | D10: =D7*D9 -> 13.2 | E10: =E7*E9 -> 31.68 | F10: =F7*F9 -> 57.024 | G10: =G7*G9 -> 91.2384 | H10: =H7*H9 -> 136.8576 | I10: =I7*I9 -> 164.22912 | J10: =J7*J9 -> 197.07494 | ... M10: =M7*M9 -> 340.5455
B11: FCF (₹ Cr) | C11: =C8*Inputs!$C$56 -> 0 | D11: =D8*Inputs!$C$56 -> 9.9 | E11: =E8*Inputs!$C$56 -> 23.76 | F11: =F8*Inputs!$C$56 -> 42.768 | G11: =G8*Inputs!$C$56 -> 68.4288 | H11: =H8*Inputs!$C$56 -> 102.6432 | I11: =I8*Inputs!$C$56 -> 123.17184 | J11: =J8*Inputs!$C$56 -> 147.80621 | ... M11: =M8*Inputs!$C$56 -> 255.40913
B12: Paytm 25% share of PAT (₹ Cr) | C12: =Inputs!$C$30*C8 -> 0 | D12: =Inputs!$C$30*D8 -> 2.475 | E12: =Inputs!$C$30*E8 -> 5.94 | F12: =Inputs!$C$30*F8 -> 10.692 | G12: =Inputs!$C$30*G8 -> 17.1072 | H12: =Inputs!$C$30*H8 -> 25.6608 | I12: =Inputs!$C$30*I8 -> 30.79296 | J12: =Inputs!$C$30*J8 -> 36.951552 | ... M12: =Inputs!$C$30*M8 -> 63.852282
B14: B. Churned path — full acquisition today; churn in Y1, then growth on the retained base
B15: Churn applied | C15: =Inputs!$C$57 -> 0.375 | D15: Sticky cost share | E15: =Inputs!$C$58 -> 0.5
B16: Year | C16: Y0 | D16: Y1 | E16: Y2 | F16: Y3 | G16: Y4 | H16: Y5 | I16: Y6 | J16: Y7 | K16: Y8 | L16: Y9 | M16: Y10
B17: Revenue before churn (₹ Cr) | C17: =C7 -> 220 | D17: =D7 -> 264 | E17: =E7 -> 316.8 | F17: =F7 -> 380.16 | G17: =G7 -> 456.192 | H17: =H7 -> 547.4304 | I17: =I7 -> 656.91648 | J17: =J7 -> 788.29978 | ... M17: =M7 -> 1362.182
B18: Revenue after churn (₹ Cr) | C18: =C17*(1-IF(0>=1,$C$15,0)) -> 220 | D18: =D17*(1-IF(1>=1,$C$15,0)) -> 165 | E18: =E17*(1-IF(2>=1,$C$15,0)) -> 198 | F18: =F17*(1-IF(3>=1,$C$15,0)) -> 237.6 | G18: =G17*(1-IF(4>=1,$C$15,0)) -> 285.12 | H18: =H17*(1-IF(5>=1,$C$15,0)) -> 342.144 | I18: =I17*(1-IF(6>=1,$C$15,0)) -> 410.5728 | J18: =J17*(1-IF(7>=1,$C$15,0)) -> 492.68736 | K18: =K17*(1-IF(8>=1,$C$15,0)) -> 591.22483 | L18: =L17*(1-IF(9>=1,$C$15,0)) -> 709.4698 | M18: =M17*(1-IF(10>=1,$C$15,0)) -> 851.36376
B19: Lost revenue (₹ Cr) | C19: =C17-C18 -> 0 | D19: =D17-D18 -> 99 | E19: =E17-E18 -> 118.8 | F19: =F17-F18 -> 142.56 | G19: =G17-G18 -> 171.072 | H19: =H17-H18 -> 205.2864 | I19: =I17-I18 -> 246.34368 | J19: =J17-J18 -> 295.61242 | ... M19: =M17-M18 -> 510.81825
B20: EBITDA margin | C20: =C9 -> 0 | D20: =D9 -> 0.05 | E20: =E9 -> 0.1 | F20: =F9 -> 0.15 | G20: =G9 -> 0.2 | H20: =H9 -> 0.25 | I20: =I9 -> 0.25 | J20: =J9 -> 0.25 | ... M20: =M9 -> 0.25
B21: EBITDA before sticky cost (₹ Cr) | C21: =C18*C20 -> 0 | D21: =D18*D20 -> 8.25 | E21: =E18*E20 -> 19.8 | F21: =F18*F20 -> 35.64 | G21: =G18*G20 -> 57.024 | H21: =H18*H20 -> 85.536 | I21: =I18*I20 -> 102.6432 | J21: =J18*J20 -> 123.17184 | ... M21: =M18*M20 -> 212.84094
B22: Sticky cost penalty (₹ Cr) | C22: =IF(0=1,$E$15*C19,0) -> 0 | D22: =IF(1=1,$E$15*D19,0) -> 49.5 | E22: =IF(2=1,$E$15*E19,0) -> 0 | F22: =IF(3=1,$E$15*F19,0) -> 0 | G22: =IF(4=1,$E$15*G19,0) -> 0 | H22: =IF(5=1,$E$15*H19,0) -> 0 | I22: =IF(6=1,$E$15*I19,0) -> 0 | J22: =IF(7=1,$E$15*J19,0) -> 0 | K22: =IF(8=1,$E$15*K19,0) -> 0 | L22: =IF(9=1,$E$15*L19,0) -> 0 | M22: =IF(10=1,$E$15*M19,0) -> 0
B23: EBITDA (₹ Cr) | C23: =C21-C22 -> 0 | D23: =D21-D22 -> -41.25 | E23: =E21-E22 -> 19.8 | F23: =F21-F22 -> 35.64 | G23: =G21-G22 -> 57.024 | H23: =H21-H22 -> 85.536 | I23: =I21-I22 -> 102.6432 | J23: =J21-J22 -> 123.17184 | ... M23: =M21-M22 -> 212.84094
B24: PAT (₹ Cr) — no group tax relief on losses | C24: =IF(C23>0,C23*Inputs!$C$55,C23) -> 0 | D24: =IF(D23>0,D23*Inputs!$C$55,D23) -> -41.25 | E24: =IF(E23>0,E23*Inputs!$C$55,E23) -> 14.85 | F24: =IF(F23>0,F23*Inputs!$C$55,F23) -> 26.73 | G24: =IF(G23>0,G23*Inputs!$C$55,G23) -> 42.768 | H24: =IF(H23>0,H23*Inputs!$C$55,H23) -> 64.152 | I24: =IF(I23>0,I23*Inputs!$C$55,I23) -> 76.9824 | J24: =IF(J23>0,J23*Inputs!$C$55,J23) -> 92.37888 | ... M24: =IF(M23>0,M23*Inputs!$C$55,M23) -> 159.6307
B25: PAT — year 1 (₹ Cr) | D25: =D24 -> -41.25
B26: FCF (₹ Cr) | C26: =C24*Inputs!$C$56 -> 0 | D26: =D24*Inputs!$C$56 -> -41.25 | E26: =E24*Inputs!$C$56 -> 14.85 | F26: =F24*Inputs!$C$56 -> 26.73 | G26: =G24*Inputs!$C$56 -> 42.768 | H26: =H24*Inputs!$C$56 -> 64.152 | I26: =I24*Inputs!$C$56 -> 76.9824 | J26: =J24*Inputs!$C$56 -> 92.37888 | ... M26: =M24*Inputs!$C$56 -> 159.6307
B28: C. Control-exercise path — 25% held Y1; control at end-Y1; churn per consent gate in Y2, then growth
B29: Churn at control | C29: =Inputs!$C$62 -> 0.2
B30: Year | C30: Y0 | D30: Y1 | E30: Y2 | F30: Y3 | G30: Y4 | H30: Y5 | I30: Y6 | J30: Y7 | K30: Y8 | L30: Y9 | M30: Y10
B31: Revenue after churn (₹ Cr) | C31: =C7*(1-IF(0>=2,$C$29,0)) -> 220 | D31: =D7*(1-IF(1>=2,$C$29,0)) -> 264 | E31: =E7*(1-IF(2>=2,$C$29,0)) -> 253.44 | F31: =F7*(1-IF(3>=2,$C$29,0)) -> 304.128 | G31: =G7*(1-IF(4>=2,$C$29,0)) -> 364.9536 | H31: =H7*(1-IF(5>=2,$C$29,0)) -> 437.94432 | I31: =I7*(1-IF(6>=2,$C$29,0)) -> 525.53318 | J31: =J7*(1-IF(7>=2,$C$29,0)) -> 630.63982 | K31: =K7*(1-IF(8>=2,$C$29,0)) -> 756.76778 | L31: =L7*(1-IF(9>=2,$C$29,0)) -> 908.12134 | M31: =M7*(1-IF(10>=2,$C$29,0)) -> 1089.7456
B32: EBITDA (₹ Cr) | C32: =C31*C9-IF(0=2,$E$15*(C7-C31),0) -> 0 | D32: =D31*D9-IF(1=2,$E$15*(D7-D31),0) -> 13.2 | E32: =E31*E9-IF(2=2,$E$15*(E7-E31),0) -> -6.336 | F32: =F31*F9-IF(3=2,$E$15*(F7-F31),0) -> 45.6192 | G32: =G31*G9-IF(4=2,$E$15*(G7-G31),0) -> 72.99072 | H32: =H31*H9-IF(5=2,$E$15*(H7-H31),0) -> 109.48608 | I32: =I31*I9-IF(6=2,$E$15*(I7-I31),0) -> 131.3833 | J32: =J31*J9-IF(7=2,$E$15*(J7-J31),0) -> 157.65996 | K32: =K31*K9-IF(8=2,$E$15*(K7-K31),0) -> 189.19195 | L32: =L31*L9-IF(9=2,$E$15*(L7-L31),0) -> 227.03034 | M32: =M31*M9-IF(10=2,$E$15*(M7-M31),0) -> 272.4364
B33: PAT (₹ Cr) | C33: =IF(C32>0,C32*Inputs!$C$55,C32) -> 0 | D33: =IF(D32>0,D32*Inputs!$C$55,D32) -> 9.9 | E33: =IF(E32>0,E32*Inputs!$C$55,E32) -> -6.336 | F33: =IF(F32>0,F32*Inputs!$C$55,F32) -> 34.2144 | G33: =IF(G32>0,G32*Inputs!$C$55,G32) -> 54.74304 | H33: =IF(H32>0,H32*Inputs!$C$55,H32) -> 82.11456 | I33: =IF(I32>0,I32*Inputs!$C$55,I32) -> 98.537472 | J33: =IF(J32>0,J32*Inputs!$C$55,J32) -> 118.24497 | ... M33: =IF(M32>0,M32*Inputs!$C$55,M32) -> 204.3273
B34: FCF (₹ Cr) | C34: =C33*Inputs!$C$56 -> 0 | D34: =D33*Inputs!$C$56 -> 9.9 | E34: =E33*Inputs!$C$56 -> -6.336 | F34: =F33*Inputs!$C$56 -> 34.2144 | G34: =G33*Inputs!$C$56 -> 54.74304 | H34: =H33*Inputs!$C$56 -> 82.11456 | I34: =I33*Inputs!$C$56 -> 98.537472 | J34: =J33*Inputs!$C$56 -> 118.24497 | ... M34: =M33*Inputs!$C$56 -> 204.3273

Sheet PAT & FCF Breakeven
B2: 5. PAT & FCF Breakeven
B3: Two separate hurdles: accounting accretion (PAT / EPS) and cash-flow viability (FCF after the ₹750 Cr capital drag)
B5: A. Full acquisition today — case headline mix (₹2,100 Cr cash from balance sheet + ₹1,900 Cr equity)
B6: Year (₹ Cr) | C6: Y1 | D6: Y2 | E6: Y3 | F6: Y4 | G6: Y5 | H6: Y6 | I6: Y7 | J6: Y8 | K6: Y9 | L6: Y10
B7: Liminal PAT (churned path) | C7: ='Liminal Projection'!D24 -> -41.25 | D7: ='Liminal Projection'!E24 -> 14.85 | E7: ='Liminal Projection'!F24 -> 26.73 | F7: ='Liminal Projection'!G24 -> 42.768 | G7: ='Liminal Projection'!H24 -> 64.152 | H7: ='Liminal Projection'!I24 -> 76.9824 | I7: ='Liminal Projection'!J24 -> 92.37888 | J7: ='Liminal Projection'!K24 -> 110.85466 | ... L7: ='Liminal Projection'!M24 -> 159.6307
B8: Foregone post-tax interest on ₹2,100 Cr cash | C8: =-Inputs!$C$19*Inputs!$C$43*(1-Inputs!$C$45) -> -94.5 | D8: =-Inputs!$C$19*Inputs!$C$43*(1-Inputs!$C$45) -> -94.5 | E8: =-Inputs!$C$19*Inputs!$C$43*(1-Inputs!$C$45) -> -94.5 | F8: =-Inputs!$C$19*Inputs!$C$43*(1-Inputs!$C$45) -> -94.5 | G8: =-Inputs!$C$19*Inputs!$C$43*(1-Inputs!$C$45) -> -94.5 | H8: =-Inputs!$C$19*Inputs!$C$43*(1-Inputs!$C$45) -> -94.5 | I8: =-Inputs!$C$19*Inputs!$C$43*(1-Inputs!$C$45) -> -94.5 | J8: =-Inputs!$C$19*Inputs!$C$43*(1-Inputs!$C$45) -> -94.5 | ... L8: =-Inputs!$C$19*Inputs!$C$43*(1-Inputs!$C$45) -> -94.5
B9: Post-tax interest on new debt | C9: =-0*Inputs!$C$44*(1-Inputs!$C$45) -> 0 | D9: =-0*Inputs!$C$44*(1-Inputs!$C$45) -> 0 | E9: =-0*Inputs!$C$44*(1-Inputs!$C$45) -> 0 | F9: =-0*Inputs!$C$44*(1-Inputs!$C$45) -> 0 | G9: =-0*Inputs!$C$44*(1-Inputs!$C$45) -> 0 | H9: =-0*Inputs!$C$44*(1-Inputs!$C$45) -> 0 | I9: =-0*Inputs!$C$44*(1-Inputs!$C$45) -> 0 | J9: =-0*Inputs!$C$44*(1-Inputs!$C$45) -> 0 | ... L9: =-0*Inputs!$C$44*(1-Inputs!$C$45) -> 0
B10: Synergies (base) | C10: =Inputs!$C$64 -> 0 | D10: =Inputs!$C$64 -> 0 | E10: =Inputs!$C$64 -> 0 | F10: =Inputs!$C$64 -> 0 | G10: =Inputs!$C$64 -> 0 | H10: =Inputs!$C$64 -> 0 | I10: =Inputs!$C$64 -> 0 | J10: =Inputs!$C$64 -> 0 | ... L10: =Inputs!$C$64 -> 0
B11: Integration / one-time costs — excluded from run-rate EPS (in FCF below) | C11: 0 | D11: 0 | E11: 0 | F11: 0 | G11: 0 | H11: 0 | I11: 0 | J11: 0 | K11: 0 | L11: 0
B12: Incremental PAT | C12: =SUM(C7:C11) -> -135.75 | D12: =SUM(D7:D11) -> -79.65 | E12: =SUM(E7:E11) -> -67.77 | F12: =SUM(F7:F11) -> -51.732 | G12: =SUM(G7:G11) -> -30.348 | H12: =SUM(H7:H11) -> -17.5176 | I12: =SUM(I7:I11) -> -2.12112 | J12: =SUM(J7:J11) -> 16.354656 | ... L12: =SUM(L7:L11) -> 65.130705
B13: Pro-forma PAT | C13: =Inputs!$C$13+C12 -> 344.25 | D13: =Inputs!$C$13+D12 -> 400.35 | E13: =Inputs!$C$13+E12 -> 412.23 | F13: =Inputs!$C$13+F12 -> 428.268 | G13: =Inputs!$C$13+G12 -> 449.652 | H13: =Inputs!$C$13+H12 -> 462.4824 | I13: =Inputs!$C$13+I12 -> 477.87888 | J13: =Inputs!$C$13+J12 -> 496.35466 | ... L13: =Inputs!$C$13+L12 -> 545.1307
B14: Pro-forma diluted shares (Cr) | C14: ='Financing & EPS'!$C$19 -> 65.024 | D14: ='Financing & EPS'!$C$19 -> 65.024 | E14: ='Financing & EPS'!$C$19 -> 65.024 | F14: ='Financing & EPS'!$C$19 -> 65.024 | G14: ='Financing & EPS'!$C$19 -> 65.024 | H14: ='Financing & EPS'!$C$19 -> 65.024 | I14: ='Financing & EPS'!$C$19 -> 65.024 | J14: ='Financing & EPS'!$C$19 -> 65.024 | ... L14: ='Financing & EPS'!$C$19 -> 65.024
B15: Pro-forma EPS (₹) | C15: =C13/C14 -> 5.2941991 | D15: =D13/D14 -> 6.1569574 | E15: =E13/E14 -> 6.3396592 | F15: =F13/F14 -> 6.5863066 | G15: =G13/G14 -> 6.9151698 | H15: =H13/H14 -> 7.1124877 | I15: =I13/I14 -> 7.3492692 | J15: =J13/J14 -> 7.633407 | ... L15: =L13/L14 -> 8.3835308
B16: Accretion / (dilution) vs ₹7.50 | C16: =C15/Inputs!$C$14-1 -> -0.29410679 | D16: =D15/Inputs!$C$14-1 -> -0.17907234 | E16: =E15/Inputs!$C$14-1 -> -0.15471211 | F16: =F15/Inputs!$C$14-1 -> -0.12182579 | G16: =G15/Inputs!$C$14-1 -> -0.077977362 | H16: =H15/Inputs!$C$14-1 -> -0.051668307 | I16: =I15/Inputs!$C$14-1 -> -0.020097441 | J16: =J15/Inputs!$C$14-1 -> 0.017787598 | ... L16: =L15/Inputs!$C$14-1 -> 0.1178041
B17: Pro-forma EPS incl. UPI MDR standalone offset (₹) | C17: =(C13+Inputs!$C$76)/C14 -> 6.3553457 | D17: =(D13+Inputs!$C$76)/D14 -> 7.2181041 | E17: =(E13+Inputs!$C$76)/E14 -> 7.4008059 | F17: =(F13+Inputs!$C$76)/F14 -> 7.6474532 | G17: =(G13+Inputs!$C$76)/G14 -> 7.9763164 | H17: =(H13+Inputs!$C$76)/H14 -> 8.1736344 | I17: =(I13+Inputs!$C$76)/I14 -> 8.4104158 | J17: =(J13+Inputs!$C$76)/J14 -> 8.6945536 | ... L17: =(L13+Inputs!$C$76)/L14 -> 9.4446774
B19: Liminal FCF (churned path) | C19: ='Liminal Projection'!D26 -> -41.25 | D19: ='Liminal Projection'!E26 -> 14.85 | E19: ='Liminal Projection'!F26 -> 26.73 | F19: ='Liminal Projection'!G26 -> 42.768 | G19: ='Liminal Projection'!H26 -> 64.152 | H19: ='Liminal Projection'!I26 -> 76.9824 | I19: ='Liminal Projection'!J26 -> 92.37888 | J19: ='Liminal Projection'!K26 -> 110.85466 | ... L19: ='Liminal Projection'!M26 -> 159.6307
B20: Foregone post-tax interest (cash) | C20: =C8 -> -94.5 | D20: =D8 -> -94.5 | E20: =E8 -> -94.5 | F20: =F8 -> -94.5 | G20: =G8 -> -94.5 | H20: =H8 -> -94.5 | I20: =I8 -> -94.5 | J20: =J8 -> -94.5 | ... L20: =L8 -> -94.5
B21: Post-tax interest on new debt (cash) | C21: =C9 -> 0 | D21: =D9 -> 0 | E21: =E9 -> 0 | F21: =F9 -> 0 | G21: =G9 -> 0 | H21: =H9 -> 0 | I21: =I9 -> 0 | J21: =J9 -> 0 | ... L21: =L9 -> 0
B22: UPI MDR standalone offset (shown separately, not deal-driven) | C22: =Inputs!$C$76 -> 69 | D22: =Inputs!$C$76 -> 69 | E22: =Inputs!$C$76 -> 69 | F22: =Inputs!$C$76 -> 69 | G22: =Inputs!$C$76 -> 69 | H22: =Inputs!$C$76 -> 69 | I22: =Inputs!$C$76 -> 69 | J22: =Inputs!$C$76 -> 69 | ... L22: =Inputs!$C$76 -> 69
B23: Capital drag — ₹750 Cr recurring annual FCF | C23: =-Inputs!$C$61 -> -750 | D23: =-Inputs!$C$61 -> -750 | E23: =-Inputs!$C$61 -> -750 | F23: =-Inputs!$C$61 -> -750 | G23: =-Inputs!$C$61 -> -750 | H23: =-Inputs!$C$61 -> -750 | I23: =-Inputs!$C$61 -> -750 | J23: =-Inputs!$C$61 -> -750 | ... L23: =-Inputs!$C$61 -> -750
B24: Integration / one-time cash costs (Y1) | C24: =IF(1=1,-Inputs!$C$39,0) -> -100 | D24: =IF(2=1,-Inputs!$C$39,0) -> 0 | E24: =IF(3=1,-Inputs!$C$39,0) -> 0 | F24: =IF(4=1,-Inputs!$C$39,0) -> 0 | G24: =IF(5=1,-Inputs!$C$39,0) -> 0 | H24: =IF(6=1,-Inputs!$C$39,0) -> 0 | I24: =IF(7=1,-Inputs!$C$39,0) -> 0 | J24: =IF(8=1,-Inputs!$C$39,0) -> 0 | K24: =IF(9=1,-Inputs!$C$39,0) -> 0 | L24: =IF(10=1,-Inputs!$C$39,0) -> 0
B25: Incremental FCF (excluding MDR) | C25: =C19+C20+C21+C23+C24 -> -985.75 | D25: =D19+D20+D21+D23+D24 -> -829.65 | E25: =E19+E20+E21+E23+E24 -> -817.77 | F25: =F19+F20+F21+F23+F24 -> -801.732 | G25: =G19+G20+G21+G23+G24 -> -780.348 | H25: =H19+H20+H21+H23+H24 -> -767.5176 | I25: =I19+I20+I21+I23+I24 -> -752.12112 | J25: =J19+J20+J21+J23+J24 -> -733.64534 | ... L25: =L19+L20+L21+L23+L24 -> -684.8693
B26: Incremental FCF (crediting MDR) | C26: =C25+C22 -> -916.75 | D26: =D25+D22 -> -760.65 | E26: =E25+E22 -> -748.77 | F26: =F25+F22 -> -732.732 | G26: =G25+G22 -> -711.348 | H26: =H25+H22 -> -698.5176 | I26: =I25+I22 -> -683.12112 | J26: =J25+J22 -> -664.64534 | ... L26: =L25+L22 -> -615.8693
B27: Cumulative incremental FCF incl. upfront cash | C27: =-Inputs!$C$19+C25 -> -3085.75 | D27: =C27+D25 -> -3915.4 | E27: =D27+E25 -> -4733.17 | F27: =E27+F25 -> -5534.902 | G27: =F27+G25 -> -6315.25 | H27: =G27+H25 -> -7082.7676 | I27: =H27+I25 -> -7834.8887 | J27: =I27+J25 -> -8568.5341 | K27: =J27+K25 -> -9280.0085 | L27: =K27+L25 -> -9964.8778
B28: PAT breakeven reached? | C28: =IF(C12>=0,"Yes","No") -> No | D28: =IF(D12>=0,"Yes","No") -> No | E28: =IF(E12>=0,"Yes","No") -> No | F28: =IF(F12>=0,"Yes","No") -> No | G28: =IF(G12>=0,"Yes","No") -> No | H28: =IF(H12>=0,"Yes","No") -> No | I28: =IF(I12>=0,"Yes","No") -> No | J28: =IF(J12>=0,"Yes","No") -> Yes | ... L28: =IF(L12>=0,"Yes","No") -> Yes
B29: FCF breakeven reached? | C29: =IF(C25>=0,"Yes","No") -> No | D29: =IF(D25>=0,"Yes","No") -> No | E29: =IF(E25>=0,"Yes","No") -> No | F29: =IF(F25>=0,"Yes","No") -> No | G29: =IF(G25>=0,"Yes","No") -> No | H29: =IF(H25>=0,"Yes","No") -> No | I29: =IF(I25>=0,"Yes","No") -> No | J29: =IF(J25>=0,"Yes","No") -> No | ... L29: =IF(L25>=0,"Yes","No") -> No
B31: First year of PAT breakeven | C31: =IFERROR(MATCH("Yes",C28:L28,0),"Not within 10 years") -> 8
B32: First year of FCF breakeven (excluding MDR) | C32: =IFERROR(MATCH("Yes",C29:L29,0),"Not within 10 years") -> Not within 10 years
B33: Liminal FCF needed to cover the drag from its own cash flow (₹ Cr) | C33: =Inputs!$C$61 -> 750 | D33: → ARR required at cap margin (₹ Cr) | G33: =Inputs!$C$61/(Inputs!$C$54*Inputs!$C$55*Inputs!$C$56) -> 4000
B35: B. Phase-1 minority — 25% for ₹1,000 Cr from existing cash; no consolidation (equity method)
B36: Year (₹ Cr) | C36: Y1 | D36: Y2 | E36: Y3 | F36: Y4 | G36: Y5 | H36: Y6 | I36: Y7 | J36: Y8 | K36: Y9 | L36: Y10
B37: Paytm 25% share of Liminal PAT (standalone path) | C37: ='Liminal Projection'!D12 -> 2.475 | D37: ='Liminal Projection'!E12 -> 5.94 | E37: ='Liminal Projection'!F12 -> 10.692 | F37: ='Liminal Projection'!G12 -> 17.1072 | G37: ='Liminal Projection'!H12 -> 25.6608 | H37: ='Liminal Projection'!I12 -> 30.79296 | I37: ='Liminal Projection'!J12 -> 36.951552 | J37: ='Liminal Projection'!K12 -> 44.341862 | ... L37: ='Liminal Projection'!M12 -> 63.852282
B38: Foregone post-tax interest on cash used | C38: =-Inputs!$C$70*Inputs!$C$32*Inputs!$C$43*(1-Inputs!$C$45) -> -45 | D38: =-Inputs!$C$70*Inputs!$C$32*Inputs!$C$43*(1-Inputs!$C$45) -> -45 | E38: =-Inputs!$C$70*Inputs!$C$32*Inputs!$C$43*(1-Inputs!$C$45) -> -45 | F38: =-Inputs!$C$70*Inputs!$C$32*Inputs!$C$43*(1-Inputs!$C$45) -> -45 | G38: =-Inputs!$C$70*Inputs!$C$32*Inputs!$C$43*(1-Inputs!$C$45) -> -45 | H38: =-Inputs!$C$70*Inputs!$C$32*Inputs!$C$43*(1-Inputs!$C$45) -> -45 | I38: =-Inputs!$C$70*Inputs!$C$32*Inputs!$C$43*(1-Inputs!$C$45) -> -45 | J38: =-Inputs!$C$70*Inputs!$C$32*Inputs!$C$43*(1-Inputs!$C$45) -> -45 | ... L38: =-Inputs!$C$70*Inputs!$C$32*Inputs!$C$43*(1-Inputs!$C$45) -> -45
B39: Phase-1 fees — excluded from run-rate EPS (in FCF below) | C39: 0 | D39: 0 | E39: 0 | F39: 0 | G39: 0 | H39: 0 | I39: 0 | J39: 0 | K39: 0 | L39: 0
B40: Incremental PAT | C40: =SUM(C37:C39) -> -42.525 | D40: =SUM(D37:D39) -> -39.06 | E40: =SUM(E37:E39) -> -34.308 | F40: =SUM(F37:F39) -> -27.8928 | G40: =SUM(G37:G39) -> -19.3392 | H40: =SUM(H37:H39) -> -14.20704 | I40: =SUM(I37:I39) -> -8.048448 | J40: =SUM(J37:J39) -> -0.6581376 | ... L40: =SUM(L37:L39) -> 18.852282
B41: Pro-forma EPS (₹) | C41: =(Inputs!$C$13+C40)/Inputs!$C$8 -> 6.8355469 | D41: =(Inputs!$C$13+D40)/Inputs!$C$8 -> 6.8896875 | E41: =(Inputs!$C$13+E40)/Inputs!$C$8 -> 6.9639375 | F41: =(Inputs!$C$13+F40)/Inputs!$C$8 -> 7.064175 | G41: =(Inputs!$C$13+G40)/Inputs!$C$8 -> 7.197825 | H41: =(Inputs!$C$13+H40)/Inputs!$C$8 -> 7.278015 | I41: =(Inputs!$C$13+I40)/Inputs!$C$8 -> 7.374243 | J41: =(Inputs!$C$13+J40)/Inputs!$C$8 -> 7.4897166 | ... L41: =(Inputs!$C$13+L40)/Inputs!$C$8 -> 7.7945669
B42: Accretion / (dilution) vs ₹7.50 | C42: =C41/Inputs!$C$14-1 -> -0.08859375 | D42: =D41/Inputs!$C$14-1 -> -0.081375 | E42: =E41/Inputs!$C$14-1 -> -0.071475 | F42: =F41/Inputs!$C$14-1 -> -0.05811 | G42: =G41/Inputs!$C$14-1 -> -0.04029 | H42: =H41/Inputs!$C$14-1 -> -0.029598 | I42: =I41/Inputs!$C$14-1 -> -0.0167676 | J42: =J41/Inputs!$C$14-1 -> -0.00137112 | ... L42: =L41/Inputs!$C$14-1 -> 0.039275587
B44: Foregone post-tax interest (cash) | C44: =C38 -> -45 | D44: =D38 -> -45 | E44: =E38 -> -45 | F44: =F38 -> -45 | G44: =G38 -> -45 | H44: =H38 -> -45 | I44: =I38 -> -45 | J44: =J38 -> -45 | ... L44: =L38 -> -45
B45: Capital drag applied at minority level (gate) | C45: =-Inputs!$C$60 -> 0 | D45: =-Inputs!$C$60 -> 0 | E45: =-Inputs!$C$60 -> 0 | F45: =-Inputs!$C$60 -> 0 | G45: =-Inputs!$C$60 -> 0 | H45: =-Inputs!$C$60 -> 0 | I45: =-Inputs!$C$60 -> 0 | J45: =-Inputs!$C$60 -> 0 | ... L45: =-Inputs!$C$60 -> 0
B46: Phase-1 fees (Y1) | C46: =IF(1=1,-Inputs!$C$33,0) -> -15 | D46: =IF(2=1,-Inputs!$C$33,0) -> 0 | E46: =IF(3=1,-Inputs!$C$33,0) -> 0 | F46: =IF(4=1,-Inputs!$C$33,0) -> 0 | G46: =IF(5=1,-Inputs!$C$33,0) -> 0 | H46: =IF(6=1,-Inputs!$C$33,0) -> 0 | I46: =IF(7=1,-Inputs!$C$33,0) -> 0 | J46: =IF(8=1,-Inputs!$C$33,0) -> 0 | K46: =IF(9=1,-Inputs!$C$33,0) -> 0 | L46: =IF(10=1,-Inputs!$C$33,0) -> 0
...

Sheet Call Option & Earn-out
B2: 6. Call Option & Earn-out
B3: Future-control consideration capped at the lower of headline mechanics and retained-ARR value; upfront = strategic access, contingent = retained value
B5: Remaining stake acquired on exercise | C5: =Inputs!$C$71 -> 0.75
B6: Control-tranche valuation cap (₹ Cr) = remaining stake × headline | C6: =Inputs!$C$72 -> 3000
B7: Upfront at exercise (₹ Cr) | C7: =Inputs!$C$73 -> 1650
B8: Earn-out maximum (₹ Cr) | C8: =Inputs!$C$74 -> 1350
B9: Earn-out floor — retained ARR | C9: =Inputs!$C$37 -> 0.55
B10: Maximum total consideration incl. Phase 1 (₹ Cr) | C10: =Inputs!$C$70+C6 -> 4000 | D10: equals headline; never exceeded
B11: Maximum unconditional consideration (₹ Cr) | C11: =Inputs!$C$70 -> 1000
B13: Post-control churn | C13: Retained ARR | D13: Earn-out paid (₹ Cr) | E13: Control total (₹ Cr) | F13: Grand total incl. Phase 1 (₹ Cr) | G13: Remaining stake × headline multiple × retained ARR (₹ Cr)
B14: 0 | C14: =1-B14 -> 1 | D14: =$C$8*MIN(MAX((C14-$C$9)/(1-$C$9),0),1) -> 1350 | E14: =$C$7+D14 -> 3000 | F14: =Inputs!$C$70+E14 -> 4000 | G14: =Inputs!$C$71*Inputs!$C$68*Inputs!$C$21*C14 -> 3000
B15: 0.1 | C15: =1-B15 -> 0.9 | D15: =$C$8*MIN(MAX((C15-$C$9)/(1-$C$9),0),1) -> 1050 | E15: =$C$7+D15 -> 2700 | F15: =Inputs!$C$70+E15 -> 3700 | G15: =Inputs!$C$71*Inputs!$C$68*Inputs!$C$21*C15 -> 2700
B16: 0.2 | C16: =1-B16 -> 0.8 | D16: =$C$8*MIN(MAX((C16-$C$9)/(1-$C$9),0),1) -> 750 | E16: =$C$7+D16 -> 2400 | F16: =Inputs!$C$70+E16 -> 3400 | G16: =Inputs!$C$71*Inputs!$C$68*Inputs!$C$21*C16 -> 2400
B17: 0.3 | C17: =1-B17 -> 0.7 | D17: =$C$8*MIN(MAX((C17-$C$9)/(1-$C$9),0),1) -> 450 | E17: =$C$7+D17 -> 2100 | F17: =Inputs!$C$70+E17 -> 3100 | G17: =Inputs!$C$71*Inputs!$C$68*Inputs!$C$21*C17 -> 2100
B18: 0.375 | C18: =1-B18 -> 0.625 | D18: =$C$8*MIN(MAX((C18-$C$9)/(1-$C$9),0),1) -> 225 | E18: =$C$7+D18 -> 1875 | F18: =Inputs!$C$70+E18 -> 2875 | G18: =Inputs!$C$71*Inputs!$C$68*Inputs!$C$21*C18 -> 1875
B19: 0.45 | C19: =1-B19 -> 0.55 | D19: =$C$8*MIN(MAX((C19-$C$9)/(1-$C$9),0),1) -> 0 | E19: =$C$7+D19 -> 1650 | F19: =Inputs!$C$70+E19 -> 2650 | G19: =Inputs!$C$71*Inputs!$C$68*Inputs!$C$21*C19 -> 1650
B20: 0.55 | C20: =1-B20 -> 0.45 | D20: =$C$8*MIN(MAX((C20-$C$9)/(1-$C$9),0),1) -> 0 | E20: =$C$7+D20 -> 1650 | F20: =Inputs!$C$70+E20 -> 2650 | G20: =Inputs!$C$71*Inputs!$C$68*Inputs!$C$21*C20 -> 1350
B22: Earn-out shares if settled in Paytm stock at current price (Cr, maximum) | C22: =IF(Inputs!$C$38=1,C8/Inputs!$C$67,0) -> 0.72757895 | D22: % of share count | E22: =C22/Inputs!$C$8 -> 0.011368421
B23: Earn-out per 10 points of retained ARR (₹ Cr) | C23: =C8/(1-C9)*0.1 -> 300
B25: Pricing principle: consideration = lower of (1) agreed headline valuation mechanics and (2) retained-ARR / performance-based value, subject to client retention, regulatory capital treatment, financial performance, the valuation cap and customary adjustments. Column G shows the retained-ARR value; column E shows what the schedule pays.
B27: Phase-1 stake — illustrative return if exited at end of Y5 at a multiple of Y5 ARR (no dividends)
B28: Exit multiple of ARR → | C28: 6 | D28: 10 | E28: 14 | F28: =Inputs!$C$68 -> 18.181818
B29: 0.1 | C29: =((Inputs!$C$30*C$28*Inputs!$C$21*(1+$B29)^5)/Inputs!$C$70)^(1/5)-1 -> -0.11875742 | D29: =((Inputs!$C$30*D$28*Inputs!$C$21*(1+$B29)^5)/Inputs!$C$70)^(1/5)-1 -> -0.023965378 | E29: =((Inputs!$C$30*E$28*Inputs!$C$21*(1+$B29)^5)/Inputs!$C$70)^(1/5)-1 -> 0.043976758 | F29: =((Inputs!$C$30*F$28*Inputs!$C$21*(1+$B29)^5)/Inputs!$C$70)^(1/5)-1 -> 0.1
B30: 0.2 | C30: =((Inputs!$C$30*C$28*Inputs!$C$21*(1+$B30)^5)/Inputs!$C$70)^(1/5)-1 -> -0.038644459 | D30: =((Inputs!$C$30*D$28*Inputs!$C$21*(1+$B30)^5)/Inputs!$C$70)^(1/5)-1 -> 0.064765042 | E30: =((Inputs!$C$30*E$28*Inputs!$C$21*(1+$B30)^5)/Inputs!$C$70)^(1/5)-1 -> 0.13888374 | F30: =((Inputs!$C$30*F$28*Inputs!$C$21*(1+$B30)^5)/Inputs!$C$70)^(1/5)-1 -> 0.2
B31: 0.3 | C31: =((Inputs!$C$30*C$28*Inputs!$C$21*(1+$B31)^5)/Inputs!$C$70)^(1/5)-1 -> 0.041468503 | D31: =((Inputs!$C$30*D$28*Inputs!$C$21*(1+$B31)^5)/Inputs!$C$70)^(1/5)-1 -> 0.15349546 | E31: =((Inputs!$C$30*E$28*Inputs!$C$21*(1+$B31)^5)/Inputs!$C$70)^(1/5)-1 -> 0.23379071 | F31: =((Inputs!$C$30*F$28*Inputs!$C$21*(1+$B31)^5)/Inputs!$C$70)^(1/5)-1 -> 0.3
B32: Growth ↓ (rows) · IRR vs hurdle (WACC) | C32: =Inputs!$C$46 -> 0.12

Sheet Sensitivities
B2: 7. Sensitivities
B3: Year-1 EPS and FCF under key downside scenarios — churn and capital requirements — plus DCF value by growth
B5: A. Full acquisition (headline mix) — year-1 EPS by churn and cash-yield assumption
B6: Cash yield ↓ · Churn → | C6: 0 | D6: 0.3 | E6: 0.375 | F6: 0.45 | G6: 0.55
B7: 0.05 | C7: =(Inputs!$C$13-Inputs!$C$19*$B7*(1-Inputs!$C$45)+IF((Inputs!$C$21*(1+Inputs!$C$52)*(1-C$6)*MIN(Inputs!$C$53,Inputs!$C$54)-Inputs!$C$58*Inputs!$C$21*(1+Inputs!$C$52)*C$6)>0,(Inputs!$C$21*(1+Inputs!$C$52)*(1-C$6)*MIN(Inputs!$C$53,Inputs!$C$54)-Inputs!$C$58*Inputs!$C$21*(1+Inputs!$C$52)*C$6)*Inputs!$C$55,(Inputs!$C$21*(1+Inputs!$C$52)*(1-C$6)*MIN(Inputs!$C$53,Inputs!$C$54)-Inputs!$C$58*Inputs!$C$21*(1+Inputs!$C$52)*C$6)))/(Inputs!$C$8+Inputs!$C$20/Inputs!$C$67) -> 6.32305 | D7: =(Inputs!$C$13-Inputs!$C$19*$B7*(1-Inputs!$C$45)+IF((Inputs!$C$21*(1+Inputs!$C$52)*(1-D$6)*MIN(Inputs!$C$53,Inputs!$C$54)-Inputs!$C$58*Inputs!$C$21*(1+Inputs!$C$52)*D$6)>0,(Inputs!$C$21*(1+Inputs!$C$52)*(1-D$6)*MIN(Inputs!$C$53,Inputs!$C$54)-Inputs!$C$58*Inputs!$C$21*(1+Inputs!$C$52)*D$6)*Inputs!$C$55,(Inputs!$C$21*(1+Inputs!$C$52)*(1-D$6)*MIN(Inputs!$C$53,Inputs!$C$54)-Inputs!$C$58*Inputs!$C$21*(1+Inputs!$C$52)*D$6)))/(Inputs!$C$8+Inputs!$C$20/Inputs!$C$67) -> 5.7038939 | E7: =(Inputs!$C$13-Inputs!$C$19*$B7*(1-Inputs!$C$45)+IF((Inputs!$C$21*(1+Inputs!$C$52)*(1-E$6)*MIN(Inputs!$C$53,Inputs!$C$54)-Inputs!$C$58*Inputs!$C$21*(1+Inputs!$C$52)*E$6)>0,(Inputs!$C$21*(1+Inputs!$C$52)*(1-E$6)*MIN(Inputs!$C$53,Inputs!$C$54)-Inputs!$C$58*Inputs!$C$21*(1+Inputs!$C$52)*E$6)*Inputs!$C$55,(Inputs!$C$21*(1+Inputs!$C$52)*(1-E$6)*MIN(Inputs!$C$53,Inputs!$C$54)-Inputs!$C$58*Inputs!$C$21*(1+Inputs!$C$52)*E$6)))/(Inputs!$C$8+Inputs!$C$20/Inputs!$C$67) -> 5.5364173 | F7: =(Inputs!$C$13-Inputs!$C$19*$B7*(1-Inputs!$C$45)+IF((Inputs!$C$21*(1+Inputs!$C$52)*(1-F$6)*MIN(Inputs!$C$53,Inputs!$C$54)-Inputs!$C$58*Inputs!$C$21*(1+Inputs!$C$52)*F$6)>0,(Inputs!$C$21*(1+Inputs!$C$52)*(1-F$6)*MIN(Inputs!$C$53,Inputs!$C$54)-Inputs!$C$58*Inputs!$C$21*(1+Inputs!$C$52)*F$6)*Inputs!$C$55,(Inputs!$C$21*(1+Inputs!$C$52)*(1-F$6)*MIN(Inputs!$C$53,Inputs!$C$54)-Inputs!$C$58*Inputs!$C$21*(1+Inputs!$C$52)*F$6)))/(Inputs!$C$8+Inputs!$C$20/Inputs!$C$67) -> 5.3689407 | G7: =(Inputs!$C$13-Inputs!$C$19*$B7*(1-Inputs!$C$45)+IF((Inputs!$C$21*(1+Inputs!$C$52)*(1-G$6)*MIN(Inputs!$C$53,Inputs!$C$54)-Inputs!$C$58*Inputs!$C$21*(1+Inputs!$C$52)*G$6)>0,(Inputs!$C$21*(1+Inputs!$C$52)*(1-G$6)*MIN(Inputs!$C$53,Inputs!$C$54)-Inputs!$C$58*Inputs!$C$21*(1+Inputs!$C$52)*G$6)*Inputs!$C$55,(Inputs!$C$21*(1+Inputs!$C$52)*(1-G$6)*MIN(Inputs!$C$53,Inputs!$C$54)-Inputs!$C$58*Inputs!$C$21*(1+Inputs!$C$52)*G$6)))/(Inputs!$C$8+Inputs!$C$20/Inputs!$C$67) -> 5.1456385
B8: 0.06 | C8: =(Inputs!$C$13-Inputs!$C$19*$B8*(1-Inputs!$C$45)+IF((Inputs!$C$21*(1+Inputs!$C$52)*(1-C$6)*MIN(Inputs!$C$53,Inputs!$C$54)-Inputs!$C$58*Inputs!$C$21*(1+Inputs!$C$52)*C$6)>0,(Inputs!$C$21*(1+Inputs!$C$52)*(1-C$6)*MIN(Inputs!$C$53,Inputs!$C$54)-Inputs!$C$58*Inputs!$C$21*(1+Inputs!$C$52)*C$6)*Inputs!$C$55,(Inputs!$C$21*(1+Inputs!$C$52)*(1-C$6)*MIN(Inputs!$C$53,Inputs!$C$54)-Inputs!$C$58*Inputs!$C$21*(1+Inputs!$C$52)*C$6)))/(Inputs!$C$8+Inputs!$C$20/Inputs!$C$67) -> 6.0808317 | D8: =(Inputs!$C$13-Inputs!$C$19*$B8*(1-Inputs!$C$45)+IF((Inputs!$C$21*(1+Inputs!$C$52)*(1-D$6)*MIN(Inputs!$C$53,Inputs!$C$54)-Inputs!$C$58*Inputs!$C$21*(1+Inputs!$C$52)*D$6)>0,(Inputs!$C$21*(1+Inputs!$C$52)*(1-D$6)*MIN(Inputs!$C$53,Inputs!$C$54)-Inputs!$C$58*Inputs!$C$21*(1+Inputs!$C$52)*D$6)*Inputs!$C$55,(Inputs!$C$21*(1+Inputs!$C$52)*(1-D$6)*MIN(Inputs!$C$53,Inputs!$C$54)-Inputs!$C$58*Inputs!$C$21*(1+Inputs!$C$52)*D$6)))/(Inputs!$C$8+Inputs!$C$20/Inputs!$C$67) -> 5.4616757 | E8: =(Inputs!$C$13-Inputs!$C$19*$B8*(1-Inputs!$C$45)+IF((Inputs!$C$21*(1+Inputs!$C$52)*(1-E$6)*MIN(Inputs!$C$53,Inputs!$C$54)-Inputs!$C$58*Inputs!$C$21*(1+Inputs!$C$52)*E$6)>0,(Inputs!$C$21*(1+Inputs!$C$52)*(1-E$6)*MIN(Inputs!$C$53,Inputs!$C$54)-Inputs!$C$58*Inputs!$C$21*(1+Inputs!$C$52)*E$6)*Inputs!$C$55,(Inputs!$C$21*(1+Inputs!$C$52)*(1-E$6)*MIN(Inputs!$C$53,Inputs!$C$54)-Inputs!$C$58*Inputs!$C$21*(1+Inputs!$C$52)*E$6)))/(Inputs!$C$8+Inputs!$C$20/Inputs!$C$67) -> 5.2941991 | F8: =(Inputs!$C$13-Inputs!$C$19*$B8*(1-Inputs!$C$45)+IF((Inputs!$C$21*(1+Inputs!$C$52)*(1-F$6)*MIN(Inputs!$C$53,Inputs!$C$54)-Inputs!$C$58*Inputs!$C$21*(1+Inputs!$C$52)*F$6)>0,(Inputs!$C$21*(1+Inputs!$C$52)*(1-F$6)*MIN(Inputs!$C$53,Inputs!$C$54)-Inputs!$C$58*Inputs!$C$21*(1+Inputs!$C$52)*F$6)*Inputs!$C$55,(Inputs!$C$21*(1+Inputs!$C$52)*(1-F$6)*MIN(Inputs!$C$53,Inputs!$C$54)-Inputs!$C$58*Inputs!$C$21*(1+Inputs!$C$52)*F$6)))/(Inputs!$C$8+Inputs!$C$20/Inputs!$C$67) -> 5.1267224 | G8: =(Inputs!$C$13-Inputs!$C$19*$B8*(1-Inputs!$C$45)+IF((Inputs!$C$21*(1+Inputs!$C$52)*(1-G$6)*MIN(Inputs!$C$53,Inputs!$C$54)-Inputs!$C$58*Inputs!$C$21*(1+Inputs!$C$52)*G$6)>0,(Inputs!$C$21*(1+Inputs!$C$52)*(1-G$6)*MIN(Inputs!$C$53,Inputs!$C$54)-Inputs!$C$58*Inputs!$C$21*(1+Inputs!$C$52)*G$6)*Inputs!$C$55,(Inputs!$C$21*(1+Inputs!$C$52)*(1-G$6)*MIN(Inputs!$C$53,Inputs!$C$54)-Inputs!$C$58*Inputs!$C$21*(1+Inputs!$C$52)*G$6)))/(Inputs!$C$8+Inputs!$C$20/Inputs!$C$67) -> 4.9034203
B9: 0.07 | C9: =(Inputs!$C$13-Inputs!$C$19*$B9*(1-Inputs!$C$45)+IF((Inputs!$C$21*(1+Inputs!$C$52)*(1-C$6)*MIN(Inputs!$C$53,Inputs!$C$54)-Inputs!$C$58*Inputs!$C$21*(1+Inputs!$C$52)*C$6)>0,(Inputs!$C$21*(1+Inputs!$C$52)*(1-C$6)*MIN(Inputs!$C$53,Inputs!$C$54)-Inputs!$C$58*Inputs!$C$21*(1+Inputs!$C$52)*C$6)*Inputs!$C$55,(Inputs!$C$21*(1+Inputs!$C$52)*(1-C$6)*MIN(Inputs!$C$53,Inputs!$C$54)-Inputs!$C$58*Inputs!$C$21*(1+Inputs!$C$52)*C$6)))/(Inputs!$C$8+Inputs!$C$20/Inputs!$C$67) -> 5.8386134 | D9: =(Inputs!$C$13-Inputs!$C$19*$B9*(1-Inputs!$C$45)+IF((Inputs!$C$21*(1+Inputs!$C$52)*(1-D$6)*MIN(Inputs!$C$53,Inputs!$C$54)-Inputs!$C$58*Inputs!$C$21*(1+Inputs!$C$52)*D$6)>0,(Inputs!$C$21*(1+Inputs!$C$52)*(1-D$6)*MIN(Inputs!$C$53,Inputs!$C$54)-Inputs!$C$58*Inputs!$C$21*(1+Inputs!$C$52)*D$6)*Inputs!$C$55,(Inputs!$C$21*(1+Inputs!$C$52)*(1-D$6)*MIN(Inputs!$C$53,Inputs!$C$54)-Inputs!$C$58*Inputs!$C$21*(1+Inputs!$C$52)*D$6)))/(Inputs!$C$8+Inputs!$C$20/Inputs!$C$67) -> 5.2194574 | E9: =(Inputs!$C$13-Inputs!$C$19*$B9*(1-Inputs!$C$45)+IF((Inputs!$C$21*(1+Inputs!$C$52)*(1-E$6)*MIN(Inputs!$C$53,Inputs!$C$54)-Inputs!$C$58*Inputs!$C$21*(1+Inputs!$C$52)*E$6)>0,(Inputs!$C$21*(1+Inputs!$C$52)*(1-E$6)*MIN(Inputs!$C$53,Inputs!$C$54)-Inputs!$C$58*Inputs!$C$21*(1+Inputs!$C$52)*E$6)*Inputs!$C$55,(Inputs!$C$21*(1+Inputs!$C$52)*(1-E$6)*MIN(Inputs!$C$53,Inputs!$C$54)-Inputs!$C$58*Inputs!$C$21*(1+Inputs!$C$52)*E$6)))/(Inputs!$C$8+Inputs!$C$20/Inputs!$C$67) -> 5.0519808 | F9: =(Inputs!$C$13-Inputs!$C$19*$B9*(1-Inputs!$C$45)+IF((Inputs!$C$21*(1+Inputs!$C$52)*(1-F$6)*MIN(Inputs!$C$53,Inputs!$C$54)-Inputs!$C$58*Inputs!$C$21*(1+Inputs!$C$52)*F$6)>0,(Inputs!$C$21*(1+Inputs!$C$52)*(1-F$6)*MIN(Inputs!$C$53,Inputs!$C$54)-Inputs!$C$58*Inputs!$C$21*(1+Inputs!$C$52)*F$6)*Inputs!$C$55,(Inputs!$C$21*(1+Inputs!$C$52)*(1-F$6)*MIN(Inputs!$C$53,Inputs!$C$54)-Inputs!$C$58*Inputs!$C$21*(1+Inputs!$C$52)*F$6)))/(Inputs!$C$8+Inputs!$C$20/Inputs!$C$67) -> 4.8845042 | G9: =(Inputs!$C$13-Inputs!$C$19*$B9*(1-Inputs!$C$45)+IF((Inputs!$C$21*(1+Inputs!$C$52)*(1-G$6)*MIN(Inputs!$C$53,Inputs!$C$54)-Inputs!$C$58*Inputs!$C$21*(1+Inputs!$C$52)*G$6)>0,(Inputs!$C$21*(1+Inputs!$C$52)*(1-G$6)*MIN(Inputs!$C$53,Inputs!$C$54)-Inputs!$C$58*Inputs!$C$21*(1+Inputs!$C$52)*G$6)*Inputs!$C$55,(Inputs!$C$21*(1+Inputs!$C$52)*(1-G$6)*MIN(Inputs!$C$53,Inputs!$C$54)-Inputs!$C$58*Inputs!$C$21*(1+Inputs!$C$52)*G$6)))/(Inputs!$C$8+Inputs!$C$20/Inputs!$C$67) -> 4.661202
B10: Baseline EPS for reference (₹) | C10: =Inputs!$C$14 -> 7.5
B12: B. Full acquisition — year-1 incremental FCF by churn and capital-drag treatment (₹ Cr)
B13: Capital drag ↓ · Churn → | C13: 0 | D13: 0.3 | E13: 0.375 | F13: 0.45 | G13: 0.55
B14: 0 | C14: =IF((Inputs!$C$21*(1+Inputs!$C$52)*(1-C$13)*MIN(Inputs!$C$53,Inputs!$C$54)-Inputs!$C$58*Inputs!$C$21*(1+Inputs!$C$52)*C$13)>0,(Inputs!$C$21*(1+Inputs!$C$52)*(1-C$13)*MIN(Inputs!$C$53,Inputs!$C$54)-Inputs!$C$58*Inputs!$C$21*(1+Inputs!$C$52)*C$13)*Inputs!$C$55*Inputs!$C$56,(Inputs!$C$21*(1+Inputs!$C$52)*(1-C$13)*MIN(Inputs!$C$53,Inputs!$C$54)-Inputs!$C$58*Inputs!$C$21*(1+Inputs!$C$52)*C$13))-Inputs!$C$19*Inputs!$C$43*(1-Inputs!$C$45)-$B14-Inputs!$C$39 -> -184.6 | D14: =IF((Inputs!$C$21*(1+Inputs!$C$52)*(1-D$13)*MIN(Inputs!$C$53,Inputs!$C$54)-Inputs!$C$58*Inputs!$C$21*(1+Inputs!$C$52)*D$13)>0,(Inputs!$C$21*(1+Inputs!$C$52)*(1-D$13)*MIN(Inputs!$C$53,Inputs!$C$54)-Inputs!$C$58*Inputs!$C$21*(1+Inputs!$C$52)*D$13)*Inputs!$C$55*Inputs!$C$56,(Inputs!$C$21*(1+Inputs!$C$52)*(1-D$13)*MIN(Inputs!$C$53,Inputs!$C$54)-Inputs!$C$58*Inputs!$C$21*(1+Inputs!$C$52)*D$13))-Inputs!$C$19*Inputs!$C$43*(1-Inputs!$C$45)-$B14-Inputs!$C$39 -> -224.86 | E14: =IF((Inputs!$C$21*(1+Inputs!$C$52)*(1-E$13)*MIN(Inputs!$C$53,Inputs!$C$54)-Inputs!$C$58*Inputs!$C$21*(1+Inputs!$C$52)*E$13)>0,(Inputs!$C$21*(1+Inputs!$C$52)*(1-E$13)*MIN(Inputs!$C$53,Inputs!$C$54)-Inputs!$C$58*Inputs!$C$21*(1+Inputs!$C$52)*E$13)*Inputs!$C$55*Inputs!$C$56,(Inputs!$C$21*(1+Inputs!$C$52)*(1-E$13)*MIN(Inputs!$C$53,Inputs!$C$54)-Inputs!$C$58*Inputs!$C$21*(1+Inputs!$C$52)*E$13))-Inputs!$C$19*Inputs!$C$43*(1-Inputs!$C$45)-$B14-Inputs!$C$39 -> -235.75 | F14: =IF((Inputs!$C$21*(1+Inputs!$C$52)*(1-F$13)*MIN(Inputs!$C$53,Inputs!$C$54)-Inputs!$C$58*Inputs!$C$21*(1+Inputs!$C$52)*F$13)>0,(Inputs!$C$21*(1+Inputs!$C$52)*(1-F$13)*MIN(Inputs!$C$53,Inputs!$C$54)-Inputs!$C$58*Inputs!$C$21*(1+Inputs!$C$52)*F$13)*Inputs!$C$55*Inputs!$C$56,(Inputs!$C$21*(1+Inputs!$C$52)*(1-F$13)*MIN(Inputs!$C$53,Inputs!$C$54)-Inputs!$C$58*Inputs!$C$21*(1+Inputs!$C$52)*F$13))-Inputs!$C$19*Inputs!$C$43*(1-Inputs!$C$45)-$B14-Inputs!$C$39 -> -246.64 | G14: =IF((Inputs!$C$21*(1+Inputs!$C$52)*(1-G$13)*MIN(Inputs!$C$53,Inputs!$C$54)-Inputs!$C$58*Inputs!$C$21*(1+Inputs!$C$52)*G$13)>0,(Inputs!$C$21*(1+Inputs!$C$52)*(1-G$13)*MIN(Inputs!$C$53,Inputs!$C$54)-Inputs!$C$58*Inputs!$C$21*(1+Inputs!$C$52)*G$13)*Inputs!$C$55*Inputs!$C$56,(Inputs!$C$21*(1+Inputs!$C$52)*(1-G$13)*MIN(Inputs!$C$53,Inputs!$C$54)-Inputs!$C$58*Inputs!$C$21*(1+Inputs!$C$52)*G$13))-Inputs!$C$19*Inputs!$C$43*(1-Inputs!$C$45)-$B14-Inputs!$C$39 -> -261.16
B15: 195 | C15: =IF((Inputs!$C$21*(1+Inputs!$C$52)*(1-C$13)*MIN(Inputs!$C$53,Inputs!$C$54)-Inputs!$C$58*Inputs!$C$21*(1+Inputs!$C$52)*C$13)>0,(Inputs!$C$21*(1+Inputs!$C$52)*(1-C$13)*MIN(Inputs!$C$53,Inputs!$C$54)-Inputs!$C$58*Inputs!$C$21*(1+Inputs!$C$52)*C$13)*Inputs!$C$55*Inputs!$C$56,(Inputs!$C$21*(1+Inputs!$C$52)*(1-C$13)*MIN(Inputs!$C$53,Inputs!$C$54)-Inputs!$C$58*Inputs!$C$21*(1+Inputs!$C$52)*C$13))-Inputs!$C$19*Inputs!$C$43*(1-Inputs!$C$45)-$B15-Inputs!$C$39 -> -379.6 | D15: =IF((Inputs!$C$21*(1+Inputs!$C$52)*(1-D$13)*MIN(Inputs!$C$53,Inputs!$C$54)-Inputs!$C$58*Inputs!$C$21*(1+Inputs!$C$52)*D$13)>0,(Inputs!$C$21*(1+Inputs!$C$52)*(1-D$13)*MIN(Inputs!$C$53,Inputs!$C$54)-Inputs!$C$58*Inputs!$C$21*(1+Inputs!$C$52)*D$13)*Inputs!$C$55*Inputs!$C$56,(Inputs!$C$21*(1+Inputs!$C$52)*(1-D$13)*MIN(Inputs!$C$53,Inputs!$C$54)-Inputs!$C$58*Inputs!$C$21*(1+Inputs!$C$52)*D$13))-Inputs!$C$19*Inputs!$C$43*(1-Inputs!$C$45)-$B15-Inputs!$C$39 -> -419.86 | E15: =IF((Inputs!$C$21*(1+Inputs!$C$52)*(1-E$13)*MIN(Inputs!$C$53,Inputs!$C$54)-Inputs!$C$58*Inputs!$C$21*(1+Inputs!$C$52)*E$13)>0,(Inputs!$C$21*(1+Inputs!$C$52)*(1-E$13)*MIN(Inputs!$C$53,Inputs!$C$54)-Inputs!$C$58*Inputs!$C$21*(1+Inputs!$C$52)*E$13)*Inputs!$C$55*Inputs!$C$56,(Inputs!$C$21*(1+Inputs!$C$52)*(1-E$13)*MIN(Inputs!$C$53,Inputs!$C$54)-Inputs!$C$58*Inputs!$C$21*(1+Inputs!$C$52)*E$13))-Inputs!$C$19*Inputs!$C$43*(1-Inputs!$C$45)-$B15-Inputs!$C$39 -> -430.75 | F15: =IF((Inputs!$C$21*(1+Inputs!$C$52)*(1-F$13)*MIN(Inputs!$C$53,Inputs!$C$54)-Inputs!$C$58*Inputs!$C$21*(1+Inputs!$C$52)*F$13)>0,(Inputs!$C$21*(1+Inputs!$C$52)*(1-F$13)*MIN(Inputs!$C$53,Inputs!$C$54)-Inputs!$C$58*Inputs!$C$21*(1+Inputs!$C$52)*F$13)*Inputs!$C$55*Inputs!$C$56,(Inputs!$C$21*(1+Inputs!$C$52)*(1-F$13)*MIN(Inputs!$C$53,Inputs!$C$54)-Inputs!$C$58*Inputs!$C$21*(1+Inputs!$C$52)*F$13))-Inputs!$C$19*Inputs!$C$43*(1-Inputs!$C$45)-$B15-Inputs!$C$39 -> -441.64 | G15: =IF((Inputs!$C$21*(1+Inputs!$C$52)*(1-G$13)*MIN(Inputs!$C$53,Inputs!$C$54)-Inputs!$C$58*Inputs!$C$21*(1+Inputs!$C$52)*G$13)>0,(Inputs!$C$21*(1+Inputs!$C$52)*(1-G$13)*MIN(Inputs!$C$53,Inputs!$C$54)-Inputs!$C$58*Inputs!$C$21*(1+Inputs!$C$52)*G$13)*Inputs!$C$55*Inputs!$C$56,(Inputs!$C$21*(1+Inputs!$C$52)*(1-G$13)*MIN(Inputs!$C$53,Inputs!$C$54)-Inputs!$C$58*Inputs!$C$21*(1+Inputs!$C$52)*G$13))-Inputs!$C$19*Inputs!$C$43*(1-Inputs!$C$45)-$B15-Inputs!$C$39 -> -456.16
B16: 375 | C16: =IF((Inputs!$C$21*(1+Inputs!$C$52)*(1-C$13)*MIN(Inputs!$C$53,Inputs!$C$54)-Inputs!$C$58*Inputs!$C$21*(1+Inputs!$C$52)*C$13)>0,(Inputs!$C$21*(1+Inputs!$C$52)*(1-C$13)*MIN(Inputs!$C$53,Inputs!$C$54)-Inputs!$C$58*Inputs!$C$21*(1+Inputs!$C$52)*C$13)*Inputs!$C$55*Inputs!$C$56,(Inputs!$C$21*(1+Inputs!$C$52)*(1-C$13)*MIN(Inputs!$C$53,Inputs!$C$54)-Inputs!$C$58*Inputs!$C$21*(1+Inputs!$C$52)*C$13))-Inputs!$C$19*Inputs!$C$43*(1-Inputs!$C$45)-$B16-Inputs!$C$39 -> -559.6 | D16: =IF((Inputs!$C$21*(1+Inputs!$C$52)*(1-D$13)*MIN(Inputs!$C$53,Inputs!$C$54)-Inputs!$C$58*Inputs!$C$21*(1+Inputs!$C$52)*D$13)>0,(Inputs!$C$21*(1+Inputs!$C$52)*(1-D$13)*MIN(Inputs!$C$53,Inputs!$C$54)-Inputs!$C$58*Inputs!$C$21*(1+Inputs!$C$52)*D$13)*Inputs!$C$55*Inputs!$C$56,(Inputs!$C$21*(1+Inputs!$C$52)*(1-D$13)*MIN(Inputs!$C$53,Inputs!$C$54)-Inputs!$C$58*Inputs!$C$21*(1+Inputs!$C$52)*D$13))-Inputs!$C$19*Inputs!$C$43*(1-Inputs!$C$45)-$B16-Inputs!$C$39 -> -599.86 | E16: =IF((Inputs!$C$21*(1+Inputs!$C$52)*(1-E$13)*MIN(Inputs!$C$53,Inputs!$C$54)-Inputs!$C$58*Inputs!$C$21*(1+Inputs!$C$52)*E$13)>0,(Inputs!$C$21*(1+Inputs!$C$52)*(1-E$13)*MIN(Inputs!$C$53,Inputs!$C$54)-Inputs!$C$58*Inputs!$C$21*(1+Inputs!$C$52)*E$13)*Inputs!$C$55*Inputs!$C$56,(Inputs!$C$21*(1+Inputs!$C$52)*(1-E$13)*MIN(Inputs!$C$53,Inputs!$C$54)-Inputs!$C$58*Inputs!$C$21*(1+Inputs!$C$52)*E$13))-Inputs!$C$19*Inputs!$C$43*(1-Inputs!$C$45)-$B16-Inputs!$C$39 -> -610.75 | F16: =IF((Inputs!$C$21*(1+Inputs!$C$52)*(1-F$13)*MIN(Inputs!$C$53,Inputs!$C$54)-Inputs!$C$58*Inputs!$C$21*(1+Inputs!$C$52)*F$13)>0,(Inputs!$C$21*(1+Inputs!$C$52)*(1-F$13)*MIN(Inputs!$C$53,Inputs!$C$54)-Inputs!$C$58*Inputs!$C$21*(1+Inputs!$C$52)*F$13)*Inputs!$C$55*Inputs!$C$56,(Inputs!$C$21*(1+Inputs!$C$52)*(1-F$13)*MIN(Inputs!$C$53,Inputs!$C$54)-Inputs!$C$58*Inputs!$C$21*(1+Inputs!$C$52)*F$13))-Inputs!$C$19*Inputs!$C$43*(1-Inputs!$C$45)-$B16-Inputs!$C$39 -> -621.64 | G16: =IF((Inputs!$C$21*(1+Inputs!$C$52)*(1-G$13)*MIN(Inputs!$C$53,Inputs!$C$54)-Inputs!$C$58*Inputs!$C$21*(1+Inputs!$C$52)*G$13)>0,(Inputs!$C$21*(1+Inputs!$C$52)*(1-G$13)*MIN(Inputs!$C$53,Inputs!$C$54)-Inputs!$C$58*Inputs!$C$21*(1+Inputs!$C$52)*G$13)*Inputs!$C$55*Inputs!$C$56,(Inputs!$C$21*(1+Inputs!$C$52)*(1-G$13)*MIN(Inputs!$C$53,Inputs!$C$54)-Inputs!$C$58*Inputs!$C$21*(1+Inputs!$C$52)*G$13))-Inputs!$C$19*Inputs!$C$43*(1-Inputs!$C$45)-$B16-Inputs!$C$39 -> -636.16
